Workbook

Sheet INPUT DATA
A1: Input Data Sheet for Electronic-Class Record (ECR)
B7: SCHOOL INFORMATION | I7: LEARNERS' NAMES
C10: REGION | D10: : | E10: Region V | J10: MALE | M10: FEMALE
C11: DIVISION | D11: : | E11: Masbate | J11: 1 | M11: 1
J12: 2 | M12: 2
C13: SCHOOL ID | D13: : | E13: 113481 | J13: 3 | M13: 3
C14: SCHOOL NAME | D14: : | E14: Danao Elementary School | J14: 4 | M14: 4
C15: SCHOOL YEAR | D15: : | E15: 2026-2027 | J15: 5 | M15: 5
C16: SCHOOL HEAD | D16: : | E16: Joan D. Alcantara | J16: 6 | M16: 6
J17: 7 | M17: 7
J18: 8 | M18: 8
J19: 9 | M19: 9
B20: TEACHER, GRADE LEVEL, SECTION INFORMATION | J20: 10 | M20: 10
J21: 11 | M21: 11
J22: 12 | M22: 12
C23: SUBJECT TEACHER | D23: : | E23: Ronel C. Ramos | J23: 13 | M23: 13
C24: SUBJECT | D24: : | E24: GMRC | J24: 14 | M24: 14
C25: GRADE LEVEL | D25: : | E25: 2 | J25: 15 | M25: 15
C26: SECTION | D26: : | E26: Gumamela | J26: 16 | M26: 16
J27: 17 | M27: 17
C28: IMPORTANT NOTE: This is the official and final version of the file. All tabs are password-protected to prevent accidental formula edits and maintain the accuracy and integrity of the data. If you identify any inconsistencies or issues, particularly with the formulas, please report them for appropriate review and necessary correction. | J28: 18 | M28: 18
J29: 19 | M29: 19
J30: 20 | M30: 20
J31: 21 | M31: 21
J32: 22 | M32: 22
J33: 23 | M33: 23
J34: 24 | M34: 24
J35: 25 | M35: 25
B36: Sheet Protection Password: password123 | J36: 26 | M36: 26
J37: 27 | M37: 27
J38: 28 | M38: 28
J39: 29 | M39: 29
J40: 30 | M40: 30
J41: 31 | M41: 31
J42: 32 | M42: 32
J43: 33 | M43: 33
J44: 34 | M44: 34
J45: 35 | M45: 35
J46: 36 | M46: 36
J47: 37 | M47: 37
...

Sheet TERM 1
B2: CLASS RECORD
E5: REGION | F5: =IF('INPUT DATA'!E10="","",'INPUT DATA'!E10) -> Region V | R5: DIVISION | S5: =IF('INPUT DATA'!E11="","",'INPUT DATA'!E11) -> Masbate | AH5: SCHOOL ID | AI5: =IF('INPUT DATA'!E13="","",'INPUT DATA'!E13) -> 113481
E7: SCHOOL NAME | F7: =IF('INPUT DATA'!E14="","",'INPUT DATA'!E14) -> Danao Elementary School | AH7: SCHOOL YEAR | AI7: =IF('INPUT DATA'!E15="","",'INPUT DATA'!E15) -> 2026-2027
B10: FIRST TERM | F10: GRADE LEVEL | L10: =IF('INPUT DATA'!E25="","",'INPUT DATA'!E25) -> 2 | V10: TEACHER | AB10: =IF('INPUT DATA'!E23="","",'INPUT DATA'!E23) -> Ronel C. Ramos | AP10: SUBJECT | AR10: =IF('INPUT DATA'!E24="","",'INPUT DATA'!E24) -> GMRC
F11: SECTION | L11: =IF('INPUT DATA'!E26="","",'INPUT DATA'!E26) -> Gumamela
F12: WRITTEN / ORAL WORKS (WWs) | V12: PRODUCT / PERFORMANCE TASKS (PTs) | AN12: EXAMINATIONS (EXs) | AV12: Initial Grade | AW12: Term Grade | AX12: Descriptor
F14: COGNITIVE DOMAIN | N14: AFFECTIVE DOMAIN | V14: COGNITIVE DOMAIN | AB14: AFFECTIVE DOMAIN | AH14: BEHAVIORAL DOMAIN
F15: 1 | G15: 2 | H15: 3 | I15: 4 | J15: 5 | K15: Total | L15: PS | M15: WS | N15: 1 | O15: 2 | P15: 3 | Q15: 4 | R15: 5 | S15: Total | T15: PS | U15: WS | V15: 1 | W15: 2 | X15: 3 | Y15: Total | Z15: PS | AA15: WS | AB15: 1 | AC15: 2 | AD15: 3 | AE15: Total | AF15: PS | AG15: WS | AH15: 1 | AI15: 2 | AJ15: 3 | AK15: Total | AL15: PS | AM15: WS | AN15: ST1 | AO15: ST2 | AP15: TE | AQ15: WS ST1 | AR15: WS ST2 | AS15: WS TE | AT15: PS | AU15: WS
B16: HIGHEST POSSIBLE SCORE | K16: =IF(COUNT(F16:J16)=0,"",SUM(F16:J16)) | L16: 100 | M16: 0.1 | S16: =IF(COUNT(N16:R16)=0,"",SUM(N16:R16)) | T16: 100 | U16: 0.1 | Y16: =IF(COUNT(V16:X16)=0,"",SUM(V16:X16)) | Z16: 100 | AA16: 0.1 | AE16: =IF(COUNT(AB16:AD16)=0,"",SUM(AB16:AD16)) | AF16: 100 | AG16: 0.1 | AK16: =IF(COUNT(AH16:AJ16)=0,"",SUM(AH16:AJ16)) | AL16: 100 | AM16: 0.3 | AQ16: 30 | AR16: 30 | AS16: 40 | AT16: 100 | AU16: 0.3
B17: LEARNERS' NAMES
B18: MALE
B19: 1 | C19: =IF('INPUT DATA'!K11="","",'INPUT DATA'!K11) | K19: =IF(COUNT($F19:$J19)=0,"",SUM($F19:$J19)) | L19: =IF(COUNT(F19:J19)=0,"",IFERROR(K19/$K$16*$L$16,"")) | M19: =IF(L19="","",L19*$M$16) | S19: =IF(COUNT($N19:$R19)=0,"",SUM($N19:$R19)) | T19: =IF(COUNT(N19:R19)=0,"",IFERROR(S19/$S$16*$T$16,"")) | U19: =IF(T19="","",T19*$U$16) | Y19: =IF(COUNT(V19:X19)=0,"",SUM(V19:X19)) | Z19: =IF(COUNT(V19:X19)=0,"",IFERROR(Y19/$Y$16*$Z$16,"")) | AA19: =IF(Z19="","",Z19*$AA$16) | AE19: =IF(COUNT(AB19:AD19)=0,"",SUM(AB19:AD19)) | AF19: =IF(COUNT(AB19:AD19)=0,"",IFERROR(AE19/$AE$16*$AF$16,"")) | AG19: =IF(AF19="","",AF19*$AG$16) | AK19: =IF(COUNT(AH19:AJ19)=0,"",SUM(AH19:AJ19)) | AL19: =IF(COUNT(AH19:AJ19)=0,"",IFERROR(AK19/$AK$16*$AL$16,"")) | AM19: =IF(AL19="","",AL19*$AM$16) | AQ19: =IF(AN19="","",IFERROR(AN19/$AN$16*$AQ$16,"")) | AR19: =IF(AO19="","",IFERROR(AO19/$AO$16*$AR$16,"")) | AS19: =IF(AP19="","",IFERROR(AP19/$AP$16*$AS$16,"")) | AT19: =IF(COUNT(AN19:AP19)=0,"",SUM(AQ19:AS19)) | AU19: =IF(AT19="","",AT19*$AU$16) | AV19: =IF(COUNT(F19:J19,N19:R19,V19:X19,AB19:AD19,AH19:AJ19,AN19:AP19)=0,"",SUM(M19,U19,AA19,AG19,AM19,AU19)) | AW19: =IF(AV19="","",IFERROR(INDEX(HELPER!$D$8:$D$48,IF(AV19>=HELPER!$B$8,1,MATCH(AV19,HELPER!$B$8:$B$48,-1)+1)),"")) | AX19: =IF(AW19="","",IFERROR(VLOOKUP(AW19,HELPER!$F$8:$G$48,2,FALSE),""))
B20: 2 | C20: =IF('INPUT DATA'!K12="","",'INPUT DATA'!K12) | K20: =IF(COUNT($F20:$J20)=0,"",SUM($F20:$J20)) | L20: =IF(COUNT(F20:J20)=0,"",IFERROR(K20/$K$16*$L$16,"")) | M20: =IF(L20="","",L20*$M$16) | S20: =IF(COUNT($N20:$R20)=0,"",SUM($N20:$R20)) | T20: =IF(COUNT(N20:R20)=0,"",IFERROR(S20/$S$16*$T$16,"")) | U20: =IF(T20="","",T20*$U$16) | Y20: =IF(COUNT(V20:X20)=0,"",SUM(V20:X20)) | Z20: =IF(COUNT(V20:X20)=0,"",IFERROR(Y20/$Y$16*$Z$16,"")) | AA20: =IF(Z20="","",Z20*$AA$16) | AE20: =IF(COUNT(AB20:AD20)=0,"",SUM(AB20:AD20)) | AF20: =IF(COUNT(AB20:AD20)=0,"",IFERROR(AE20/$AE$16*$AF$16,"")) | AG20: =IF(AF20="","",AF20*$AG$16) | AK20: =IF(COUNT(AH20:AJ20)=0,"",SUM(AH20:AJ20)) | AL20: =IF(COUNT(AH20:AJ20)=0,"",IFERROR(AK20/$AK$16*$AL$16,"")) | AM20: =IF(AL20="","",AL20*$AM$16) | AQ20: =IF(AN20="","",IFERROR(AN20/$AN$16*$AQ$16,"")) | AR20: =IF(AO20="","",IFERROR(AO20/$AO$16*$AR$16,"")) | AS20: =IF(AP20="","",IFERROR(AP20/$AP$16*$AS$16,"")) | AT20: =IF(COUNT(AN20:AP20)=0,"",SUM(AQ20:AS20)) | AU20: =IF(AT20="","",AT20*$AU$16) | AV20: =IF(COUNT(F20:J20,N20:R20,V20:X20,AB20:AD20,AH20:AJ20,AN20:AP20)=0,"",SUM(M20,U20,AA20,AG20,AM20,AU20)) | AW20: =IF(AV20="","",IFERROR(INDEX(HELPER!$D$8:$D$48,IF(AV20>=HELPER!$B$8,1,MATCH(AV20,HELPER!$B$8:$B$48,-1)+1)),"")) | AX20: =IF(AW20="","",IFERROR(VLOOKUP(AW20,HELPER!$F$8:$G$48,2,FALSE),""))
B21: 3 | C21: =IF('INPUT DATA'!K13="","",'INPUT DATA'!K13) | K21: =IF(COUNT($F21:$J21)=0,"",SUM($F21:$J21)) | L21: =IF(COUNT(F21:J21)=0,"",IFERROR(K21/$K$16*$L$16,"")) | M21: =IF(L21="","",L21*$M$16) | S21: =IF(COUNT($N21:$R21)=0,"",SUM($N21:$R21)) | T21: =IF(COUNT(N21:R21)=0,"",IFERROR(S21/$S$16*$T$16,"")) | U21: =IF(T21="","",T21*$U$16) | Y21: =IF(COUNT(V21:X21)=0,"",SUM(V21:X21)) | Z21: =IF(COUNT(V21:X21)=0,"",IFERROR(Y21/$Y$16*$Z$16,"")) | AA21: =IF(Z21="","",Z21*$AA$16) | AE21: =IF(COUNT(AB21:AD21)=0,"",SUM(AB21:AD21)) | AF21: =IF(COUNT(AB21:AD21)=0,"",IFERROR(AE21/$AE$16*$AF$16,"")) | AG21: =IF(AF21="","",AF21*$AG$16) | AK21: =IF(COUNT(AH21:AJ21)=0,"",SUM(AH21:AJ21)) | AL21: =IF(COUNT(AH21:AJ21)=0,"",IFERROR(AK21/$AK$16*$AL$16,"")) | AM21: =IF(AL21="","",AL21*$AM$16) | AQ21: =IF(AN21="","",IFERROR(AN21/$AN$16*$AQ$16,"")) | AR21: =IF(AO21="","",IFERROR(AO21/$AO$16*$AR$16,"")) | AS21: =IF(AP21="","",IFERROR(AP21/$AP$16*$AS$16,"")) | AT21: =IF(COUNT(AN21:AP21)=0,"",SUM(AQ21:AS21)) | AU21: =IF(AT21="","",AT21*$AU$16) | AV21: =IF(COUNT(F21:J21,N21:R21,V21:X21,AB21:AD21,AH21:AJ21,AN21:AP21)=0,"",SUM(M21,U21,AA21,AG21,AM21,AU21)) | AW21: =IF(AV21="","",IFERROR(INDEX(HELPER!$D$8:$D$48,IF(AV21>=HELPER!$B$8,1,MATCH(AV21,HELPER!$B$8:$B$48,-1)+1)),"")) | AX21: =IF(AW21="","",IFERROR(VLOOKUP(AW21,HELPER!$F$8:$G$48,2,FALSE),""))
B22: 4 | C22: =IF('INPUT DATA'!K14="","",'INPUT DATA'!K14) | K22: =IF(COUNT($F22:$J22)=0,"",SUM($F22:$J22)) | L22: =IF(COUNT(F22:J22)=0,"",IFERROR(K22/$K$16*$L$16,"")) | M22: =IF(L22="","",L22*$M$16) | S22: =IF(COUNT($N22:$R22)=0,"",SUM($N22:$R22)) | T22: =IF(COUNT(N22:R22)=0,"",IFERROR(S22/$S$16*$T$16,"")) | U22: =IF(T22="","",T22*$U$16) | Y22: =IF(COUNT(V22:X22)=0,"",SUM(V22:X22)) | Z22: =IF(COUNT(V22:X22)=0,"",IFERROR(Y22/$Y$16*$Z$16,"")) | AA22: =IF(Z22="","",Z22*$AA$16) | AE22: =IF(COUNT(AB22:AD22)=0,"",SUM(AB22:AD22)) | AF22: =IF(COUNT(AB22:AD22)=0,"",IFERROR(AE22/$AE$16*$AF$16,"")) | AG22: =IF(AF22="","",AF22*$AG$16) | AK22: =IF(COUNT(AH22:AJ22)=0,"",SUM(AH22:AJ22)) | AL22: =IF(COUNT(AH22:AJ22)=0,"",IFERROR(AK22/$AK$16*$AL$16,"")) | AM22: =IF(AL22="","",AL22*$AM$16) | AQ22: =IF(AN22="","",IFERROR(AN22/$AN$16*$AQ$16,"")) | AR22: =IF(AO22="","",IFERROR(AO22/$AO$16*$AR$16,"")) | AS22: =IF(AP22="","",IFERROR(AP22/$AP$16*$AS$16,"")) | AT22: =IF(COUNT(AN22:AP22)=0,"",SUM(AQ22:AS22)) | AU22: =IF(AT22="","",AT22*$AU$16) | AV22: =IF(COUNT(F22:J22,N22:R22,V22:X22,AB22:AD22,AH22:AJ22,AN22:AP22)=0,"",SUM(M22,U22,AA22,AG22,AM22,AU22)) | AW22: =IF(AV22="","",IFERROR(INDEX(HELPER!$D$8:$D$48,IF(AV22>=HELPER!$B$8,1,MATCH(AV22,HELPER!$B$8:$B$48,-1)+1)),"")) | AX22: =IF(AW22="","",IFERROR(VLOOKUP(AW22,HELPER!$F$8:$G$48,2,FALSE),""))
B23: 5 | C23: =IF('INPUT DATA'!K15="","",'INPUT DATA'!K15) | K23: =IF(COUNT($F23:$J23)=0,"",SUM($F23:$J23)) | L23: =IF(COUNT(F23:J23)=0,"",IFERROR(K23/$K$16*$L$16,"")) | M23: =IF(L23="","",L23*$M$16) | S23: =IF(COUNT($N23:$R23)=0,"",SUM($N23:$R23)) | T23: =IF(COUNT(N23:R23)=0,"",IFERROR(S23/$S$16*$T$16,"")) | U23: =IF(T23="","",T23*$U$16) | Y23: =IF(COUNT(V23:X23)=0,"",SUM(V23:X23)) | Z23: =IF(COUNT(V23:X23)=0,"",IFERROR(Y23/$Y$16*$Z$16,"")) | AA23: =IF(Z23="","",Z23*$AA$16) | AE23: =IF(COUNT(AB23:AD23)=0,"",SUM(AB23:AD23)) | AF23: =IF(COUNT(AB23:AD23)=0,"",IFERROR(AE23/$AE$16*$AF$16,"")) | AG23: =IF(AF23="","",AF23*$AG$16) | AK23: =IF(COUNT(AH23:AJ23)=0,"",SUM(AH23:AJ23)) | AL23: =IF(COUNT(AH23:AJ23)=0,"",IFERROR(AK23/$AK$16*$AL$16,"")) | AM23: =IF(AL23="","",AL23*$AM$16) | AQ23: =IF(AN23="","",IFERROR(AN23/$AN$16*$AQ$16,"")) | AR23: =IF(AO23="","",IFERROR(AO23/$AO$16*$AR$16,"")) | AS23: =IF(AP23="","",IFERROR(AP23/$AP$16*$AS$16,"")) | AT23: =IF(COUNT(AN23:AP23)=0,"",SUM(AQ23:AS23)) | AU23: =IF(AT23="","",AT23*$AU$16) | AV23: =IF(COUNT(F23:J23,N23:R23,V23:X23,AB23:AD23,AH23:AJ23,AN23:AP23)=0,"",SUM(M23,U23,AA23,AG23,AM23,AU23)) | AW23: =IF(AV23="","",IFERROR(INDEX(HELPER!$D$8:$D$48,IF(AV23>=HELPER!$B$8,1,MATCH(AV23,HELPER!$B$8:$B$48,-1)+1)),"")) | AX23: =IF(AW23="","",IFERROR(VLOOKUP(AW23,HELPER!$F$8:$G$48,2,FALSE),""))
B24: 6 | C24: =IF('INPUT DATA'!K16="","",'INPUT DATA'!K16) | K24: =IF(COUNT($F24:$J24)=0,"",SUM($F24:$J24)) | L24: =IF(COUNT(F24:J24)=0,"",IFERROR(K24/$K$16*$L$16,"")) | M24: =IF(L24="","",L24*$M$16) | S24: =IF(COUNT($N24:$R24)=0,"",SUM($N24:$R24)) | T24: =IF(COUNT(N24:R24)=0,"",IFERROR(S24/$S$16*$T$16,"")) | U24: =IF(T24="","",T24*$U$16) | Y24: =IF(COUNT(V24:X24)=0,"",SUM(V24:X24)) | Z24: =IF(COUNT(V24:X24)=0,"",IFERROR(Y24/$Y$16*$Z$16,"")) | AA24: =IF(Z24="","",Z24*$AA$16) | AE24: =IF(COUNT(AB24:AD24)=0,"",SUM(AB24:AD24)) | AF24: =IF(COUNT(AB24:AD24)=0,"",IFERROR(AE24/$AE$16*$AF$16,"")) | AG24: =IF(AF24="","",AF24*$AG$16) | AK24: =IF(COUNT(AH24:AJ24)=0,"",SUM(AH24:AJ24)) | AL24: =IF(COUNT(AH24:AJ24)=0,"",IFERROR(AK24/$AK$16*$AL$16,"")) | AM24: =IF(AL24="","",AL24*$AM$16) | AQ24: =IF(AN24="","",IFERROR(AN24/$AN$16*$AQ$16,"")) | AR24: =IF(AO24="","",IFERROR(AO24/$AO$16*$AR$16,"")) | AS24: =IF(AP24="","",IFERROR(AP24/$AP$16*$AS$16,"")) | AT24: =IF(COUNT(AN24:AP24)=0,"",SUM(AQ24:AS24)) | AU24: =IF(AT24="","",AT24*$AU$16) | AV24: =IF(COUNT(F24:J24,N24:R24,V24:X24,AB24:AD24,AH24:AJ24,AN24:AP24)=0,"",SUM(M24,U24,AA24,AG24,AM24,AU24)) | AW24: =IF(AV24="","",IFERROR(INDEX(HELPER!$D$8:$D$48,IF(AV24>=HELPER!$B$8,1,MATCH(AV24,HELPER!$B$8:$B$48,-1)+1)),"")) | AX24: =IF(AW24="","",IFERROR(VLOOKUP(AW24,HELPER!$F$8:$G$48,2,FALSE),""))
B25: 7 | C25: =IF('INPUT DATA'!K17="","",'INPUT DATA'!K17) | K25: =IF(COUNT($F25:$J25)=0,"",SUM($F25:$J25)) | L25: =IF(COUNT(F25:J25)=0,"",IFERROR(K25/$K$16*$L$16,"")) | M25: =IF(L25="","",L25*$M$16) | S25: =IF(COUNT($N25:$R25)=0,"",SUM($N25:$R25)) | T25: =IF(COUNT(N25:R25)=0,"",IFERROR(S25/$S$16*$T$16,"")) | U25: =IF(T25="","",T25*$U$16) | Y25: =IF(COUNT(V25:X25)=0,"",SUM(V25:X25)) | Z25: =IF(COUNT(V25:X25)=0,"",IFERROR(Y25/$Y$16*$Z$16,"")) | AA25: =IF(Z25="","",Z25*$AA$16) | AE25: =IF(COUNT(AB25:AD25)=0,"",SUM(AB25:AD25)) | AF25: =IF(COUNT(AB25:AD25)=0,"",IFERROR(AE25/$AE$16*$AF$16,"")) | AG25: =IF(AF25="","",AF25*$AG$16) | AK25: =IF(COUNT(AH25:AJ25)=0,"",SUM(AH25:AJ25)) | AL25: =IF(COUNT(AH25:AJ25)=0,"",IFERROR(AK25/$AK$16*$AL$16,"")) | AM25: =IF(AL25="","",AL25*$AM$16) | AQ25: =IF(AN25="","",IFERROR(AN25/$AN$16*$AQ$16,"")) | AR25: =IF(AO25="","",IFERROR(AO25/$AO$16*$AR$16,"")) | AS25: =IF(AP25="","",IFERROR(AP25/$AP$16*$AS$16,"")) | AT25: =IF(COUNT(AN25:AP25)=0,"",SUM(AQ25:AS25)) | AU25: =IF(AT25="","",AT25*$AU$16) | AV25: =IF(COUNT(F25:J25,N25:R25,V25:X25,AB25:AD25,AH25:AJ25,AN25:AP25)=0,"",SUM(M25,U25,AA25,AG25,AM25,AU25)) | AW25: =IF(AV25="","",IFERROR(INDEX(HELPER!$D$8:$D$48,IF(AV25>=HELPER!$B$8,1,MATCH(AV25,HELPER!$B$8:$B$48,-1)+1)),"")) | AX25: =IF(AW25="","",IFERROR(VLOOKUP(AW25,HELPER!$F$8:$G$48,2,FALSE),""))
B26: 8 | C26: =IF('INPUT DATA'!K18="","",'INPUT DATA'!K18) | K26: =IF(COUNT($F26:$J26)=0,"",SUM($F26:$J26)) | L26: =IF(COUNT(F26:J26)=0,"",IFERROR(K26/$K$16*$L$16,"")) | M26: =IF(L26="","",L26*$M$16) | S26: =IF(COUNT($N26:$R26)=0,"",SUM($N26:$R26)) | T26: =IF(COUNT(N26:R26)=0,"",IFERROR(S26/$S$16*$T$16,"")) | U26: =IF(T26="","",T26*$U$16) | Y26: =IF(COUNT(V26:X26)=0,"",SUM(V26:X26)) | Z26: =IF(COUNT(V26:X26)=0,"",IFERROR(Y26/$Y$16*$Z$16,"")) | AA26: =IF(Z26="","",Z26*$AA$16) | AE26: =IF(COUNT(AB26:AD26)=0,"",SUM(AB26:AD26)) | AF26: =IF(COUNT(AB26:AD26)=0,"",IFERROR(AE26/$AE$16*$AF$16,"")) | AG26: =IF(AF26="","",AF26*$AG$16) | AK26: =IF(COUNT(AH26:AJ26)=0,"",SUM(AH26:AJ26)) | AL26: =IF(COUNT(AH26:AJ26)=0,"",IFERROR(AK26/$AK$16*$AL$16,"")) | AM26: =IF(AL26="","",AL26*$AM$16) | AQ26: =IF(AN26="","",IFERROR(AN26/$AN$16*$AQ$16,"")) | AR26: =IF(AO26="","",IFERROR(AO26/$AO$16*$AR$16,"")) | AS26: =IF(AP26="","",IFERROR(AP26/$AP$16*$AS$16,"")) | AT26: =IF(COUNT(AN26:AP26)=0,"",SUM(AQ26:AS26)) | AU26: =IF(AT26="","",AT26*$AU$16) | AV26: =IF(COUNT(F26:J26,N26:R26,V26:X26,AB26:AD26,AH26:AJ26,AN26:AP26)=0,"",SUM(M26,U26,AA26,AG26,AM26,AU26)) | AW26: =IF(AV26="","",IFERROR(INDEX(HELPER!$D$8:$D$48,IF(AV26>=HELPER!$B$8,1,MATCH(AV26,HELPER!$B$8:$B$48,-1)+1)),"")) | AX26: =IF(AW26="","",IFERROR(VLOOKUP(AW26,HELPER!$F$8:$G$48,2,FALSE),""))
B27: 9 | C27: =IF('INPUT DATA'!K19="","",'INPUT DATA'!K19) | K27: =IF(COUNT($F27:$J27)=0,"",SUM($F27:$J27)) | L27: =IF(COUNT(F27:J27)=0,"",IFERROR(K27/$K$16*$L$16,"")) | M27: =IF(L27="","",L27*$M$16) | S27: =IF(COUNT($N27:$R27)=0,"",SUM($N27:$R27)) | T27: =IF(COUNT(N27:R27)=0,"",IFERROR(S27/$S$16*$T$16,"")) | U27: =IF(T27="","",T27*$U$16) | Y27: =IF(COUNT(V27:X27)=0,"",SUM(V27:X27)) | Z27: =IF(COUNT(V27:X27)=0,"",IFERROR(Y27/$Y$16*$Z$16,"")) | AA27: =IF(Z27="","",Z27*$AA$16) | AE27: =IF(COUNT(AB27:AD27)=0,"",SUM(AB27:AD27)) | AF27: =IF(COUNT(AB27:AD27)=0,"",IFERROR(AE27/$AE$16*$AF$16,"")) | AG27: =IF(AF27="","",AF27*$AG$16) | AK27: =IF(COUNT(AH27:AJ27)=0,"",SUM(AH27:AJ27)) | AL27: =IF(COUNT(AH27:AJ27)=0,"",IFERROR(AK27/$AK$16*$AL$16,"")) | AM27: =IF(AL27="","",AL27*$AM$16) | AQ27: =IF(AN27="","",IFERROR(AN27/$AN$16*$AQ$16,"")) | AR27: =IF(AO27="","",IFERROR(AO27/$AO$16*$AR$16,"")) | AS27: =IF(AP27="","",IFERROR(AP27/$AP$16*$AS$16,"")) | AT27: =IF(COUNT(AN27:AP27)=0,"",SUM(AQ27:AS27)) | AU27: =IF(AT27="","",AT27*$AU$16) | AV27: =IF(COUNT(F27:J27,N27:R27,V27:X27,AB27:AD27,AH27:AJ27,AN27:AP27)=0,"",SUM(M27,U27,AA27,AG27,AM27,AU27)) | AW27: =IF(AV27="","",IFERROR(INDEX(HELPER!$D$8:$D$48,IF(AV27>=HELPER!$B$8,1,MATCH(AV27,HELPER!$B$8:$B$48,-1)+1)),"")) | AX27: =IF(AW27="","",IFERROR(VLOOKUP(AW27,HELPER!$F$8:$G$48,2,FALSE),""))
B28: 10 | C28: =IF('INPUT DATA'!K20="","",'INPUT DATA'!K20) | K28: =IF(COUNT($F28:$J28)=0,"",SUM($F28:$J28)) | L28: =IF(COUNT(F28:J28)=0,"",IFERROR(K28/$K$16*$L$16,"")) | M28: =IF(L28="","",L28*$M$16) | S28: =IF(COUNT($N28:$R28)=0,"",SUM($N28:$R28)) | T28: =IF(COUNT(N28:R28)=0,"",IFERROR(S28/$S$16*$T$16,"")) | U28: =IF(T28="","",T28*$U$16) | Y28: =IF(COUNT(V28:X28)=0,"",SUM(V28:X28)) | Z28: =IF(COUNT(V28:X28)=0,"",IFERROR(Y28/$Y$16*$Z$16,"")) | AA28: =IF(Z28="","",Z28*$AA$16) | AE28: =IF(COUNT(AB28:AD28)=0,"",SUM(AB28:AD28)) | AF28: =IF(COUNT(AB28:AD28)=0,"",IFERROR(AE28/$AE$16*$AF$16,"")) | AG28: =IF(AF28="","",AF28*$AG$16) | AK28: =IF(COUNT(AH28:AJ28)=0,"",SUM(AH28:AJ28)) | AL28: =IF(COUNT(AH28:AJ28)=0,"",IFERROR(AK28/$AK$16*$AL$16,"")) | AM28: =IF(AL28="","",AL28*$AM$16) | AQ28: =IF(AN28="","",IFERROR(AN28/$AN$16*$AQ$16,"")) | AR28: =IF(AO28="","",IFERROR(AO28/$AO$16*$AR$16,"")) | AS28: =IF(AP28="","",IFERROR(AP28/$AP$16*$AS$16,"")) | AT28: =IF(COUNT(AN28:AP28)=0,"",SUM(AQ28:AS28)) | AU28: =IF(AT28="","",AT28*$AU$16) | AV28: =IF(COUNT(F28:J28,N28:R28,V28:X28,AB28:AD28,AH28:AJ28,AN28:AP28)=0,"",SUM(M28,U28,AA28,AG28,AM28,AU28)) | AW28: =IF(AV28="","",IFERROR(INDEX(HELPER!$D$8:$D$48,IF(AV28>=HELPER!$B$8,1,MATCH(AV28,HELPER!$B$8:$B$48,-1)+1)),"")) | AX28: =IF(AW28="","",IFERROR(VLOOKUP(AW28,HELPER!$F$8:$G$48,2,FALSE),""))
B29: 11 | C29: =IF('INPUT DATA'!K21="","",'INPUT DATA'!K21) | K29: =IF(COUNT($F29:$J29)=0,"",SUM($F29:$J29)) | L29: =IF(COUNT(F29:J29)=0,"",IFERROR(K29/$K$16*$L$16,"")) | M29: =IF(L29="","",L29*$M$16) | S29: =IF(COUNT($N29:$R29)=0,"",SUM($N29:$R29)) | T29: =IF(COUNT(N29:R29)=0,"",IFERROR(S29/$S$16*$T$16,"")) | U29: =IF(T29="","",T29*$U$16) | Y29: =IF(COUNT(V29:X29)=0,"",SUM(V29:X29)) | Z29: =IF(COUNT(V29:X29)=0,"",IFERROR(Y29/$Y$16*$Z$16,"")) | AA29: =IF(Z29="","",Z29*$AA$16) | AE29: =IF(COUNT(AB29:AD29)=0,"",SUM(AB29:AD29)) | AF29: =IF(COUNT(AB29:AD29)=0,"",IFERROR(AE29/$AE$16*$AF$16,"")) | AG29: =IF(AF29="","",AF29*$AG$16) | AK29: =IF(COUNT(AH29:AJ29)=0,"",SUM(AH29:AJ29)) | AL29: =IF(COUNT(AH29:AJ29)=0,"",IFERROR(AK29/$AK$16*$AL$16,"")) | AM29: =IF(AL29="","",AL29*$AM$16) | AQ29: =IF(AN29="","",IFERROR(AN29/$AN$16*$AQ$16,"")) | AR29: =IF(AO29="","",IFERROR(AO29/$AO$16*$AR$16,"")) | AS29: =IF(AP29="","",IFERROR(AP29/$AP$16*$AS$16,"")) | AT29: =IF(COUNT(AN29:AP29)=0,"",SUM(AQ29:AS29)) | AU29: =IF(AT29="","",AT29*$AU$16) | AV29: =IF(COUNT(F29:J29,N29:R29,V29:X29,AB29:AD29,AH29:AJ29,AN29:AP29)=0,"",SUM(M29,U29,AA29,AG29,AM29,AU29)) | AW29: =IF(AV29="","",IFERROR(INDEX(HELPER!$D$8:$D$48,IF(AV29>=HELPER!$B$8,1,MATCH(AV29,HELPER!$B$8:$B$48,-1)+1)),"")) | AX29: =IF(AW29="","",IFERROR(VLOOKUP(AW29,HELPER!$F$8:$G$48,2,FALSE),""))
B30: 12 | C30: =IF('INPUT DATA'!K22="","",'INPUT DATA'!K22) | K30: =IF(COUNT($F30:$J30)=0,"",SUM($F30:$J30)) | L30: =IF(COUNT(F30:J30)=0,"",IFERROR(K30/$K$16*$L$16,"")) | M30: =IF(L30="","",L30*$M$16) | S30: =IF(COUNT($N30:$R30)=0,"",SUM($N30:$R30)) | T30: =IF(COUNT(N30:R30)=0,"",IFERROR(S30/$S$16*$T$16,"")) | U30: =IF(T30="","",T30*$U$16) | Y30: =IF(COUNT(V30:X30)=0,"",SUM(V30:X30)) | Z30: =IF(COUNT(V30:X30)=0,"",IFERROR(Y30/$Y$16*$Z$16,"")) | AA30: =IF(Z30="","",Z30*$AA$16) | AE30: =IF(COUNT(AB30:AD30)=0,"",SUM(AB30:AD30)) | AF30: =IF(COUNT(AB30:AD30)=0,"",IFERROR(AE30/$AE$16*$AF$16,"")) | AG30: =IF(AF30="","",AF30*$AG$16) | AK30: =IF(COUNT(AH30:AJ30)=0,"",SUM(AH30:AJ30)) | AL30: =IF(COUNT(AH30:AJ30)=0,"",IFERROR(AK30/$AK$16*$AL$16,"")) | AM30: =IF(AL30="","",AL30*$AM$16) | AQ30: =IF(AN30="","",IFERROR(AN30/$AN$16*$AQ$16,"")) | AR30: =IF(AO30="","",IFERROR(AO30/$AO$16*$AR$16,"")) | AS30: =IF(AP30="","",IFERROR(AP30/$AP$16*$AS$16,"")) | AT30: =IF(COUNT(AN30:AP30)=0,"",SUM(AQ30:AS30)) | AU30: =IF(AT30="","",AT30*$AU$16) | AV30: =IF(COUNT(F30:J30,N30:R30,V30:X30,AB30:AD30,AH30:AJ30,AN30:AP30)=0,"",SUM(M30,U30,AA30,AG30,AM30,AU30)) | AW30: =IF(AV30="","",IFERROR(INDEX(HELPER!$D$8:$D$48,IF(AV30>=HELPER!$B$8,1,MATCH(AV30,HELPER!$B$8:$B$48,-1)+1)),"")) | AX30: =IF(AW30="","",IFERROR(VLOOKUP(AW30,HELPER!$F$8:$G$48,2,FALSE),""))
... B68: 50 | C68: =IF('INPUT DATA'!K60="","",'INPUT DATA'!K60) | K68: =IF(COUNT($F68:$J68)=0,"",SUM($F68:$J68)) | L68: =IF(COUNT(F68:J68)=0,"",IFERROR(K68/$K$16*$L$16,"")) | M68: =IF(L68="","",L68*$M$16) | S68: =IF(COUNT($N68:$R68)=0,"",SUM($N68:$R68)) | T68: =IF(COUNT(N68:R68)=0,"",IFERROR(S68/$S$16*$T$16,"")) | U68: =IF(T68="","",T68*$U$16) | Y68: =IF(COUNT(V68:X68)=0,"",SUM(V68:X68)) | Z68: =IF(COUNT(V68:X68)=0,"",IFERROR(Y68/$Y$16*$Z$16,"")) | AA68: =IF(Z68="","",Z68*$AA$16) | AE68: =IF(COUNT(AB68:AD68)=0,"",SUM(AB68:AD68)) | AF68: =IF(COUNT(AB68:AD68)=0,"",IFERROR(AE68/$AE$16*$AF$16,"")) | AG68: =IF(AF68="","",AF68*$AG$16) | AK68: =IF(COUNT(AH68:AJ68)=0,"",SUM(AH68:AJ68)) | AL68: =IF(COUNT(AH68:AJ68)=0,"",IFERROR(AK68/$AK$16*$AL$16,"")) | AM68: =IF(AL68="","",AL68*$AM$16) | AQ68: =IF(AN68="","",IFERROR(AN68/$AN$16*$AQ$16,"")) | AR68: =IF(AO68="","",IFERROR(AO68/$AO$16*$AR$16,"")) | AS68: =IF(AP68="","",IFERROR(AP68/$AP$16*$AS$16,"")) | AT68: =IF(COUNT(AN68:AP68)=0,"",SUM(AQ68:AS68)) | AU68: =IF(AT68="","",AT68*$AU$16) | AV68: =IF(COUNT(F68:J68,N68:R68,V68:X68,AB68:AD68,AH68:AJ68,AN68:AP68)=0,"",SUM(M68,U68,AA68,AG68,AM68,AU68)) | AW68: =IF(AV68="","",IFERROR(INDEX(HELPER!$D$8:$D$48,IF(AV68>=HELPER!$B$8,1,MATCH(AV68,HELPER!$B$8:$B$48,-1)+1)),"")) | AX68: =IF(AW68="","",IFERROR(VLOOKUP(AW68,HELPER!$F$8:$G$48,2,FALSE),""))
B69: FEMALE
B70: 1 | C70: =IF('INPUT DATA'!N11="","",'INPUT DATA'!N11) | K70: =IF(COUNT($F70:$J70)=0,"",SUM($F70:$J70)) | L70: =IF(COUNT(F70:J70)=0,"",IFERROR(K70/$K$16*$L$16,"")) | M70: =IF(L70="","",L70*$M$16) | S70: =IF(COUNT($N70:$R70)=0,"",SUM($N70:$R70)) | T70: =IF(COUNT(N70:R70)=0,"",IFERROR(S70/$S$16*$T$16,"")) | U70: =IF(T70="","",T70*$U$16) | Y70: =IF(COUNT(V70:X70)=0,"",SUM(V70:X70)) | Z70: =IF(COUNT(V70:X70)=0,"",IFERROR(Y70/$Y$16*$Z$16,"")) | AA70: =IF(Z70="","",Z70*$AA$16) | AE70: =IF(COUNT(AB70:AD70)=0,"",SUM(AB70:AD70)) | AF70: =IF(COUNT(AB70:AD70)=0,"",IFERROR(AE70/$AE$16*$AF$16,"")) | AG70: =IF(AF70="","",AF70*$AG$16) | AK70: =IF(COUNT(AH70:AJ70)=0,"",SUM(AH70:AJ70)) | AL70: =IF(COUNT(AH70:AJ70)=0,"",IFERROR(AK70/$AK$16*$AL$16,"")) | AM70: =IF(AL70="","",AL70*$AM$16) | AQ70: =IF(AN70="","",IFERROR(AN70/$AN$16*$AQ$16,"")) | AR70: =IF(AO70="","",IFERROR(AO70/$AO$16*$AR$16,"")) | AS70: =IF(AP70="","",IFERROR(AP70/$AP$16*$AS$16,"")) | AT70: =IF(COUNT(AN70:AP70)=0,"",SUM(AQ70:AS70)) | AU70: =IF(AT70="","",AT70*$AU$16) | AV70: =IF(COUNT(F70:J70,N70:R70,V70:X70,AB70:AD70,AH70:AJ70,AN70:AP70)=0,"",SUM(M70,U70,AA70,AG70,AM70,AU70)) | AW70: =IF(AV70="","",IFERROR(INDEX(HELPER!$D$8:$D$48,IF(AV70>=HELPER!$B$8,1,MATCH(AV70,HELPER!$B$8:$B$48,-1)+1)),"")) | AX70: =IF(AW70="","",IFERROR(VLOOKUP(AW70,HELPER!$F$8:$G$48,2,FALSE),""))
B71: 2 | C71: =IF('INPUT DATA'!N12="","",'INPUT DATA'!N12) | K71: =IF(COUNT($F71:$J71)=0,"",SUM($F71:$J71)) | L71: =IF(COUNT(F71:J71)=0,"",IFERROR(K71/$K$16*$L$16,"")) | M71: =IF(L71="","",L71*$M$16) | S71: =IF(COUNT($N71:$R71)=0,"",SUM($N71:$R71)) | T71: =IF(COUNT(N71:R71)=0,"",IFERROR(S71/$S$16*$T$16,"")) | U71: =IF(T71="","",T71*$U$16) | Y71: =IF(COUNT(V71:X71)=0,"",SUM(V71:X71)) | Z71: =IF(COUNT(V71:X71)=0,"",IFERROR(Y71/$Y$16*$Z$16,"")) | AA71: =IF(Z71="","",Z71*$AA$16) | AE71: =IF(COUNT(AB71:AD71)=0,"",SUM(AB71:AD71)) | AF71: =IF(COUNT(AB71:AD71)=0,"",IFERROR(AE71/$AE$16*$AF$16,"")) | AG71: =IF(AF71="","",AF71*$AG$16) | AK71: =IF(COUNT(AH71:AJ71)=0,"",SUM(AH71:AJ71)) | AL71: =IF(COUNT(AH71:AJ71)=0,"",IFERROR(AK71/$AK$16*$AL$16,"")) | AM71: =IF(AL71="","",AL71*$AM$16) | AQ71: =IF(AN71="","",IFERROR(AN71/$AN$16*$AQ$16,"")) | AR71: =IF(AO71="","",IFERROR(AO71/$AO$16*$AR$16,"")) | AS71: =IF(AP71="","",IFERROR(AP71/$AP$16*$AS$16,"")) | AT71: =IF(COUNT(AN71:AP71)=0,"",SUM(AQ71:AS71)) | AU71: =IF(AT71="","",AT71*$AU$16) | AV71: =IF(COUNT(F71:J71,N71:R71,V71:X71,AB71:AD71,AH71:AJ71,AN71:AP71)=0,"",SUM(M71,U71,AA71,AG71,AM71,AU71)) | AW71: =IF(AV71="","",IFERROR(INDEX(HELPER!$D$8:$D$48,IF(AV71>=HELPER!$B$8,1,MATCH(AV71,HELPER!$B$8:$B$48,-1)+1)),"")) | AX71: =IF(AW71="","",IFERROR(VLOOKUP(AW71,HELPER!$F$8:$G$48,2,FALSE),""))
B72: 3 | C72: =IF('INPUT DATA'!N13="","",'INPUT DATA'!N13) | K72: =IF(COUNT($F72:$J72)=0,"",SUM($F72:$J72)) | L72: =IF(COUNT(F72:J72)=0,"",IFERROR(K72/$K$16*$L$16,"")) | M72: =IF(L72="","",L72*$M$16) | S72: =IF(COUNT($N72:$R72)=0,"",SUM($N72:$R72)) | T72: =IF(COUNT(N72:R72)=0,"",IFERROR(S72/$S$16*$T$16,"")) | U72: =IF(T72="","",T72*$U$16) | Y72: =IF(COUNT(V72:X72)=0,"",SUM(V72:X72)) | Z72: =IF(COUNT(V72:X72)=0,"",IFERROR(Y72/$Y$16*$Z$16,"")) | AA72: =IF(Z72="","",Z72*$AA$16) | AE72: =IF(COUNT(AB72:AD72)=0,"",SUM(AB72:AD72)) | AF72: =IF(COUNT(AB72:AD72)=0,"",IFERROR(AE72/$AE$16*$AF$16,"")) | AG72: =IF(AF72="","",AF72*$AG$16) | AK72: =IF(COUNT(AH72:AJ72)=0,"",SUM(AH72:AJ72)) | AL72: =IF(COUNT(AH72:AJ72)=0,"",IFERROR(AK72/$AK$16*$AL$16,"")) | AM72: =IF(AL72="","",AL72*$AM$16) | AQ72: =IF(AN72="","",IFERROR(AN72/$AN$16*$AQ$16,"")) | AR72: =IF(AO72="","",IFERROR(AO72/$AO$16*$AR$16,"")) | AS72: =IF(AP72="","",IFERROR(AP72/$AP$16*$AS$16,"")) | AT72: =IF(COUNT(AN72:AP72)=0,"",SUM(AQ72:AS72)) | AU72: =IF(AT72="","",AT72*$AU$16) | AV72: =IF(COUNT(F72:J72,N72:R72,V72:X72,AB72:AD72,AH72:AJ72,AN72:AP72)=0,"",SUM(M72,U72,AA72,AG72,AM72,AU72)) | AW72: =IF(AV72="","",IFERROR(INDEX(HELPER!$D$8:$D$48,IF(AV72>=HELPER!$B$8,1,MATCH(AV72,HELPER!$B$8:$B$48,-1)+1)),"")) | AX72: =IF(AW72="","",IFERROR(VLOOKUP(AW72,HELPER!$F$8:$G$48,2,FALSE),""))
B73: 4 | C73: =IF('INPUT DATA'!N14="","",'INPUT DATA'!N14) | K73: =IF(COUNT($F73:$J73)=0,"",SUM($F73:$J73)) | L73: =IF(COUNT(F73:J73)=0,"",IFERROR(K73/$K$16*$L$16,"")) | M73: =IF(L73="","",L73*$M$16) | S73: =IF(COUNT($N73:$R73)=0,"",SUM($N73:$R73)) | T73: =IF(COUNT(N73:R73)=0,"",IFERROR(S73/$S$16*$T$16,"")) | U73: =IF(T73="","",T73*$U$16) | Y73: =IF(COUNT(V73:X73)=0,"",SUM(V73:X73)) | Z73: =IF(COUNT(V73:X73)=0,"",IFERROR(Y73/$Y$16*$Z$16,"")) | AA73: =IF(Z73="","",Z73*$AA$16) | AE73: =IF(COUNT(AB73:AD73)=0,"",SUM(AB73:AD73)) | AF73: =IF(COUNT(AB73:AD73)=0,"",IFERROR(AE73/$AE$16*$AF$16,"")) | AG73: =IF(AF73="","",AF73*$AG$16) | AK73: =IF(COUNT(AH73:AJ73)=0,"",SUM(AH73:AJ73)) | AL73: =IF(COUNT(AH73:AJ73)=0,"",IFERROR(AK73/$AK$16*$AL$16,"")) | AM73: =IF(AL73="","",AL73*$AM$16) | AQ73: =IF(AN73="","",IFERROR(AN73/$AN$16*$AQ$16,"")) | AR73: =IF(AO73="","",IFERROR(AO73/$AO$16*$AR$16,"")) | AS73: =IF(AP73="","",IFERROR(AP73/$AP$16*$AS$16,"")) | AT73: =IF(COUNT(AN73:AP73)=0,"",SUM(AQ73:AS73)) | AU73: =IF(AT73="","",AT73*$AU$16) | AV73: =IF(COUNT(F73:J73,N73:R73,V73:X73,AB73:AD73,AH73:AJ73,AN73:AP73)=0,"",SUM(M73,U73,AA73,AG73,AM73,AU73)) | AW73: =IF(AV73="","",IFERROR(INDEX(HELPER!$D$8:$D$48,IF(AV73>=HELPER!$B$8,1,MATCH(AV73,HELPER!$B$8:$B$48,-1)+1)),"")) | AX73: =IF(AW73="","",IFERROR(VLOOKUP(AW73,HELPER!$F$8:$G$48,2,FALSE),""))
B74: 5 | C74: =IF('INPUT DATA'!N15="","",'INPUT DATA'!N15) | K74: =IF(COUNT($F74:$J74)=0,"",SUM($F74:$J74)) | L74: =IF(COUNT(F74:J74)=0,"",IFERROR(K74/$K$16*$L$16,"")) | M74: =IF(L74="","",L74*$M$16) | S74: =IF(COUNT($N74:$R74)=0,"",SUM($N74:$R74)) | T74: =IF(COUNT(N74:R74)=0,"",IFERROR(S74/$S$16*$T$16,"")) | U74: =IF(T74="","",T74*$U$16) | Y74: =IF(COUNT(V74:X74)=0,"",SUM(V74:X74)) | Z74: =IF(COUNT(V74:X74)=0,"",IFERROR(Y74/$Y$16*$Z$16,"")) | AA74: =IF(Z74="","",Z74*$AA$16) | AE74: =IF(COUNT(AB74:AD74)=0,"",SUM(AB74:AD74)) | AF74: =IF(COUNT(AB74:AD74)=0,"",IFERROR(AE74/$AE$16*$AF$16,"")) | AG74: =IF(AF74="","",AF74*$AG$16) | AK74: =IF(COUNT(AH74:AJ74)=0,"",SUM(AH74:AJ74)) | AL74: =IF(COUNT(AH74:AJ74)=0,"",IFERROR(AK74/$AK$16*$AL$16,"")) | AM74: =IF(AL74="","",AL74*$AM$16) | AQ74: =IF(AN74="","",IFERROR(AN74/$AN$16*$AQ$16,"")) | AR74: =IF(AO74="","",IFERROR(AO74/$AO$16*$AR$16,"")) | AS74: =IF(AP74="","",IFERROR(AP74/$AP$16*$AS$16,"")) | AT74: =IF(COUNT(AN74:AP74)=0,"",SUM(AQ74:AS74)) | AU74: =IF(AT74="","",AT74*$AU$16) | AV74: =IF(COUNT(F74:J74,N74:R74,V74:X74,AB74:AD74,AH74:AJ74,AN74:AP74)=0,"",SUM(M74,U74,AA74,AG74,AM74,AU74)) | AW74: =IF(AV74="","",IFERROR(INDEX(HELPER!$D$8:$D$48,IF(AV74>=HELPER!$B$8,1,MATCH(AV74,HELPER!$B$8:$B$48,-1)+1)),"")) | AX74: =IF(AW74="","",IFERROR(VLOOKUP(AW74,HELPER!$F$8:$G$48,2,FALSE),""))
B75: 6 | C75: =IF('INPUT DATA'!N16="","",'INPUT DATA'!N16) | K75: =IF(COUNT($F75:$J75)=0,"",SUM($F75:$J75)) | L75: =IF(COUNT(F75:J75)=0,"",IFERROR(K75/$K$16*$L$16,"")) | M75: =IF(L75="","",L75*$M$16) | S75: =IF(COUNT($N75:$R75)=0,"",SUM($N75:$R75)) | T75: =IF(COUNT(N75:R75)=0,"",IFERROR(S75/$S$16*$T$16,"")) | U75: =IF(T75="","",T75*$U$16) | Y75: =IF(COUNT(V75:X75)=0,"",SUM(V75:X75)) | Z75: =IF(COUNT(V75:X75)=0,"",IFERROR(Y75/$Y$16*$Z$16,"")) | AA75: =IF(Z75="","",Z75*$AA$16) | AE75: =IF(COUNT(AB75:AD75)=0,"",SUM(AB75:AD75)) | AF75: =IF(COUNT(AB75:AD75)=0,"",IFERROR(AE75/$AE$16*$AF$16,"")) | AG75: =IF(AF75="","",AF75*$AG$16) | AK75: =IF(COUNT(AH75:AJ75)=0,"",SUM(AH75:AJ75)) | AL75: =IF(COUNT(AH75:AJ75)=0,"",IFERROR(AK75/$AK$16*$AL$16,"")) | AM75: =IF(AL75="","",AL75*$AM$16) | AQ75: =IF(AN75="","",IFERROR(AN75/$AN$16*$AQ$16,"")) | AR75: =IF(AO75="","",IFERROR(AO75/$AO$16*$AR$16,"")) | AS75: =IF(AP75="","",IFERROR(AP75/$AP$16*$AS$16,"")) | AT75: =IF(COUNT(AN75:AP75)=0,"",SUM(AQ75:AS75)) | AU75: =IF(AT75="","",AT75*$AU$16) | AV75: =IF(COUNT(F75:J75,N75:R75,V75:X75,AB75:AD75,AH75:AJ75,AN75:AP75)=0,"",SUM(M75,U75,AA75,AG75,AM75,AU75)) | AW75: =IF(AV75="","",IFERROR(INDEX(HELPER!$D$8:$D$48,IF(AV75>=HELPER!$B$8,1,MATCH(AV75,HELPER!$B$8:$B$48,-1)+1)),"")) | AX75: =IF(AW75="","",IFERROR(VLOOKUP(AW75,HELPER!$F$8:$G$48,2,FALSE),""))
B76: 7 | C76: =IF('INPUT DATA'!N17="","",'INPUT DATA'!N17) | K76: =IF(COUNT($F76:$J76)=0,"",SUM($F76:$J76)) | L76: =IF(COUNT(F76:J76)=0,"",IFERROR(K76/$K$16*$L$16,"")) | M76: =IF(L76="","",L76*$M$16) | S76: =IF(COUNT($N76:$R76)=0,"",SUM($N76:$R76)) | T76: =IF(COUNT(N76:R76)=0,"",IFERROR(S76/$S$16*$T$16,"")) | U76: =IF(T76="","",T76*$U$16) | Y76: =IF(COUNT(V76:X76)=0,"",SUM(V76:X76)) | Z76: =IF(COUNT(V76:X76)=0,"",IFERROR(Y76/$Y$16*$Z$16,"")) | AA76: =IF(Z76="","",Z76*$AA$16) | AE76: =IF(COUNT(AB76:AD76)=0,"",SUM(AB76:AD76)) | AF76: =IF(COUNT(AB76:AD76)=0,"",IFERROR(AE76/$AE$16*$AF$16,"")) | AG76: =IF(AF76="","",AF76*$AG$16) | AK76: =IF(COUNT(AH76:AJ76)=0,"",SUM(AH76:AJ76)) | AL76: =IF(COUNT(AH76:AJ76)=0,"",IFERROR(AK76/$AK$16*$AL$16,"")) | AM76: =IF(AL76="","",AL76*$AM$16) | AQ76: =IF(AN76="","",IFERROR(AN76/$AN$16*$AQ$16,"")) | AR76: =IF(AO76="","",IFERROR(AO76/$AO$16*$AR$16,"")) | AS76: =IF(AP76="","",IFERROR(AP76/$AP$16*$AS$16,"")) | AT76: =IF(COUNT(AN76:AP76)=0,"",SUM(AQ76:AS76)) | AU76: =IF(AT76="","",AT76*$AU$16) | AV76: =IF(COUNT(F76:J76,N76:R76,V76:X76,AB76:AD76,AH76:AJ76,AN76:AP76)=0,"",SUM(M76,U76,AA76,AG76,AM76,AU76)) | AW76: =IF(AV76="","",IFERROR(INDEX(HELPER!$D$8:$D$48,IF(AV76>=HELPER!$B$8,1,MATCH(AV76,HELPER!$B$8:$B$48,-1)+1)),"")) | AX76: =IF(AW76="","",IFERROR(VLOOKUP(AW76,HELPER!$F$8:$G$48,2,FALSE),""))
B77: 8 | C77: =IF('INPUT DATA'!N18="","",'INPUT DATA'!N18) | K77: =IF(COUNT($F77:$J77)=0,"",SUM($F77:$J77)) | L77: =IF(COUNT(F77:J77)=0,"",IFERROR(K77/$K$16*$L$16,"")) | M77: =IF(L77="","",L77*$M$16) | S77: =IF(COUNT($N77:$R77)=0,"",SUM($N77:$R77)) | T77: =IF(COUNT(N77:R77)=0,"",IFERROR(S77/$S$16*$T$16,"")) | U77: =IF(T77="","",T77*$U$16) | Y77: =IF(COUNT(V77:X77)=0,"",SUM(V77:X77)) | Z77: =IF(COUNT(V77:X77)=0,"",IFERROR(Y77/$Y$16*$Z$16,"")) | AA77: =IF(Z77="","",Z77*$AA$16) | AE77: =IF(COUNT(AB77:AD77)=0,"",SUM(AB77:AD77)) | AF77: =IF(COUNT(AB77:AD77)=0,"",IFERROR(AE77/$AE$16*$AF$16,"")) | AG77: =IF(AF77="","",AF77*$AG$16) | AK77: =IF(COUNT(AH77:AJ77)=0,"",SUM(AH77:AJ77)) | AL77: =IF(COUNT(AH77:AJ77)=0,"",IFERROR(AK77/$AK$16*$AL$16,"")) | AM77: =IF(AL77="","",AL77*$AM$16) | AQ77: =IF(AN77="","",IFERROR(AN77/$AN$16*$AQ$16,"")) | AR77: =IF(AO77="","",IFERROR(AO77/$AO$16*$AR$16,"")) | AS77: =IF(AP77="","",IFERROR(AP77/$AP$16*$AS$16,"")) | AT77: =IF(COUNT(AN77:AP77)=0,"",SUM(AQ77:AS77)) | AU77: =IF(AT77="","",AT77*$AU$16) | AV77: =IF(COUNT(F77:J77,N77:R77,V77:X77,AB77:AD77,AH77:AJ77,AN77:AP77)=0,"",SUM(M77,U77,AA77,AG77,AM77,AU77)) | AW77: =IF(AV77="","",IFERROR(INDEX(HELPER!$D$8:$D$48,IF(AV77>=HELPER!$B$8,1,MATCH(AV77,HELPER!$B$8:$B$48,-1)+1)),"")) | AX77: =IF(AW77="","",IFERROR(VLOOKUP(AW77,HELPER!$F$8:$G$48,2,FALSE),""))
B78: 9 | C78: =IF('INPUT DATA'!N19="","",'INPUT DATA'!N19) | K78: =IF(COUNT($F78:$J78)=0,"",SUM($F78:$J78)) | L78: =IF(COUNT(F78:J78)=0,"",IFERROR(K78/$K$16*$L$16,"")) | M78: =IF(L78="","",L78*$M$16) | S78: =IF(COUNT($N78:$R78)=0,"",SUM($N78:$R78)) | T78: =IF(COUNT(N78:R78)=0,"",IFERROR(S78/$S$16*$T$16,"")) | U78: =IF(T78="","",T78*$U$16) | Y78: =IF(COUNT(V78:X78)=0,"",SUM(V78:X78)) | Z78: =IF(COUNT(V78:X78)=0,"",IFERROR(Y78/$Y$16*$Z$16,"")) | AA78: =IF(Z78="","",Z78*$AA$16) | AE78: =IF(COUNT(AB78:AD78)=0,"",SUM(AB78:AD78)) | AF78: =IF(COUNT(AB78:AD78)=0,"",IFERROR(AE78/$AE$16*$AF$16,"")) | AG78: =IF(AF78="","",AF78*$AG$16) | AK78: =IF(COUNT(AH78:AJ78)=0,"",SUM(AH78:AJ78)) | AL78: =IF(COUNT(AH78:AJ78)=0,"",IFERROR(AK78/$AK$16*$AL$16,"")) | AM78: =IF(AL78="","",AL78*$AM$16) | AQ78: =IF(AN78="","",IFERROR(AN78/$AN$16*$AQ$16,"")) | AR78: =IF(AO78="","",IFERROR(AO78/$AO$16*$AR$16,"")) | AS78: =IF(AP78="","",IFERROR(AP78/$AP$16*$AS$16,"")) | AT78: =IF(COUNT(AN78:AP78)=0,"",SUM(AQ78:AS78)) | AU78: =IF(AT78="","",AT78*$AU$16) | AV78: =IF(COUNT(F78:J78,N78:R78,V78:X78,AB78:AD78,AH78:AJ78,AN78:AP78)=0,"",SUM(M78,U78,AA78,AG78,AM78,AU78)) | AW78: =IF(AV78="","",IFERROR(INDEX(HELPER!$D$8:$D$48,IF(AV78>=HELPER!$B$8,1,MATCH(AV78,HELPER!$B$8:$B$48,-1)+1)),"")) | AX78: =IF(AW78="","",IFERROR(VLOOKUP(AW78,HELPER!$F$8:$G$48,2,FALSE),""))
B79: 10 | C79: =IF('INPUT DATA'!N20="","",'INPUT DATA'!N20) | K79: =IF(COUNT($F79:$J79)=0,"",SUM($F79:$J79)) | L79: =IF(COUNT(F79:J79)=0,"",IFERROR(K79/$K$16*$L$16,"")) | M79: =IF(L79="","",L79*$M$16) | S79: =IF(COUNT($N79:$R79)=0,"",SUM($N79:$R79)) | T79: =IF(COUNT(N79:R79)=0,"",IFERROR(S79/$S$16*$T$16,"")) | U79: =IF(T79="","",T79*$U$16) | Y79: =IF(COUNT(V79:X79)=0,"",SUM(V79:X79)) | Z79: =IF(COUNT(V79:X79)=0,"",IFERROR(Y79/$Y$16*$Z$16,"")) | AA79: =IF(Z79="","",Z79*$AA$16) | AE79: =IF(COUNT(AB79:AD79)=0,"",SUM(AB79:AD79)) | AF79: =IF(COUNT(AB79:AD79)=0,"",IFERROR(AE79/$AE$16*$AF$16,"")) | AG79: =IF(AF79="","",AF79*$AG$16) | AK79: =IF(COUNT(AH79:AJ79)=0,"",SUM(AH79:AJ79)) | AL79: =IF(COUNT(AH79:AJ79)=0,"",IFERROR(AK79/$AK$16*$AL$16,"")) | AM79: =IF(AL79="","",AL79*$AM$16) | AQ79: =IF(AN79="","",IFERROR(AN79/$AN$16*$AQ$16,"")) | AR79: =IF(AO79="","",IFERROR(AO79/$AO$16*$AR$16,"")) | AS79: =IF(AP79="","",IFERROR(AP79/$AP$16*$AS$16,"")) | AT79: =IF(COUNT(AN79:AP79)=0,"",SUM(AQ79:AS79)) | AU79: =IF(AT79="","",AT79*$AU$16) | AV79: =IF(COUNT(F79:J79,N79:R79,V79:X79,AB79:AD79,AH79:AJ79,AN79:AP79)=0,"",SUM(M79,U79,AA79,AG79,AM79,AU79)) | AW79: =IF(AV79="","",IFERROR(INDEX(HELPER!$D$8:$D$48,IF(AV79>=HELPER!$B$8,1,MATCH(AV79,HELPER!$B$8:$B$48,-1)+1)),"")) | AX79: =IF(AW79="","",IFERROR(VLOOKUP(AW79,HELPER!$F$8:$G$48,2,FALSE),""))
B80: 11 | C80: =IF('INPUT DATA'!N21="","",'INPUT DATA'!N21) | K80: =IF(COUNT($F80:$J80)=0,"",SUM($F80:$J80)) | L80: =IF(COUNT(F80:J80)=0,"",IFERROR(K80/$K$16*$L$16,"")) | M80: =IF(L80="","",L80*$M$16) | S80: =IF(COUNT($N80:$R80)=0,"",SUM($N80:$R80)) | T80: =IF(COUNT(N80:R80)=0,"",IFERROR(S80/$S$16*$T$16,"")) | U80: =IF(T80="","",T80*$U$16) | Y80: =IF(COUNT(V80:X80)=0,"",SUM(V80:X80)) | Z80: =IF(COUNT(V80:X80)=0,"",IFERROR(Y80/$Y$16*$Z$16,"")) | AA80: =IF(Z80="","",Z80*$AA$16) | AE80: =IF(COUNT(AB80:AD80)=0,"",SUM(AB80:AD80)) | AF80: =IF(COUNT(AB80:AD80)=0,"",IFERROR(AE80/$AE$16*$AF$16,"")) | AG80: =IF(AF80="","",AF80*$AG$16) | AK80: =IF(COUNT(AH80:AJ80)=0,"",SUM(AH80:AJ80)) | AL80: =IF(COUNT(AH80:AJ80)=0,"",IFERROR(AK80/$AK$16*$AL$16,"")) | AM80: =IF(AL80="","",AL80*$AM$16) | AQ80: =IF(AN80="","",IFERROR(AN80/$AN$16*$AQ$16,"")) | AR80: =IF(AO80="","",IFERROR(AO80/$AO$16*$AR$16,"")) | AS80: =IF(AP80="","",IFERROR(AP80/$AP$16*$AS$16,"")) | AT80: =IF(COUNT(AN80:AP80)=0,"",SUM(AQ80:AS80)) | AU80: =IF(AT80="","",AT80*$AU$16) | AV80: =IF(COUNT(F80:J80,N80:R80,V80:X80,AB80:AD80,AH80:AJ80,AN80:AP80)=0,"",SUM(M80,U80,AA80,AG80,AM80,AU80)) | AW80: =IF(AV80="","",IFERROR(INDEX(HELPER!$D$8:$D$48,IF(AV80>=HELPER!$B$8,1,MATCH(AV80,HELPER!$B$8:$B$48,-1)+1)),"")) | AX80: =IF(AW80="","",IFERROR(VLOOKUP(AW80,HELPER!$F$8:$G$48,2,FALSE),""))
B81: 12 | C81: =IF('INPUT DATA'!N22="","",'INPUT DATA'!N22) | K81: =IF(COUNT($F81:$J81)=0,"",SUM($F81:$J81)) | L81: =IF(COUNT(F81:J81)=0,"",IFERROR(K81/$K$16*$L$16,"")) | M81: =IF(L81="","",L81*$M$16) | S81: =IF(COUNT($N81:$R81)=0,"",SUM($N81:$R81)) | T81: =IF(COUNT(N81:R81)=0,"",IFERROR(S81/$S$16*$T$16,"")) | U81: =IF(T81="","",T81*$U$16) | Y81: =IF(COUNT(V81:X81)=0,"",SUM(V81:X81)) | Z81: =IF(COUNT(V81:X81)=0,"",IFERROR(Y81/$Y$16*$Z$16,"")) | AA81: =IF(Z81="","",Z81*$AA$16) | AE81: =IF(COUNT(AB81:AD81)=0,"",SUM(AB81:AD81)) | AF81: =IF(COUNT(AB81:AD81)=0,"",IFERROR(AE81/$AE$16*$AF$16,"")) | AG81: =IF(AF81="","",AF81*$AG$16) | AK81: =IF(COUNT(AH81:AJ81)=0,"",SUM(AH81:AJ81)) | AL81: =IF(COUNT(AH81:AJ81)=0,"",IFERROR(AK81/$AK$16*$AL$16,"")) | AM81: =IF(AL81="","",AL81*$AM$16) | AQ81: =IF(AN81="","",IFERROR(AN81/$AN$16*$AQ$16,"")) | AR81: =IF(AO81="","",IFERROR(AO81/$AO$16*$AR$16,"")) | AS81: =IF(AP81="","",IFERROR(AP81/$AP$16*$AS$16,"")) | AT81: =IF(COUNT(AN81:AP81)=0,"",SUM(AQ81:AS81)) | AU81: =IF(AT81="","",AT81*$AU$16) | AV81: =IF(COUNT(F81:J81,N81:R81,V81:X81,AB81:AD81,AH81:AJ81,AN81:AP81)=0,"",SUM(M81,U81,AA81,AG81,AM81,AU81)) | AW81: =IF(AV81="","",IFERROR(INDEX(HELPER!$D$8:$D$48,IF(AV81>=HELPER!$B$8,1,MATCH(AV81,HELPER!$B$8:$B$48,-1)+1)),"")) | AX81: =IF(AW81="","",IFERROR(VLOOKUP(AW81,HELPER!$F$8:$G$48,2,FALSE),""))
... B119: 50 | C119: =IF('INPUT DATA'!N60="","",'INPUT DATA'!N60) | K119: =IF(COUNT($F119:$J119)=0,"",SUM($F119:$J119)) | L119: =IF(COUNT(F119:J119)=0,"",IFERROR(K119/$K$16*$L$16,"")) | M119: =IF(L119="","",L119*$M$16) | S119: =IF(COUNT($N119:$R119)=0,"",SUM($N119:$R119)) | T119: =IF(COUNT(N119:R119)=0,"",IFERROR(S119/$S$16*$T$16,"")) | U119: =IF(T119="","",T119*$U$16) | Y119: =IF(COUNT(V119:X119)=0,"",SUM(V119:X119)) | Z119: =IF(COUNT(V119:X119)=0,"",IFERROR(Y119/$Y$16*$Z$16,"")) | AA119: =IF(Z119="","",Z119*$AA$16) | AE119: =IF(COUNT(AB119:AD119)=0,"",SUM(AB119:AD119)) | AF119: =IF(COUNT(AB119:AD119)=0,"",IFERROR(AE119/$AE$16*$AF$16,"")) | AG119: =IF(AF119="","",AF119*$AG$16) | AK119: =IF(COUNT(AH119:AJ119)=0,"",SUM(AH119:AJ119)) | AL119: =IF(COUNT(AH119:AJ119)=0,"",IFERROR(AK119/$AK$16*$AL$16,"")) | AM119: =IF(AL119="","",AL119*$AM$16) | AQ119: =IF(AN119="","",IFERROR(AN119/$AN$16*$AQ$16,"")) | AR119: =IF(AO119="","",IFERROR(AO119/$AO$16*$AR$16,"")) | AS119: =IF(AP119="","",IFERROR(AP119/$AP$16*$AS$16,"")) | AT119: =IF(COUNT(AN119:AP119)=0,"",SUM(AQ119:AS119)) | AU119: =IF(AT119="","",AT119*$AU$16) | AV119: =IF(COUNT(F119:J119,N119:R119,V119:X119,AB119:AD119,AH119:AJ119,AN119:AP119)=0,"",SUM(M119,U119,AA119,AG119,AM119,AU119)) | AW119: =IF(AV119="","",IFERROR(INDEX(HELPER!$D$8:$D$48,IF(AV119>=HELPER!$B$8,1,MATCH(AV119,HELPER!$B$8:$B$48,-1)+1)),"")) | AX119: =IF(AW119="","",IFERROR(VLOOKUP(AW119,HELPER!$F$8:$G$48,2,FALSE),""))

Sheet TERM 2
B2: CLASS RECORD
E5: REGION | F5: =IF('INPUT DATA'!E10="","",'INPUT DATA'!E10) -> Region V | R5: DIVISION | S5: =IF('INPUT DATA'!E11="","",'INPUT DATA'!E11) -> Masbate | AH5: SCHOOL ID | AI5: =IF('INPUT DATA'!E13="","",'INPUT DATA'!E13) -> 113481
E7: SCHOOL NAME | F7: =IF('INPUT DATA'!E14="","",'INPUT DATA'!E14) -> Danao Elementary School | AH7: SCHOOL YEAR | AI7: =IF('INPUT DATA'!E15="","",'INPUT DATA'!E15) -> 2026-2027
B10: SECOND TERM | F10: GRADE LEVEL | L10: =IF('INPUT DATA'!E25="","",'INPUT DATA'!E25) -> 2 | V10: TEACHER | AB10: =IF('INPUT DATA'!E23="","",'INPUT DATA'!E23) -> Ronel C. Ramos | AP10: SUBJECT | AR10: =IF('INPUT DATA'!E24="","",'INPUT DATA'!E24) -> GMRC
F11: SECTION | L11: =IF('INPUT DATA'!E26="","",'INPUT DATA'!E26) -> Gumamela
F12: WRITTEN / ORAL WORKS (WWs) | V12: PRODUCT / PERFORMANCE TASKS (PTs) | AN12: EXAMINATIONS (EXs) | AV12: Initial Grade | AW12: Term Grade | AX12: Descriptor
F14: COGNITIVE DOMAIN | N14: AFFECTIVE DOMAIN | V14: COGNITIVE DOMAIN | AB14: AFFECTIVE DOMAIN | AH14: BEHAVIORAL DOMAIN
F15: 1 | G15: 2 | H15: 3 | I15: 4 | J15: 5 | K15: Total | L15: PS | M15: WS | N15: 1 | O15: 2 | P15: 3 | Q15: 4 | R15: 5 | S15: Total | T15: PS | U15: WS | V15: 1 | W15: 2 | X15: 3 | Y15: Total | Z15: PS | AA15: WS | AB15: 1 | AC15: 2 | AD15: 3 | AE15: Total | AF15: PS | AG15: WS | AH15: 1 | AI15: 2 | AJ15: 3 | AK15: Total | AL15: PS | AM15: WS | AN15: ST1 | AO15: ST2 | AP15: TE | AQ15: WS ST1 | AR15: WS ST2 | AS15: WS TE | AT15: PS | AU15: WS
B16: HIGHEST POSSIBLE SCORE | K16: =IF(COUNT(F16:J16)=0,"",SUM(F16:J16)) | L16: 100 | M16: 0.1 | S16: =IF(COUNT(N16:R16)=0,"",SUM(N16:R16)) | T16: 100 | U16: 0.1 | Y16: =IF(COUNT(V16:X16)=0,"",SUM(V16:X16)) | Z16: 100 | AA16: 0.1 | AE16: =IF(COUNT(AB16:AD16)=0,"",SUM(AB16:AD16)) | AF16: 100 | AG16: 0.1 | AK16: =IF(COUNT(AH16:AJ16)=0,"",SUM(AH16:AJ16)) | AL16: 100 | AM16: 0.3 | AQ16: 30 | AR16: 30 | AS16: 40 | AT16: 100 | AU16: 0.3
B17: LEARNERS' NAMES
B18: MALE
B19: 1 | C19: =IF('INPUT DATA'!K11="","",'INPUT DATA'!K11) | K19: =IF(COUNT($F19:$J19)=0,"",SUM($F19:$J19)) | L19: =IF(COUNT(F19:J19)=0,"",IFERROR(K19/$K$16*$L$16,"")) | M19: =IF(L19="","",L19*$M$16) | S19: =IF(COUNT($N19:$R19)=0,"",SUM($N19:$R19)) | T19: =IF(COUNT(N19:R19)=0,"",IFERROR(S19/$S$16*$T$16,"")) | U19: =IF(T19="","",T19*$U$16) | Y19: =IF(COUNT(V19:X19)=0,"",SUM(V19:X19)) | Z19: =IF(COUNT(V19:X19)=0,"",IFERROR(Y19/$Y$16*$Z$16,"")) | AA19: =IF(Z19="","",Z19*$AA$16) | AE19: =IF(COUNT(AB19:AD19)=0,"",SUM(AB19:AD19)) | AF19: =IF(COUNT(AB19:AD19)=0,"",IFERROR(AE19/$AE$16*$AF$16,"")) | AG19: =IF(AF19="","",AF19*$AG$16) | AK19: =IF(COUNT(AH19:AJ19)=0,"",SUM(AH19:AJ19)) | AL19: =IF(COUNT(AH19:AJ19)=0,"",IFERROR(AK19/$AK$16*$AL$16,"")) | AM19: =IF(AL19="","",AL19*$AM$16) | AQ19: =IF(AN19="","",IFERROR(AN19/$AN$16*$AQ$16,"")) | AR19: =IF(AO19="","",IFERROR(AO19/$AO$16*$AR$16,"")) | AS19: =IF(AP19="","",IFERROR(AP19/$AP$16*$AS$16,"")) | AT19: =IF(COUNT(AN19:AP19)=0,"",SUM(AQ19:AS19)) | AU19: =IF(AT19="","",AT19*$AU$16) | AV19: =IF(COUNT(F19:J19,N19:R19,V19:X19,AB19:AD19,AH19:AJ19,AN19:AP19)=0,"",SUM(M19,U19,AA19,AG19,AM19,AU19)) | AW19: =IF(AV19="","",IFERROR(INDEX(HELPER!$D$8:$D$48,IF(AV19>=HELPER!$B$8,1,MATCH(AV19,HELPER!$B$8:$B$48,-1)+1)),"")) | AX19: =IF(AW19="","",IFERROR(VLOOKUP(AW19,HELPER!$F$8:$G$48,2,FALSE),""))
B20: 2 | C20: =IF('INPUT DATA'!K12="","",'INPUT DATA'!K12) | K20: =IF(COUNT($F20:$J20)=0,"",SUM($F20:$J20)) | L20: =IF(COUNT(F20:J20)=0,"",IFERROR(K20/$K$16*$L$16,"")) | M20: =IF(L20="","",L20*$M$16) | S20: =IF(COUNT($N20:$R20)=0,"",SUM($N20:$R20)) | T20: =IF(COUNT(N20:R20)=0,"",IFERROR(S20/$S$16*$T$16,"")) | U20: =IF(T20="","",T20*$U$16) | Y20: =IF(COUNT(V20:X20)=0,"",SUM(V20:X20)) | Z20: =IF(COUNT(V20:X20)=0,"",IFERROR(Y20/$Y$16*$Z$16,"")) | AA20: =IF(Z20="","",Z20*$AA$16) | AE20: =IF(COUNT(AB20:AD20)=0,"",SUM(AB20:AD20)) | AF20: =IF(COUNT(AB20:AD20)=0,"",IFERROR(AE20/$AE$16*$AF$16,"")) | AG20: =IF(AF20="","",AF20*$AG$16) | AK20: =IF(COUNT(AH20:AJ20)=0,"",SUM(AH20:AJ20)) | AL20: =IF(COUNT(AH20:AJ20)=0,"",IFERROR(AK20/$AK$16*$AL$16,"")) | AM20: =IF(AL20="","",AL20*$AM$16) | AQ20: =IF(AN20="","",IFERROR(AN20/$AN$16*$AQ$16,"")) | AR20: =IF(AO20="","",IFERROR(AO20/$AO$16*$AR$16,"")) | AS20: =IF(AP20="","",IFERROR(AP20/$AP$16*$AS$16,"")) | AT20: =IF(COUNT(AN20:AP20)=0,"",SUM(AQ20:AS20)) | AU20: =IF(AT20="","",AT20*$AU$16) | AV20: =IF(COUNT(F20:J20,N20:R20,V20:X20,AB20:AD20,AH20:AJ20,AN20:AP20)=0,"",SUM(M20,U20,AA20,AG20,AM20,AU20)) | AW20: =IF(AV20="","",IFERROR(INDEX(HELPER!$D$8:$D$48,IF(AV20>=HELPER!$B$8,1,MATCH(AV20,HELPER!$B$8:$B$48,-1)+1)),"")) | AX20: =IF(AW20="","",IFERROR(VLOOKUP(AW20,HELPER!$F$8:$G$48,2,FALSE),""))
B21: 3 | C21: =IF('INPUT DATA'!K13="","",'INPUT DATA'!K13) | K21: =IF(COUNT($F21:$J21)=0,"",SUM($F21:$J21)) | L21: =IF(COUNT(F21:J21)=0,"",IFERROR(K21/$K$16*$L$16,"")) | M21: =IF(L21="","",L21*$M$16) | S21: =IF(COUNT($N21:$R21)=0,"",SUM($N21:$R21)) | T21: =IF(COUNT(N21:R21)=0,"",IFERROR(S21/$S$16*$T$16,"")) | U21: =IF(T21="","",T21*$U$16) | Y21: =IF(COUNT(V21:X21)=0,"",SUM(V21:X21)) | Z21: =IF(COUNT(V21:X21)=0,"",IFERROR(Y21/$Y$16*$Z$16,"")) | AA21: =IF(Z21="","",Z21*$AA$16) | AE21: =IF(COUNT(AB21:AD21)=0,"",SUM(AB21:AD21)) | AF21: =IF(COUNT(AB21:AD21)=0,"",IFERROR(AE21/$AE$16*$AF$16,"")) | AG21: =IF(AF21="","",AF21*$AG$16) | AK21: =IF(COUNT(AH21:AJ21)=0,"",SUM(AH21:AJ21)) | AL21: =IF(COUNT(AH21:AJ21)=0,"",IFERROR(AK21/$AK$16*$AL$16,"")) | AM21: =IF(AL21="","",AL21*$AM$16) | AQ21: =IF(AN21="","",IFERROR(AN21/$AN$16*$AQ$16,"")) | AR21: =IF(AO21="","",IFERROR(AO21/$AO$16*$AR$16,"")) | AS21: =IF(AP21="","",IFERROR(AP21/$AP$16*$AS$16,"")) | AT21: =IF(COUNT(AN21:AP21)=0,"",SUM(AQ21:AS21)) | AU21: =IF(AT21="","",AT21*$AU$16) | AV21: =IF(COUNT(F21:J21,N21:R21,V21:X21,AB21:AD21,AH21:AJ21,AN21:AP21)=0,"",SUM(M21,U21,AA21,AG21,AM21,AU21)) | AW21: =IF(AV21="","",IFERROR(INDEX(HELPER!$D$8:$D$48,IF(AV21>=HELPER!$B$8,1,MATCH(AV21,HELPER!$B$8:$B$48,-1)+1)),"")) | AX21: =IF(AW21="","",IFERROR(VLOOKUP(AW21,HELPER!$F$8:$G$48,2,FALSE),""))
B22: 4 | C22: =IF('INPUT DATA'!K14="","",'INPUT DATA'!K14) | K22: =IF(COUNT($F22:$J22)=0,"",SUM($F22:$J22)) | L22: =IF(COUNT(F22:J22)=0,"",IFERROR(K22/$K$16*$L$16,"")) | M22: =IF(L22="","",L22*$M$16) | S22: =IF(COUNT($N22:$R22)=0,"",SUM($N22:$R22)) | T22: =IF(COUNT(N22:R22)=0,"",IFERROR(S22/$S$16*$T$16,"")) | U22: =IF(T22="","",T22*$U$16) | Y22: =IF(COUNT(V22:X22)=0,"",SUM(V22:X22)) | Z22: =IF(COUNT(V22:X22)=0,"",IFERROR(Y22/$Y$16*$Z$16,"")) | AA22: =IF(Z22="","",Z22*$AA$16) | AE22: =IF(COUNT(AB22:AD22)=0,"",SUM(AB22:AD22)) | AF22: =IF(COUNT(AB22:AD22)=0,"",IFERROR(AE22/$AE$16*$AF$16,"")) | AG22: =IF(AF22="","",AF22*$AG$16) | AK22: =IF(COUNT(AH22:AJ22)=0,"",SUM(AH22:AJ22)) | AL22: =IF(COUNT(AH22:AJ22)=0,"",IFERROR(AK22/$AK$16*$AL$16,"")) | AM22: =IF(AL22="","",AL22*$AM$16) | AQ22: =IF(AN22="","",IFERROR(AN22/$AN$16*$AQ$16,"")) | AR22: =IF(AO22="","",IFERROR(AO22/$AO$16*$AR$16,"")) | AS22: =IF(AP22="","",IFERROR(AP22/$AP$16*$AS$16,"")) | AT22: =IF(COUNT(AN22:AP22)=0,"",SUM(AQ22:AS22)) | AU22: =IF(AT22="","",AT22*$AU$16) | AV22: =IF(COUNT(F22:J22,N22:R22,V22:X22,AB22:AD22,AH22:AJ22,AN22:AP22)=0,"",SUM(M22,U22,AA22,AG22,AM22,AU22)) | AW22: =IF(AV22="","",IFERROR(INDEX(HELPER!$D$8:$D$48,IF(AV22>=HELPER!$B$8,1,MATCH(AV22,HELPER!$B$8:$B$48,-1)+1)),"")) | AX22: =IF(AW22="","",IFERROR(VLOOKUP(AW22,HELPER!$F$8:$G$48,2,FALSE),""))
B23: 5 | C23: =IF('INPUT DATA'!K15="","",'INPUT DATA'!K15) | K23: =IF(COUNT($F23:$J23)=0,"",SUM($F23:$J23)) | L23: =IF(COUNT(F23:J23)=0,"",IFERROR(K23/$K$16*$L$16,"")) | M23: =IF(L23="","",L23*$M$16) | S23: =IF(COUNT($N23:$R23)=0,"",SUM($N23:$R23)) | T23: =IF(COUNT(N23:R23)=0,"",IFERROR(S23/$S$16*$T$16,"")) | U23: =IF(T23="","",T23*$U$16) | Y23: =IF(COUNT(V23:X23)=0,"",SUM(V23:X23)) | Z23: =IF(COUNT(V23:X23)=0,"",IFERROR(Y23/$Y$16*$Z$16,"")) | AA23: =IF(Z23="","",Z23*$AA$16) | AE23: =IF(COUNT(AB23:AD23)=0,"",SUM(AB23:AD23)) | AF23: =IF(COUNT(AB23:AD23)=0,"",IFERROR(AE23/$AE$16*$AF$16,"")) | AG23: =IF(AF23="","",AF23*$AG$16) | AK23: =IF(COUNT(AH23:AJ23)=0,"",SUM(AH23:AJ23)) | AL23: =IF(COUNT(AH23:AJ23)=0,"",IFERROR(AK23/$AK$16*$AL$16,"")) | AM23: =IF(AL23="","",AL23*$AM$16) | AQ23: =IF(AN23="","",IFERROR(AN23/$AN$16*$AQ$16,"")) | AR23: =IF(AO23="","",IFERROR(AO23/$AO$16*$AR$16,"")) | AS23: =IF(AP23="","",IFERROR(AP23/$AP$16*$AS$16,"")) | AT23: =IF(COUNT(AN23:AP23)=0,"",SUM(AQ23:AS23)) | AU23: =IF(AT23="","",AT23*$AU$16) | AV23: =IF(COUNT(F23:J23,N23:R23,V23:X23,AB23:AD23,AH23:AJ23,AN23:AP23)=0,"",SUM(M23,U23,AA23,AG23,AM23,AU23)) | AW23: =IF(AV23="","",IFERROR(INDEX(HELPER!$D$8:$D$48,IF(AV23>=HELPER!$B$8,1,MATCH(AV23,HELPER!$B$8:$B$48,-1)+1)),"")) | AX23: =IF(AW23="","",IFERROR(VLOOKUP(AW23,HELPER!$F$8:$G$48,2,FALSE),""))
B24: 6 | C24: =IF('INPUT DATA'!K16="","",'INPUT DATA'!K16) | K24: =IF(COUNT($F24:$J24)=0,"",SUM($F24:$J24)) | L24: =IF(COUNT(F24:J24)=0,"",IFERROR(K24/$K$16*$L$16,"")) | M24: =IF(L24="","",L24*$M$16) | S24: =IF(COUNT($N24:$R24)=0,"",SUM($N24:$R24)) | T24: =IF(COUNT(N24:R24)=0,"",IFERROR(S24/$S$16*$T$16,"")) | U24: =IF(T24="","",T24*$U$16) | Y24: =IF(COUNT(V24:X24)=0,"",SUM(V24:X24)) | Z24: =IF(COUNT(V24:X24)=0,"",IFERROR(Y24/$Y$16*$Z$16,"")) | AA24: =IF(Z24="","",Z24*$AA$16) | AE24: =IF(COUNT(AB24:AD24)=0,"",SUM(AB24:AD24)) | AF24: =IF(COUNT(AB24:AD24)=0,"",IFERROR(AE24/$AE$16*$AF$16,"")) | AG24: =IF(AF24="","",AF24*$AG$16) | AK24: =IF(COUNT(AH24:AJ24)=0,"",SUM(AH24:AJ24)) | AL24: =IF(COUNT(AH24:AJ24)=0,"",IFERROR(AK24/$AK$16*$AL$16,"")) | AM24: =IF(AL24="","",AL24*$AM$16) | AQ24: =IF(AN24="","",IFERROR(AN24/$AN$16*$AQ$16,"")) | AR24: =IF(AO24="","",IFERROR(AO24/$AO$16*$AR$16,"")) | AS24: =IF(AP24="","",IFERROR(AP24/$AP$16*$AS$16,"")) | AT24: =IF(COUNT(AN24:AP24)=0,"",SUM(AQ24:AS24)) | AU24: =IF(AT24="","",AT24*$AU$16) | AV24: =IF(COUNT(F24:J24,N24:R24,V24:X24,AB24:AD24,AH24:AJ24,AN24:AP24)=0,"",SUM(M24,U24,AA24,AG24,AM24,AU24)) | AW24: =IF(AV24="","",IFERROR(INDEX(HELPER!$D$8:$D$48,IF(AV24>=HELPER!$B$8,1,MATCH(AV24,HELPER!$B$8:$B$48,-1)+1)),"")) | AX24: =IF(AW24="","",IFERROR(VLOOKUP(AW24,HELPER!$F$8:$G$48,2,FALSE),""))
B25: 7 | C25: =IF('INPUT DATA'!K17="","",'INPUT DATA'!K17) | K25: =IF(COUNT($F25:$J25)=0,"",SUM($F25:$J25)) | L25: =IF(COUNT(F25:J25)=0,"",IFERROR(K25/$K$16*$L$16,"")) | M25: =IF(L25="","",L25*$M$16) | S25: =IF(COUNT($N25:$R25)=0,"",SUM($N25:$R25)) | T25: =IF(COUNT(N25:R25)=0,"",IFERROR(S25/$S$16*$T$16,"")) | U25: =IF(T25="","",T25*$U$16) | Y25: =IF(COUNT(V25:X25)=0,"",SUM(V25:X25)) | Z25: =IF(COUNT(V25:X25)=0,"",IFERROR(Y25/$Y$16*$Z$16,"")) | AA25: =IF(Z25="","",Z25*$AA$16) | AE25: =IF(COUNT(AB25:AD25)=0,"",SUM(AB25:AD25)) | AF25: =IF(COUNT(AB25:AD25)=0,"",IFERROR(AE25/$AE$16*$AF$16,"")) | AG25: =IF(AF25="","",AF25*$AG$16) | AK25: =IF(COUNT(AH25:AJ25)=0,"",SUM(AH25:AJ25)) | AL25: =IF(COUNT(AH25:AJ25)=0,"",IFERROR(AK25/$AK$16*$AL$16,"")) | AM25: =IF(AL25="","",AL25*$AM$16) | AQ25: =IF(AN25="","",IFERROR(AN25/$AN$16*$AQ$16,"")) | AR25: =IF(AO25="","",IFERROR(AO25/$AO$16*$AR$16,"")) | AS25: =IF(AP25="","",IFERROR(AP25/$AP$16*$AS$16,"")) | AT25: =IF(COUNT(AN25:AP25)=0,"",SUM(AQ25:AS25)) | AU25: =IF(AT25="","",AT25*$AU$16) | AV25: =IF(COUNT(F25:J25,N25:R25,V25:X25,AB25:AD25,AH25:AJ25,AN25:AP25)=0,"",SUM(M25,U25,AA25,AG25,AM25,AU25)) | AW25: =IF(AV25="","",IFERROR(INDEX(HELPER!$D$8:$D$48,IF(AV25>=HELPER!$B$8,1,MATCH(AV25,HELPER!$B$8:$B$48,-1)+1)),"")) | AX25: =IF(AW25="","",IFERROR(VLOOKUP(AW25,HELPER!$F$8:$G$48,2,FALSE),""))
B26: 8 | C26: =IF('INPUT DATA'!K18="","",'INPUT DATA'!K18) | K26: =IF(COUNT($F26:$J26)=0,"",SUM($F26:$J26)) | L26: =IF(COUNT(F26:J26)=0,"",IFERROR(K26/$K$16*$L$16,"")) | M26: =IF(L26="","",L26*$M$16) | S26: =IF(COUNT($N26:$R26)=0,"",SUM($N26:$R26)) | T26: =IF(COUNT(N26:R26)=0,"",IFERROR(S26/$S$16*$T$16,"")) | U26: =IF(T26="","",T26*$U$16) | Y26: =IF(COUNT(V26:X26)=0,"",SUM(V26:X26)) | Z26: =IF(COUNT(V26:X26)=0,"",IFERROR(Y26/$Y$16*$Z$16,"")) | AA26: =IF(Z26="","",Z26*$AA$16) | AE26: =IF(COUNT(AB26:AD26)=0,"",SUM(AB26:AD26)) | AF26: =IF(COUNT(AB26:AD26)=0,"",IFERROR(AE26/$AE$16*$AF$16,"")) | AG26: =IF(AF26="","",AF26*$AG$16) | AK26: =IF(COUNT(AH26:AJ26)=0,"",SUM(AH26:AJ26)) | AL26: =IF(COUNT(AH26:AJ26)=0,"",IFERROR(AK26/$AK$16*$AL$16,"")) | AM26: =IF(AL26="","",AL26*$AM$16) | AQ26: =IF(AN26="","",IFERROR(AN26/$AN$16*$AQ$16,"")) | AR26: =IF(AO26="","",IFERROR(AO26/$AO$16*$AR$16,"")) | AS26: =IF(AP26="","",IFERROR(AP26/$AP$16*$AS$16,"")) | AT26: =IF(COUNT(AN26:AP26)=0,"",SUM(AQ26:AS26)) | AU26: =IF(AT26="","",AT26*$AU$16) | AV26: =IF(COUNT(F26:J26,N26:R26,V26:X26,AB26:AD26,AH26:AJ26,AN26:AP26)=0,"",SUM(M26,U26,AA26,AG26,AM26,AU26)) | AW26: =IF(AV26="","",IFERROR(INDEX(HELPER!$D$8:$D$48,IF(AV26>=HELPER!$B$8,1,MATCH(AV26,HELPER!$B$8:$B$48,-1)+1)),"")) | AX26: =IF(AW26="","",IFERROR(VLOOKUP(AW26,HELPER!$F$8:$G$48,2,FALSE),""))
B27: 9 | C27: =IF('INPUT DATA'!K19="","",'INPUT DATA'!K19) | K27: =IF(COUNT($F27:$J27)=0,"",SUM($F27:$J27)) | L27: =IF(COUNT(F27:J27)=0,"",IFERROR(K27/$K$16*$L$16,"")) | M27: =IF(L27="","",L27*$M$16) | S27: =IF(COUNT($N27:$R27)=0,"",SUM($N27:$R27)) | T27: =IF(COUNT(N27:R27)=0,"",IFERROR(S27/$S$16*$T$16,"")) | U27: =IF(T27="","",T27*$U$16) | Y27: =IF(COUNT(V27:X27)=0,"",SUM(V27:X27)) | Z27: =IF(COUNT(V27:X27)=0,"",IFERROR(Y27/$Y$16*$Z$16,"")) | AA27: =IF(Z27="","",Z27*$AA$16) | AE27: =IF(COUNT(AB27:AD27)=0,"",SUM(AB27:AD27)) | AF27: =IF(COUNT(AB27:AD27)=0,"",IFERROR(AE27/$AE$16*$AF$16,"")) | AG27: =IF(AF27="","",AF27*$AG$16) | AK27: =IF(COUNT(AH27:AJ27)=0,"",SUM(AH27:AJ27)) | AL27: =IF(COUNT(AH27:AJ27)=0,"",IFERROR(AK27/$AK$16*$AL$16,"")) | AM27: =IF(AL27="","",AL27*$AM$16) | AQ27: =IF(AN27="","",IFERROR(AN27/$AN$16*$AQ$16,"")) | AR27: =IF(AO27="","",IFERROR(AO27/$AO$16*$AR$16,"")) | AS27: =IF(AP27="","",IFERROR(AP27/$AP$16*$AS$16,"")) | AT27: =IF(COUNT(AN27:AP27)=0,"",SUM(AQ27:AS27)) | AU27: =IF(AT27="","",AT27*$AU$16) | AV27: =IF(COUNT(F27:J27,N27:R27,V27:X27,AB27:AD27,AH27:AJ27,AN27:AP27)=0,"",SUM(M27,U27,AA27,AG27,AM27,AU27)) | AW27: =IF(AV27="","",IFERROR(INDEX(HELPER!$D$8:$D$48,IF(AV27>=HELPER!$B$8,1,MATCH(AV27,HELPER!$B$8:$B$48,-1)+1)),"")) | AX27: =IF(AW27="","",IFERROR(VLOOKUP(AW27,HELPER!$F$8:$G$48,2,FALSE),""))
B28: 10 | C28: =IF('INPUT DATA'!K20="","",'INPUT DATA'!K20) | K28: =IF(COUNT($F28:$J28)=0,"",SUM($F28:$J28)) | L28: =IF(COUNT(F28:J28)=0,"",IFERROR(K28/$K$16*$L$16,"")) | M28: =IF(L28="","",L28*$M$16) | S28: =IF(COUNT($N28:$R28)=0,"",SUM($N28:$R28)) | T28: =IF(COUNT(N28:R28)=0,"",IFERROR(S28/$S$16*$T$16,"")) | U28: =IF(T28="","",T28*$U$16) | Y28: =IF(COUNT(V28:X28)=0,"",SUM(V28:X28)) | Z28: =IF(COUNT(V28:X28)=0,"",IFERROR(Y28/$Y$16*$Z$16,"")) | AA28: =IF(Z28="","",Z28*$AA$16) | AE28: =IF(COUNT(AB28:AD28)=0,"",SUM(AB28:AD28)) | AF28: =IF(COUNT(AB28:AD28)=0,"",IFERROR(AE28/$AE$16*$AF$16,"")) | AG28: =IF(AF28="","",AF28*$AG$16) | AK28: =IF(COUNT(AH28:AJ28)=0,"",SUM(AH28:AJ28)) | AL28: =IF(COUNT(AH28:AJ28)=0,"",IFERROR(AK28/$AK$16*$AL$16,"")) | AM28: =IF(AL28="","",AL28*$AM$16) | AQ28: =IF(AN28="","",IFERROR(AN28/$AN$16*$AQ$16,"")) | AR28: =IF(AO28="","",IFERROR(AO28/$AO$16*$AR$16,"")) | AS28: =IF(AP28="","",IFERROR(AP28/$AP$16*$AS$16,"")) | AT28: =IF(COUNT(AN28:AP28)=0,"",SUM(AQ28:AS28)) | AU28: =IF(AT28="","",AT28*$AU$16) | AV28: =IF(COUNT(F28:J28,N28:R28,V28:X28,AB28:AD28,AH28:AJ28,AN28:AP28)=0,"",SUM(M28,U28,AA28,AG28,AM28,AU28)) | AW28: =IF(AV28="","",IFERROR(INDEX(HELPER!$D$8:$D$48,IF(AV28>=HELPER!$B$8,1,MATCH(AV28,HELPER!$B$8:$B$48,-1)+1)),"")) | AX28: =IF(AW28="","",IFERROR(VLOOKUP(AW28,HELPER!$F$8:$G$48,2,FALSE),""))
B29: 11 | C29: =IF('INPUT DATA'!K21="","",'INPUT DATA'!K21) | K29: =IF(COUNT($F29:$J29)=0,"",SUM($F29:$J29)) | L29: =IF(COUNT(F29:J29)=0,"",IFERROR(K29/$K$16*$L$16,"")) | M29: =IF(L29="","",L29*$M$16) | S29: =IF(COUNT($N29:$R29)=0,"",SUM($N29:$R29)) | T29: =IF(COUNT(N29:R29)=0,"",IFERROR(S29/$S$16*$T$16,"")) | U29: =IF(T29="","",T29*$U$16) | Y29: =IF(COUNT(V29:X29)=0,"",SUM(V29:X29)) | Z29: =IF(COUNT(V29:X29)=0,"",IFERROR(Y29/$Y$16*$Z$16,"")) | AA29: =IF(Z29="","",Z29*$AA$16) | AE29: =IF(COUNT(AB29:AD29)=0,"",SUM(AB29:AD29)) | AF29: =IF(COUNT(AB29:AD29)=0,"",IFERROR(AE29/$AE$16*$AF$16,"")) | AG29: =IF(AF29="","",AF29*$AG$16) | AK29: =IF(COUNT(AH29:AJ29)=0,"",SUM(AH29:AJ29)) | AL29: =IF(COUNT(AH29:AJ29)=0,"",IFERROR(AK29/$AK$16*$AL$16,"")) | AM29: =IF(AL29="","",AL29*$AM$16) | AQ29: =IF(AN29="","",IFERROR(AN29/$AN$16*$AQ$16,"")) | AR29: =IF(AO29="","",IFERROR(AO29/$AO$16*$AR$16,"")) | AS29: =IF(AP29="","",IFERROR(AP29/$AP$16*$AS$16,"")) | AT29: =IF(COUNT(AN29:AP29)=0,"",SUM(AQ29:AS29)) | AU29: =IF(AT29="","",AT29*$AU$16) | AV29: =IF(COUNT(F29:J29,N29:R29,V29:X29,AB29:AD29,AH29:AJ29,AN29:AP29)=0,"",SUM(M29,U29,AA29,AG29,AM29,AU29)) | AW29: =IF(AV29="","",IFERROR(INDEX(HELPER!$D$8:$D$48,IF(AV29>=HELPER!$B$8,1,MATCH(AV29,HELPER!$B$8:$B$48,-1)+1)),"")) | AX29: =IF(AW29="","",IFERROR(VLOOKUP(AW29,HELPER!$F$8:$G$48,2,FALSE),""))
B30: 12 | C30: =IF('INPUT DATA'!K22="","",'INPUT DATA'!K22) | K30: =IF(COUNT($F30:$J30)=0,"",SUM($F30:$J30)) | L30: =IF(COUNT(F30:J30)=0,"",IFERROR(K30/$K$16*$L$16,"")) | M30: =IF(L30="","",L30*$M$16) | S30: =IF(COUNT($N30:$R30)=0,"",SUM($N30:$R30)) | T30: =IF(COUNT(N30:R30)=0,"",IFERROR(S30/$S$16*$T$16,"")) | U30: =IF(T30="","",T30*$U$16) | Y30: =IF(COUNT(V30:X30)=0,"",SUM(V30:X30)) | Z30: =IF(COUNT(V30:X30)=0,"",IFERROR(Y30/$Y$16*$Z$16,"")) | AA30: =IF(Z30="","",Z30*$AA$16) | AE30: =IF(COUNT(AB30:AD30)=0,"",SUM(AB30:AD30)) | AF30: =IF(COUNT(AB30:AD30)=0,"",IFERROR(AE30/$AE$16*$AF$16,"")) | AG30: =IF(AF30="","",AF30*$AG$16) | AK30: =IF(COUNT(AH30:AJ30)=0,"",SUM(AH30:AJ30)) | AL30: =IF(COUNT(AH30:AJ30)=0,"",IFERROR(AK30/$AK$16*$AL$16,"")) | AM30: =IF(AL30="","",AL30*$AM$16) | AQ30: =IF(AN30="","",IFERROR(AN30/$AN$16*$AQ$16,"")) | AR30: =IF(AO30="","",IFERROR(AO30/$AO$16*$AR$16,"")) | AS30: =IF(AP30="","",IFERROR(AP30/$AP$16*$AS$16,"")) | AT30: =IF(COUNT(AN30:AP30)=0,"",SUM(AQ30:AS30)) | AU30: =IF(AT30="","",AT30*$AU$16) | AV30: =IF(COUNT(F30:J30,N30:R30,V30:X30,AB30:AD30,AH30:AJ30,AN30:AP30)=0,"",SUM(M30,U30,AA30,AG30,AM30,AU30)) | AW30: =IF(AV30="","",IFERROR(INDEX(HELPER!$D$8:$D$48,IF(AV30>=HELPER!$B$8,1,MATCH(AV30,HELPER!$B$8:$B$48,-1)+1)),"")) | AX30: =IF(AW30="","",IFERROR(VLOOKUP(AW30,HELPER!$F$8:$G$48,2,FALSE),""))
... B68: 50 | C68: =IF('INPUT DATA'!K60="","",'INPUT DATA'!K60) | K68: =IF(COUNT($F68:$J68)=0,"",SUM($F68:$J68)) | L68: =IF(COUNT(F68:J68)=0,"",IFERROR(K68/$K$16*$L$16,"")) | M68: =IF(L68="","",L68*$M$16) | S68: =IF(COUNT($N68:$R68)=0,"",SUM($N68:$R68)) | T68: =IF(COUNT(N68:R68)=0,"",IFERROR(S68/$S$16*$T$16,"")) | U68: =IF(T68="","",T68*$U$16) | Y68: =IF(COUNT(V68:X68)=0,"",SUM(V68:X68)) | Z68: =IF(COUNT(V68:X68)=0,"",IFERROR(Y68/$Y$16*$Z$16,"")) | AA68: =IF(Z68="","",Z68*$AA$16) | AE68: =IF(COUNT(AB68:AD68)=0,"",SUM(AB68:AD68)) | AF68: =IF(COUNT(AB68:AD68)=0,"",IFERROR(AE68/$AE$16*$AF$16,"")) | AG68: =IF(AF68="","",AF68*$AG$16) | AK68: =IF(COUNT(AH68:AJ68)=0,"",SUM(AH68:AJ68)) | AL68: =IF(COUNT(AH68:AJ68)=0,"",IFERROR(AK68/$AK$16*$AL$16,"")) | AM68: =IF(AL68="","",AL68*$AM$16) | AQ68: =IF(AN68="","",IFERROR(AN68/$AN$16*$AQ$16,"")) | AR68: =IF(AO68="","",IFERROR(AO68/$AO$16*$AR$16,"")) | AS68: =IF(AP68="","",IFERROR(AP68/$AP$16*$AS$16,"")) | AT68: =IF(COUNT(AN68:AP68)=0,"",SUM(AQ68:AS68)) | AU68: =IF(AT68="","",AT68*$AU$16) | AV68: =IF(COUNT(F68:J68,N68:R68,V68:X68,AB68:AD68,AH68:AJ68,AN68:AP68)=0,"",SUM(M68,U68,AA68,AG68,AM68,AU68)) | AW68: =IF(AV68="","",IFERROR(INDEX(HELPER!$D$8:$D$48,IF(AV68>=HELPER!$B$8,1,MATCH(AV68,HELPER!$B$8:$B$48,-1)+1)),"")) | AX68: =IF(AW68="","",IFERROR(VLOOKUP(AW68,HELPER!$F$8:$G$48,2,FALSE),""))
B69: FEMALE
B70: 1 | C70: =IF('INPUT DATA'!N11="","",'INPUT DATA'!N11) | K70: =IF(COUNT($F70:$J70)=0,"",SUM($F70:$J70)) | L70: =IF(COUNT(F70:J70)=0,"",IFERROR(K70/$K$16*$L$16,"")) | M70: =IF(L70="","",L70*$M$16) | S70: =IF(COUNT($N70:$R70)=0,"",SUM($N70:$R70)) | T70: =IF(COUNT(N70:R70)=0,"",IFERROR(S70/$S$16*$T$16,"")) | U70: =IF(T70="","",T70*$U$16) | Y70: =IF(COUNT(V70:X70)=0,"",SUM(V70:X70)) | Z70: =IF(COUNT(V70:X70)=0,"",IFERROR(Y70/$Y$16*$Z$16,"")) | AA70: =IF(Z70="","",Z70*$AA$16) | AE70: =IF(COUNT(AB70:AD70)=0,"",SUM(AB70:AD70)) | AF70: =IF(COUNT(AB70:AD70)=0,"",IFERROR(AE70/$AE$16*$AF$16,"")) | AG70: =IF(AF70="","",AF70*$AG$16) | AK70: =IF(COUNT(AH70:AJ70)=0,"",SUM(AH70:AJ70)) | AL70: =IF(COUNT(AH70:AJ70)=0,"",IFERROR(AK70/$AK$16*$AL$16,"")) | AM70: =IF(AL70="","",AL70*$AM$16) | AQ70: =IF(AN70="","",IFERROR(AN70/$AN$16*$AQ$16,"")) | AR70: =IF(AO70="","",IFERROR(AO70/$AO$16*$AR$16,"")) | AS70: =IF(AP70="","",IFERROR(AP70/$AP$16*$AS$16,"")) | AT70: =IF(COUNT(AN70:AP70)=0,"",SUM(AQ70:AS70)) | AU70: =IF(AT70="","",AT70*$AU$16) | AV70: =IF(COUNT(F70:J70,N70:R70,V70:X70,AB70:AD70,AH70:AJ70,AN70:AP70)=0,"",SUM(M70,U70,AA70,AG70,AM70,AU70)) | AW70: =IF(AV70="","",IFERROR(INDEX(HELPER!$D$8:$D$48,IF(AV70>=HELPER!$B$8,1,MATCH(AV70,HELPER!$B$8:$B$48,-1)+1)),"")) | AX70: =IF(AW70="","",IFERROR(VLOOKUP(AW70,HELPER!$F$8:$G$48,2,FALSE),""))
