Workbook

Sheet INPUT DATA
A1: Input Data Sheet for Electronic-Class Record (ECR)
B7: SCHOOL INFORMATION | I7: LEARNERS' NAMES
C10: REGION | D10: : | J10: MALE | M10: FEMALE
C11: DIVISION | D11: : | J11: 1 | M11: 1
J12: 2 | M12: 2
C13: SCHOOL ID | D13: : | J13: 3 | M13: 3
C14: SCHOOL NAME | D14: : | J14: 4 | M14: 4
C15: SCHOOL YEAR | D15: : | J15: 5 | M15: 5
C16: SCHOOL HEAD | D16: : | J16: 6 | M16: 6
J17: 7 | M17: 7
J18: 8 | M18: 8
J19: 9 | M19: 9
B20: TEACHER, GRADE LEVEL, SECTION INFORMATION | J20: 10 | M20: 10
J21: 11 | M21: 11
J22: 12 | M22: 12
C23: SUBJECT TEACHER | D23: : | J23: 13 | M23: 13
C24: SUBJECT | D24: : | J24: 14 | M24: 14
C25: GRADE LEVEL | D25: : | J25: 15 | M25: 15
C26: SECTION | D26: : | J26: 16 | M26: 16
J27: 17 | M27: 17
C28: IMPORTANT NOTE: This is the official and final version of the file. All tabs are password-protected to prevent accidental formula edits and maintain the accuracy and integrity of the data. If you identify any inconsistencies or issues, particularly with the formulas, please report them for appropriate review and necessary correction. | J28: 18 | M28: 18
J29: 19 | M29: 19
J30: 20 | M30: 20
J31: 21 | M31: 21
J32: 22 | M32: 22
J33: 23 | M33: 23
J34: 24 | M34: 24
J35: 25 | M35: 25
B36: Sheet Protection Password: password123 | J36: 26 | M36: 26
J37: 27 | M37: 27
J38: 28 | M38: 28
J39: 29 | M39: 29
J40: 30 | M40: 30
J41: 31 | M41: 31
J42: 32 | M42: 32
J43: 33 | M43: 33
J44: 34 | M44: 34
J45: 35 | M45: 35
J46: 36 | M46: 36
J47: 37 | M47: 37
...

Sheet TERM 1 M and A
B2: CLASS RECORD
E5: REGION | F5: =IF('INPUT DATA'!E10="","",'INPUT DATA'!E10) | Q5: DIVISION | R5: =IF('INPUT DATA'!E11="","",'INPUT DATA'!E11) | Y5: SCHOOL ID | Z5: =IF('INPUT DATA'!E13="","",'INPUT DATA'!E13)
E7: SCHOOL NAME | F7: =IF('INPUT DATA'!E14="","",'INPUT DATA'!E14) | Y7: SCHOOL YEAR | Z7: =IF('INPUT DATA'!E15="","",'INPUT DATA'!E15)
B10: FIRST TERM | F10: GRADE LEVEL | J10: =IF('INPUT DATA'!E25="","",'INPUT DATA'!E25) | N10: TEACHER | Q10: =IF('INPUT DATA'!E23="","",'INPUT DATA'!E23) | Y10: SUBJECT | AA10: Music and Arts
F11: SECTION | J11: =IF('INPUT DATA'!E26="","",'INPUT DATA'!E26)
F12: WRITTEN / ORAL WORKS (WWs) | N12: PRODUCT / PERFORMANCE TASKS (PTs) | T12: EXAMINATIONS (EXs) | AB12: Initial Grade | AC12: Term Grade | AD12: Descriptor
F14: 1 | G14: 2 | H14: 3 | I14: 4 | J14: 5 | K14: Total | L14: PS | M14: WS | N14: 1 | O14: 2 | P14: 3 | Q14: Total | R14: PS | S14: WS | T14: ST1 | U14: ST2 | V14: TE | W14: WS ST1 | X14: WS ST2 | Y14: WS TE | Z14: PS | AA14: WS
B15: HIGHEST POSSIBLE SCORE | K15: =IF(COUNT(F15:J15)=0,"",SUM(F15:J15)) | L15: 100 | M15: 0.2 | Q15: =IF(COUNT(N15:P15)=0,"",SUM(N15:P15)) | R15: 100 | S15: 0.6 | W15: 30 | X15: 30 | Y15: 40 | Z15: 100 | AA15: 0.2
B16: LEARNERS' NAMES
B17: MALE
B18: 1 | C18: =IF('INPUT DATA'!K11="","",'INPUT DATA'!K11) | K18: =IF(COUNT($F18:$J18)=0,"",SUM($F18:$J18)) | L18: =IF(COUNT(F18:J18)=0,"",IFERROR(K18/$K$15*$L$15,"")) | M18: =IF(L18="","",L18*$M$15) | Q18: =IF(COUNT(N18:P18)=0,"",SUM(N18:P18)) | R18: =IF(COUNT(N18:P18)=0,"",IFERROR(Q18/$Q$15*$R$15,"")) | S18: =IF(R18="","",R18*$S$15) | W18: =IF(T18="","",IFERROR(T18/$T$15*$W$15,"")) | X18: =IF(U18="","",IFERROR(U18/$U$15*$X$15,"")) | Y18: =IF(V18="","",IFERROR(V18/$V$15*$Y$15,"")) | Z18: =IF(COUNT(T18:V18)=0,"",SUM(W18:Y18)) | AA18: =IF(Z18="","",Z18*$AA$15) | AB18: =IF(COUNT(F18:J18,N18:P18,T18:V18)=0,"",SUM(M18,S18,AA18)) | AC18: =IF(AB18="","",IFERROR(INDEX(HELPER!$D$8:$D$48,IF(AB18>=HELPER!$B$8,1,MATCH(AB18,HELPER!$B$8:$B$48,-1)+1)),"")) | AD18: =IF(AC18="","",IFERROR(VLOOKUP(AC18,HELPER!$F$8:$G$48,2,FALSE),""))
B19: 2 | C19: =IF('INPUT DATA'!K12="","",'INPUT DATA'!K12) | K19: =IF(COUNT($F19:$J19)=0,"",SUM($F19:$J19)) | L19: =IF(COUNT(F19:J19)=0,"",IFERROR(K19/$K$15*$L$15,"")) | M19: =IF(L19="","",L19*$M$15) | Q19: =IF(COUNT(N19:P19)=0,"",SUM(N19:P19)) | R19: =IF(COUNT(N19:P19)=0,"",IFERROR(Q19/$Q$15*$R$15,"")) | S19: =IF(R19="","",R19*$S$15) | W19: =IF(T19="","",IFERROR(T19/$T$15*$W$15,"")) | X19: =IF(U19="","",IFERROR(U19/$U$15*$X$15,"")) | Y19: =IF(V19="","",IFERROR(V19/$V$15*$Y$15,"")) | Z19: =IF(COUNT(T19:V19)=0,"",SUM(W19:Y19)) | AA19: =IF(Z19="","",Z19*$AA$15) | AB19: =IF(COUNT(F19:J19,N19:P19,T19:V19)=0,"",SUM(M19,S19,AA19)) | AC19: =IF(AB19="","",IFERROR(INDEX(HELPER!$D$8:$D$48,IF(AB19>=HELPER!$B$8,1,MATCH(AB19,HELPER!$B$8:$B$48,-1)+1)),"")) | AD19: =IF(AC19="","",IFERROR(VLOOKUP(AC19,HELPER!$F$8:$G$48,2,FALSE),""))
B20: 3 | C20: =IF('INPUT DATA'!K13="","",'INPUT DATA'!K13) | K20: =IF(COUNT($F20:$J20)=0,"",SUM($F20:$J20)) | L20: =IF(COUNT(F20:J20)=0,"",IFERROR(K20/$K$15*$L$15,"")) | M20: =IF(L20="","",L20*$M$15) | Q20: =IF(COUNT(N20:P20)=0,"",SUM(N20:P20)) | R20: =IF(COUNT(N20:P20)=0,"",IFERROR(Q20/$Q$15*$R$15,"")) | S20: =IF(R20="","",R20*$S$15) | W20: =IF(T20="","",IFERROR(T20/$T$15*$W$15,"")) | X20: =IF(U20="","",IFERROR(U20/$U$15*$X$15,"")) | Y20: =IF(V20="","",IFERROR(V20/$V$15*$Y$15,"")) | Z20: =IF(COUNT(T20:V20)=0,"",SUM(W20:Y20)) | AA20: =IF(Z20="","",Z20*$AA$15) | AB20: =IF(COUNT(F20:J20,N20:P20,T20:V20)=0,"",SUM(M20,S20,AA20)) | AC20: =IF(AB20="","",IFERROR(INDEX(HELPER!$D$8:$D$48,IF(AB20>=HELPER!$B$8,1,MATCH(AB20,HELPER!$B$8:$B$48,-1)+1)),"")) | AD20: =IF(AC20="","",IFERROR(VLOOKUP(AC20,HELPER!$F$8:$G$48,2,FALSE),""))
B21: 4 | C21: =IF('INPUT DATA'!K14="","",'INPUT DATA'!K14) | K21: =IF(COUNT($F21:$J21)=0,"",SUM($F21:$J21)) | L21: =IF(COUNT(F21:J21)=0,"",IFERROR(K21/$K$15*$L$15,"")) | M21: =IF(L21="","",L21*$M$15) | Q21: =IF(COUNT(N21:P21)=0,"",SUM(N21:P21)) | R21: =IF(COUNT(N21:P21)=0,"",IFERROR(Q21/$Q$15*$R$15,"")) | S21: =IF(R21="","",R21*$S$15) | W21: =IF(T21="","",IFERROR(T21/$T$15*$W$15,"")) | X21: =IF(U21="","",IFERROR(U21/$U$15*$X$15,"")) | Y21: =IF(V21="","",IFERROR(V21/$V$15*$Y$15,"")) | Z21: =IF(COUNT(T21:V21)=0,"",SUM(W21:Y21)) | AA21: =IF(Z21="","",Z21*$AA$15) | AB21: =IF(COUNT(F21:J21,N21:P21,T21:V21)=0,"",SUM(M21,S21,AA21)) | AC21: =IF(AB21="","",IFERROR(INDEX(HELPER!$D$8:$D$48,IF(AB21>=HELPER!$B$8,1,MATCH(AB21,HELPER!$B$8:$B$48,-1)+1)),"")) | AD21: =IF(AC21="","",IFERROR(VLOOKUP(AC21,HELPER!$F$8:$G$48,2,FALSE),""))
B22: 5 | C22: =IF('INPUT DATA'!K15="","",'INPUT DATA'!K15) | K22: =IF(COUNT($F22:$J22)=0,"",SUM($F22:$J22)) | L22: =IF(COUNT(F22:J22)=0,"",IFERROR(K22/$K$15*$L$15,"")) | M22: =IF(L22="","",L22*$M$15) | Q22: =IF(COUNT(N22:P22)=0,"",SUM(N22:P22)) | R22: =IF(COUNT(N22:P22)=0,"",IFERROR(Q22/$Q$15*$R$15,"")) | S22: =IF(R22="","",R22*$S$15) | W22: =IF(T22="","",IFERROR(T22/$T$15*$W$15,"")) | X22: =IF(U22="","",IFERROR(U22/$U$15*$X$15,"")) | Y22: =IF(V22="","",IFERROR(V22/$V$15*$Y$15,"")) | Z22: =IF(COUNT(T22:V22)=0,"",SUM(W22:Y22)) | AA22: =IF(Z22="","",Z22*$AA$15) | AB22: =IF(COUNT(F22:J22,N22:P22,T22:V22)=0,"",SUM(M22,S22,AA22)) | AC22: =IF(AB22="","",IFERROR(INDEX(HELPER!$D$8:$D$48,IF(AB22>=HELPER!$B$8,1,MATCH(AB22,HELPER!$B$8:$B$48,-1)+1)),"")) | AD22: =IF(AC22="","",IFERROR(VLOOKUP(AC22,HELPER!$F$8:$G$48,2,FALSE),""))
B23: 6 | C23: =IF('INPUT DATA'!K16="","",'INPUT DATA'!K16) | K23: =IF(COUNT($F23:$J23)=0,"",SUM($F23:$J23)) | L23: =IF(COUNT(F23:J23)=0,"",IFERROR(K23/$K$15*$L$15,"")) | M23: =IF(L23="","",L23*$M$15) | Q23: =IF(COUNT(N23:P23)=0,"",SUM(N23:P23)) | R23: =IF(COUNT(N23:P23)=0,"",IFERROR(Q23/$Q$15*$R$15,"")) | S23: =IF(R23="","",R23*$S$15) | W23: =IF(T23="","",IFERROR(T23/$T$15*$W$15,"")) | X23: =IF(U23="","",IFERROR(U23/$U$15*$X$15,"")) | Y23: =IF(V23="","",IFERROR(V23/$V$15*$Y$15,"")) | Z23: =IF(COUNT(T23:V23)=0,"",SUM(W23:Y23)) | AA23: =IF(Z23="","",Z23*$AA$15) | AB23: =IF(COUNT(F23:J23,N23:P23,T23:V23)=0,"",SUM(M23,S23,AA23)) | AC23: =IF(AB23="","",IFERROR(INDEX(HELPER!$D$8:$D$48,IF(AB23>=HELPER!$B$8,1,MATCH(AB23,HELPER!$B$8:$B$48,-1)+1)),"")) | AD23: =IF(AC23="","",IFERROR(VLOOKUP(AC23,HELPER!$F$8:$G$48,2,FALSE),""))
B24: 7 | C24: =IF('INPUT DATA'!K17="","",'INPUT DATA'!K17) | K24: =IF(COUNT($F24:$J24)=0,"",SUM($F24:$J24)) | L24: =IF(COUNT(F24:J24)=0,"",IFERROR(K24/$K$15*$L$15,"")) | M24: =IF(L24="","",L24*$M$15) | Q24: =IF(COUNT(N24:P24)=0,"",SUM(N24:P24)) | R24: =IF(COUNT(N24:P24)=0,"",IFERROR(Q24/$Q$15*$R$15,"")) | S24: =IF(R24="","",R24*$S$15) | W24: =IF(T24="","",IFERROR(T24/$T$15*$W$15,"")) | X24: =IF(U24="","",IFERROR(U24/$U$15*$X$15,"")) | Y24: =IF(V24="","",IFERROR(V24/$V$15*$Y$15,"")) | Z24: =IF(COUNT(T24:V24)=0,"",SUM(W24:Y24)) | AA24: =IF(Z24="","",Z24*$AA$15) | AB24: =IF(COUNT(F24:J24,N24:P24,T24:V24)=0,"",SUM(M24,S24,AA24)) | AC24: =IF(AB24="","",IFERROR(INDEX(HELPER!$D$8:$D$48,IF(AB24>=HELPER!$B$8,1,MATCH(AB24,HELPER!$B$8:$B$48,-1)+1)),"")) | AD24: =IF(AC24="","",IFERROR(VLOOKUP(AC24,HELPER!$F$8:$G$48,2,FALSE),""))
B25: 8 | C25: =IF('INPUT DATA'!K18="","",'INPUT DATA'!K18) | K25: =IF(COUNT($F25:$J25)=0,"",SUM($F25:$J25)) | L25: =IF(COUNT(F25:J25)=0,"",IFERROR(K25/$K$15*$L$15,"")) | M25: =IF(L25="","",L25*$M$15) | Q25: =IF(COUNT(N25:P25)=0,"",SUM(N25:P25)) | R25: =IF(COUNT(N25:P25)=0,"",IFERROR(Q25/$Q$15*$R$15,"")) | S25: =IF(R25="","",R25*$S$15) | W25: =IF(T25="","",IFERROR(T25/$T$15*$W$15,"")) | X25: =IF(U25="","",IFERROR(U25/$U$15*$X$15,"")) | Y25: =IF(V25="","",IFERROR(V25/$V$15*$Y$15,"")) | Z25: =IF(COUNT(T25:V25)=0,"",SUM(W25:Y25)) | AA25: =IF(Z25="","",Z25*$AA$15) | AB25: =IF(COUNT(F25:J25,N25:P25,T25:V25)=0,"",SUM(M25,S25,AA25)) | AC25: =IF(AB25="","",IFERROR(INDEX(HELPER!$D$8:$D$48,IF(AB25>=HELPER!$B$8,1,MATCH(AB25,HELPER!$B$8:$B$48,-1)+1)),"")) | AD25: =IF(AC25="","",IFERROR(VLOOKUP(AC25,HELPER!$F$8:$G$48,2,FALSE),""))
B26: 9 | C26: =IF('INPUT DATA'!K19="","",'INPUT DATA'!K19) | K26: =IF(COUNT($F26:$J26)=0,"",SUM($F26:$J26)) | L26: =IF(COUNT(F26:J26)=0,"",IFERROR(K26/$K$15*$L$15,"")) | M26: =IF(L26="","",L26*$M$15) | Q26: =IF(COUNT(N26:P26)=0,"",SUM(N26:P26)) | R26: =IF(COUNT(N26:P26)=0,"",IFERROR(Q26/$Q$15*$R$15,"")) | S26: =IF(R26="","",R26*$S$15) | W26: =IF(T26="","",IFERROR(T26/$T$15*$W$15,"")) | X26: =IF(U26="","",IFERROR(U26/$U$15*$X$15,"")) | Y26: =IF(V26="","",IFERROR(V26/$V$15*$Y$15,"")) | Z26: =IF(COUNT(T26:V26)=0,"",SUM(W26:Y26)) | AA26: =IF(Z26="","",Z26*$AA$15) | AB26: =IF(COUNT(F26:J26,N26:P26,T26:V26)=0,"",SUM(M26,S26,AA26)) | AC26: =IF(AB26="","",IFERROR(INDEX(HELPER!$D$8:$D$48,IF(AB26>=HELPER!$B$8,1,MATCH(AB26,HELPER!$B$8:$B$48,-1)+1)),"")) | AD26: =IF(AC26="","",IFERROR(VLOOKUP(AC26,HELPER!$F$8:$G$48,2,FALSE),""))
B27: 10 | C27: =IF('INPUT DATA'!K20="","",'INPUT DATA'!K20) | K27: =IF(COUNT($F27:$J27)=0,"",SUM($F27:$J27)) | L27: =IF(COUNT(F27:J27)=0,"",IFERROR(K27/$K$15*$L$15,"")) | M27: =IF(L27="","",L27*$M$15) | Q27: =IF(COUNT(N27:P27)=0,"",SUM(N27:P27)) | R27: =IF(COUNT(N27:P27)=0,"",IFERROR(Q27/$Q$15*$R$15,"")) | S27: =IF(R27="","",R27*$S$15) | W27: =IF(T27="","",IFERROR(T27/$T$15*$W$15,"")) | X27: =IF(U27="","",IFERROR(U27/$U$15*$X$15,"")) | Y27: =IF(V27="","",IFERROR(V27/$V$15*$Y$15,"")) | Z27: =IF(COUNT(T27:V27)=0,"",SUM(W27:Y27)) | AA27: =IF(Z27="","",Z27*$AA$15) | AB27: =IF(COUNT(F27:J27,N27:P27,T27:V27)=0,"",SUM(M27,S27,AA27)) | AC27: =IF(AB27="","",IFERROR(INDEX(HELPER!$D$8:$D$48,IF(AB27>=HELPER!$B$8,1,MATCH(AB27,HELPER!$B$8:$B$48,-1)+1)),"")) | AD27: =IF(AC27="","",IFERROR(VLOOKUP(AC27,HELPER!$F$8:$G$48,2,FALSE),""))
B28: 11 | C28: =IF('INPUT DATA'!K21="","",'INPUT DATA'!K21) | K28: =IF(COUNT($F28:$J28)=0,"",SUM($F28:$J28)) | L28: =IF(COUNT(F28:J28)=0,"",IFERROR(K28/$K$15*$L$15,"")) | M28: =IF(L28="","",L28*$M$15) | Q28: =IF(COUNT(N28:P28)=0,"",SUM(N28:P28)) | R28: =IF(COUNT(N28:P28)=0,"",IFERROR(Q28/$Q$15*$R$15,"")) | S28: =IF(R28="","",R28*$S$15) | W28: =IF(T28="","",IFERROR(T28/$T$15*$W$15,"")) | X28: =IF(U28="","",IFERROR(U28/$U$15*$X$15,"")) | Y28: =IF(V28="","",IFERROR(V28/$V$15*$Y$15,"")) | Z28: =IF(COUNT(T28:V28)=0,"",SUM(W28:Y28)) | AA28: =IF(Z28="","",Z28*$AA$15) | AB28: =IF(COUNT(F28:J28,N28:P28,T28:V28)=0,"",SUM(M28,S28,AA28)) | AC28: =IF(AB28="","",IFERROR(INDEX(HELPER!$D$8:$D$48,IF(AB28>=HELPER!$B$8,1,MATCH(AB28,HELPER!$B$8:$B$48,-1)+1)),"")) | AD28: =IF(AC28="","",IFERROR(VLOOKUP(AC28,HELPER!$F$8:$G$48,2,FALSE),""))
B29: 12 | C29: =IF('INPUT DATA'!K22="","",'INPUT DATA'!K22) | K29: =IF(COUNT($F29:$J29)=0,"",SUM($F29:$J29)) | L29: =IF(COUNT(F29:J29)=0,"",IFERROR(K29/$K$15*$L$15,"")) | M29: =IF(L29="","",L29*$M$15) | Q29: =IF(COUNT(N29:P29)=0,"",SUM(N29:P29)) | R29: =IF(COUNT(N29:P29)=0,"",IFERROR(Q29/$Q$15*$R$15,"")) | S29: =IF(R29="","",R29*$S$15) | W29: =IF(T29="","",IFERROR(T29/$T$15*$W$15,"")) | X29: =IF(U29="","",IFERROR(U29/$U$15*$X$15,"")) | Y29: =IF(V29="","",IFERROR(V29/$V$15*$Y$15,"")) | Z29: =IF(COUNT(T29:V29)=0,"",SUM(W29:Y29)) | AA29: =IF(Z29="","",Z29*$AA$15) | AB29: =IF(COUNT(F29:J29,N29:P29,T29:V29)=0,"",SUM(M29,S29,AA29)) | AC29: =IF(AB29="","",IFERROR(INDEX(HELPER!$D$8:$D$48,IF(AB29>=HELPER!$B$8,1,MATCH(AB29,HELPER!$B$8:$B$48,-1)+1)),"")) | AD29: =IF(AC29="","",IFERROR(VLOOKUP(AC29,HELPER!$F$8:$G$48,2,FALSE),""))
... B67: 50 | C67: =IF('INPUT DATA'!K60="","",'INPUT DATA'!K60) | K67: =IF(COUNT($F67:$J67)=0,"",SUM($F67:$J67)) | L67: =IF(COUNT(F67:J67)=0,"",IFERROR(K67/$K$15*$L$15,"")) | M67: =IF(L67="","",L67*$M$15) | Q67: =IF(COUNT(N67:P67)=0,"",SUM(N67:P67)) | R67: =IF(COUNT(N67:P67)=0,"",IFERROR(Q67/$Q$15*$R$15,"")) | S67: =IF(R67="","",R67*$S$15) | W67: =IF(T67="","",IFERROR(T67/$T$15*$W$15,"")) | X67: =IF(U67="","",IFERROR(U67/$U$15*$X$15,"")) | Y67: =IF(V67="","",IFERROR(V67/$V$15*$Y$15,"")) | Z67: =IF(COUNT(T67:V67)=0,"",SUM(W67:Y67)) | AA67: =IF(Z67="","",Z67*$AA$15) | AB67: =IF(COUNT(F67:J67,N67:P67,T67:V67)=0,"",SUM(M67,S67,AA67)) | AC67: =IF(AB67="","",IFERROR(INDEX(HELPER!$D$8:$D$48,IF(AB67>=HELPER!$B$8,1,MATCH(AB67,HELPER!$B$8:$B$48,-1)+1)),"")) | AD67: =IF(AC67="","",IFERROR(VLOOKUP(AC67,HELPER!$F$8:$G$48,2,FALSE),""))
B68: FEMALE
B69: 1 | C69: =IF('INPUT DATA'!N11="","",'INPUT DATA'!N11) | K69: =IF(COUNT($F69:$J69)=0,"",SUM($F69:$J69)) | L69: =IF(COUNT(F69:J69)=0,"",IFERROR(K69/$K$15*$L$15,"")) | M69: =IF(L69="","",L69*$M$15) | Q69: =IF(COUNT(N69:P69)=0,"",SUM(N69:P69)) | R69: =IF(COUNT(N69:P69)=0,"",IFERROR(Q69/$Q$15*$R$15,"")) | S69: =IF(R69="","",R69*$S$15) | W69: =IF(T69="","",IFERROR(T69/$T$15*$W$15,"")) | X69: =IF(U69="","",IFERROR(U69/$U$15*$X$15,"")) | Y69: =IF(V69="","",IFERROR(V69/$V$15*$Y$15,"")) | Z69: =IF(COUNT(T69:V69)=0,"",SUM(W69:Y69)) | AA69: =IF(Z69="","",Z69*$AA$15) | AB69: =IF(COUNT(F69:J69,N69:P69,T69:V69)=0,"",SUM(M69,S69,AA69)) | AC69: =IF(AB69="","",IFERROR(INDEX(HELPER!$D$8:$D$48,IF(AB69>=HELPER!$B$8,1,MATCH(AB69,HELPER!$B$8:$B$48,-1)+1)),"")) | AD69: =IF(AC69="","",IFERROR(VLOOKUP(AC69,HELPER!$F$8:$G$48,2,FALSE),""))
B70: 2 | C70: =IF('INPUT DATA'!N12="","",'INPUT DATA'!N12) | K70: =IF(COUNT($F70:$J70)=0,"",SUM($F70:$J70)) | L70: =IF(COUNT(F70:J70)=0,"",IFERROR(K70/$K$15*$L$15,"")) | M70: =IF(L70="","",L70*$M$15) | Q70: =IF(COUNT(N70:P70)=0,"",SUM(N70:P70)) | R70: =IF(COUNT(N70:P70)=0,"",IFERROR(Q70/$Q$15*$R$15,"")) | S70: =IF(R70="","",R70*$S$15) | W70: =IF(T70="","",IFERROR(T70/$T$15*$W$15,"")) | X70: =IF(U70="","",IFERROR(U70/$U$15*$X$15,"")) | Y70: =IF(V70="","",IFERROR(V70/$V$15*$Y$15,"")) | Z70: =IF(COUNT(T70:V70)=0,"",SUM(W70:Y70)) | AA70: =IF(Z70="","",Z70*$AA$15) | AB70: =IF(COUNT(F70:J70,N70:P70,T70:V70)=0,"",SUM(M70,S70,AA70)) | AC70: =IF(AB70="","",IFERROR(INDEX(HELPER!$D$8:$D$48,IF(AB70>=HELPER!$B$8,1,MATCH(AB70,HELPER!$B$8:$B$48,-1)+1)),"")) | AD70: =IF(AC70="","",IFERROR(VLOOKUP(AC70,HELPER!$F$8:$G$48,2,FALSE),""))
B71: 3 | C71: =IF('INPUT DATA'!N13="","",'INPUT DATA'!N13) | K71: =IF(COUNT($F71:$J71)=0,"",SUM($F71:$J71)) | L71: =IF(COUNT(F71:J71)=0,"",IFERROR(K71/$K$15*$L$15,"")) | M71: =IF(L71="","",L71*$M$15) | Q71: =IF(COUNT(N71:P71)=0,"",SUM(N71:P71)) | R71: =IF(COUNT(N71:P71)=0,"",IFERROR(Q71/$Q$15*$R$15,"")) | S71: =IF(R71="","",R71*$S$15) | W71: =IF(T71="","",IFERROR(T71/$T$15*$W$15,"")) | X71: =IF(U71="","",IFERROR(U71/$U$15*$X$15,"")) | Y71: =IF(V71="","",IFERROR(V71/$V$15*$Y$15,"")) | Z71: =IF(COUNT(T71:V71)=0,"",SUM(W71:Y71)) | AA71: =IF(Z71="","",Z71*$AA$15) | AB71: =IF(COUNT(F71:J71,N71:P71,T71:V71)=0,"",SUM(M71,S71,AA71)) | AC71: =IF(AB71="","",IFERROR(INDEX(HELPER!$D$8:$D$48,IF(AB71>=HELPER!$B$8,1,MATCH(AB71,HELPER!$B$8:$B$48,-1)+1)),"")) | AD71: =IF(AC71="","",IFERROR(VLOOKUP(AC71,HELPER!$F$8:$G$48,2,FALSE),""))
B72: 4 | C72: =IF('INPUT DATA'!N14="","",'INPUT DATA'!N14) | K72: =IF(COUNT($F72:$J72)=0,"",SUM($F72:$J72)) | L72: =IF(COUNT(F72:J72)=0,"",IFERROR(K72/$K$15*$L$15,"")) | M72: =IF(L72="","",L72*$M$15) | Q72: =IF(COUNT(N72:P72)=0,"",SUM(N72:P72)) | R72: =IF(COUNT(N72:P72)=0,"",IFERROR(Q72/$Q$15*$R$15,"")) | S72: =IF(R72="","",R72*$S$15) | W72: =IF(T72="","",IFERROR(T72/$T$15*$W$15,"")) | X72: =IF(U72="","",IFERROR(U72/$U$15*$X$15,"")) | Y72: =IF(V72="","",IFERROR(V72/$V$15*$Y$15,"")) | Z72: =IF(COUNT(T72:V72)=0,"",SUM(W72:Y72)) | AA72: =IF(Z72="","",Z72*$AA$15) | AB72: =IF(COUNT(F72:J72,N72:P72,T72:V72)=0,"",SUM(M72,S72,AA72)) | AC72: =IF(AB72="","",IFERROR(INDEX(HELPER!$D$8:$D$48,IF(AB72>=HELPER!$B$8,1,MATCH(AB72,HELPER!$B$8:$B$48,-1)+1)),"")) | AD72: =IF(AC72="","",IFERROR(VLOOKUP(AC72,HELPER!$F$8:$G$48,2,FALSE),""))
B73: 5 | C73: =IF('INPUT DATA'!N15="","",'INPUT DATA'!N15) | K73: =IF(COUNT($F73:$J73)=0,"",SUM($F73:$J73)) | L73: =IF(COUNT(F73:J73)=0,"",IFERROR(K73/$K$15*$L$15,"")) | M73: =IF(L73="","",L73*$M$15) | Q73: =IF(COUNT(N73:P73)=0,"",SUM(N73:P73)) | R73: =IF(COUNT(N73:P73)=0,"",IFERROR(Q73/$Q$15*$R$15,"")) | S73: =IF(R73="","",R73*$S$15) | W73: =IF(T73="","",IFERROR(T73/$T$15*$W$15,"")) | X73: =IF(U73="","",IFERROR(U73/$U$15*$X$15,"")) | Y73: =IF(V73="","",IFERROR(V73/$V$15*$Y$15,"")) | Z73: =IF(COUNT(T73:V73)=0,"",SUM(W73:Y73)) | AA73: =IF(Z73="","",Z73*$AA$15) | AB73: =IF(COUNT(F73:J73,N73:P73,T73:V73)=0,"",SUM(M73,S73,AA73)) | AC73: =IF(AB73="","",IFERROR(INDEX(HELPER!$D$8:$D$48,IF(AB73>=HELPER!$B$8,1,MATCH(AB73,HELPER!$B$8:$B$48,-1)+1)),"")) | AD73: =IF(AC73="","",IFERROR(VLOOKUP(AC73,HELPER!$F$8:$G$48,2,FALSE),""))
B74: 6 | C74: =IF('INPUT DATA'!N16="","",'INPUT DATA'!N16) | K74: =IF(COUNT($F74:$J74)=0,"",SUM($F74:$J74)) | L74: =IF(COUNT(F74:J74)=0,"",IFERROR(K74/$K$15*$L$15,"")) | M74: =IF(L74="","",L74*$M$15) | Q74: =IF(COUNT(N74:P74)=0,"",SUM(N74:P74)) | R74: =IF(COUNT(N74:P74)=0,"",IFERROR(Q74/$Q$15*$R$15,"")) | S74: =IF(R74="","",R74*$S$15) | W74: =IF(T74="","",IFERROR(T74/$T$15*$W$15,"")) | X74: =IF(U74="","",IFERROR(U74/$U$15*$X$15,"")) | Y74: =IF(V74="","",IFERROR(V74/$V$15*$Y$15,"")) | Z74: =IF(COUNT(T74:V74)=0,"",SUM(W74:Y74)) | AA74: =IF(Z74="","",Z74*$AA$15) | AB74: =IF(COUNT(F74:J74,N74:P74,T74:V74)=0,"",SUM(M74,S74,AA74)) | AC74: =IF(AB74="","",IFERROR(INDEX(HELPER!$D$8:$D$48,IF(AB74>=HELPER!$B$8,1,MATCH(AB74,HELPER!$B$8:$B$48,-1)+1)),"")) | AD74: =IF(AC74="","",IFERROR(VLOOKUP(AC74,HELPER!$F$8:$G$48,2,FALSE),""))
B75: 7 | C75: =IF('INPUT DATA'!N17="","",'INPUT DATA'!N17) | K75: =IF(COUNT($F75:$J75)=0,"",SUM($F75:$J75)) | L75: =IF(COUNT(F75:J75)=0,"",IFERROR(K75/$K$15*$L$15,"")) | M75: =IF(L75="","",L75*$M$15) | Q75: =IF(COUNT(N75:P75)=0,"",SUM(N75:P75)) | R75: =IF(COUNT(N75:P75)=0,"",IFERROR(Q75/$Q$15*$R$15,"")) | S75: =IF(R75="","",R75*$S$15) | W75: =IF(T75="","",IFERROR(T75/$T$15*$W$15,"")) | X75: =IF(U75="","",IFERROR(U75/$U$15*$X$15,"")) | Y75: =IF(V75="","",IFERROR(V75/$V$15*$Y$15,"")) | Z75: =IF(COUNT(T75:V75)=0,"",SUM(W75:Y75)) | AA75: =IF(Z75="","",Z75*$AA$15) | AB75: =IF(COUNT(F75:J75,N75:P75,T75:V75)=0,"",SUM(M75,S75,AA75)) | AC75: =IF(AB75="","",IFERROR(INDEX(HELPER!$D$8:$D$48,IF(AB75>=HELPER!$B$8,1,MATCH(AB75,HELPER!$B$8:$B$48,-1)+1)),"")) | AD75: =IF(AC75="","",IFERROR(VLOOKUP(AC75,HELPER!$F$8:$G$48,2,FALSE),""))
B76: 8 | C76: =IF('INPUT DATA'!N18="","",'INPUT DATA'!N18) | K76: =IF(COUNT($F76:$J76)=0,"",SUM($F76:$J76)) | L76: =IF(COUNT(F76:J76)=0,"",IFERROR(K76/$K$15*$L$15,"")) | M76: =IF(L76="","",L76*$M$15) | Q76: =IF(COUNT(N76:P76)=0,"",SUM(N76:P76)) | R76: =IF(COUNT(N76:P76)=0,"",IFERROR(Q76/$Q$15*$R$15,"")) | S76: =IF(R76="","",R76*$S$15) | W76: =IF(T76="","",IFERROR(T76/$T$15*$W$15,"")) | X76: =IF(U76="","",IFERROR(U76/$U$15*$X$15,"")) | Y76: =IF(V76="","",IFERROR(V76/$V$15*$Y$15,"")) | Z76: =IF(COUNT(T76:V76)=0,"",SUM(W76:Y76)) | AA76: =IF(Z76="","",Z76*$AA$15) | AB76: =IF(COUNT(F76:J76,N76:P76,T76:V76)=0,"",SUM(M76,S76,AA76)) | AC76: =IF(AB76="","",IFERROR(INDEX(HELPER!$D$8:$D$48,IF(AB76>=HELPER!$B$8,1,MATCH(AB76,HELPER!$B$8:$B$48,-1)+1)),"")) | AD76: =IF(AC76="","",IFERROR(VLOOKUP(AC76,HELPER!$F$8:$G$48,2,FALSE),""))
B77: 9 | C77: =IF('INPUT DATA'!N19="","",'INPUT DATA'!N19) | K77: =IF(COUNT($F77:$J77)=0,"",SUM($F77:$J77)) | L77: =IF(COUNT(F77:J77)=0,"",IFERROR(K77/$K$15*$L$15,"")) | M77: =IF(L77="","",L77*$M$15) | Q77: =IF(COUNT(N77:P77)=0,"",SUM(N77:P77)) | R77: =IF(COUNT(N77:P77)=0,"",IFERROR(Q77/$Q$15*$R$15,"")) | S77: =IF(R77="","",R77*$S$15) | W77: =IF(T77="","",IFERROR(T77/$T$15*$W$15,"")) | X77: =IF(U77="","",IFERROR(U77/$U$15*$X$15,"")) | Y77: =IF(V77="","",IFERROR(V77/$V$15*$Y$15,"")) | Z77: =IF(COUNT(T77:V77)=0,"",SUM(W77:Y77)) | AA77: =IF(Z77="","",Z77*$AA$15) | AB77: =IF(COUNT(F77:J77,N77:P77,T77:V77)=0,"",SUM(M77,S77,AA77)) | AC77: =IF(AB77="","",IFERROR(INDEX(HELPER!$D$8:$D$48,IF(AB77>=HELPER!$B$8,1,MATCH(AB77,HELPER!$B$8:$B$48,-1)+1)),"")) | AD77: =IF(AC77="","",IFERROR(VLOOKUP(AC77,HELPER!$F$8:$G$48,2,FALSE),""))
B78: 10 | C78: =IF('INPUT DATA'!N20="","",'INPUT DATA'!N20) | K78: =IF(COUNT($F78:$J78)=0,"",SUM($F78:$J78)) | L78: =IF(COUNT(F78:J78)=0,"",IFERROR(K78/$K$15*$L$15,"")) | M78: =IF(L78="","",L78*$M$15) | Q78: =IF(COUNT(N78:P78)=0,"",SUM(N78:P78)) | R78: =IF(COUNT(N78:P78)=0,"",IFERROR(Q78/$Q$15*$R$15,"")) | S78: =IF(R78="","",R78*$S$15) | W78: =IF(T78="","",IFERROR(T78/$T$15*$W$15,"")) | X78: =IF(U78="","",IFERROR(U78/$U$15*$X$15,"")) | Y78: =IF(V78="","",IFERROR(V78/$V$15*$Y$15,"")) | Z78: =IF(COUNT(T78:V78)=0,"",SUM(W78:Y78)) | AA78: =IF(Z78="","",Z78*$AA$15) | AB78: =IF(COUNT(F78:J78,N78:P78,T78:V78)=0,"",SUM(M78,S78,AA78)) | AC78: =IF(AB78="","",IFERROR(INDEX(HELPER!$D$8:$D$48,IF(AB78>=HELPER!$B$8,1,MATCH(AB78,HELPER!$B$8:$B$48,-1)+1)),"")) | AD78: =IF(AC78="","",IFERROR(VLOOKUP(AC78,HELPER!$F$8:$G$48,2,FALSE),""))
B79: 11 | C79: =IF('INPUT DATA'!N21="","",'INPUT DATA'!N21) | K79: =IF(COUNT($F79:$J79)=0,"",SUM($F79:$J79)) | L79: =IF(COUNT(F79:J79)=0,"",IFERROR(K79/$K$15*$L$15,"")) | M79: =IF(L79="","",L79*$M$15) | Q79: =IF(COUNT(N79:P79)=0,"",SUM(N79:P79)) | R79: =IF(COUNT(N79:P79)=0,"",IFERROR(Q79/$Q$15*$R$15,"")) | S79: =IF(R79="","",R79*$S$15) | W79: =IF(T79="","",IFERROR(T79/$T$15*$W$15,"")) | X79: =IF(U79="","",IFERROR(U79/$U$15*$X$15,"")) | Y79: =IF(V79="","",IFERROR(V79/$V$15*$Y$15,"")) | Z79: =IF(COUNT(T79:V79)=0,"",SUM(W79:Y79)) | AA79: =IF(Z79="","",Z79*$AA$15) | AB79: =IF(COUNT(F79:J79,N79:P79,T79:V79)=0,"",SUM(M79,S79,AA79)) | AC79: =IF(AB79="","",IFERROR(INDEX(HELPER!$D$8:$D$48,IF(AB79>=HELPER!$B$8,1,MATCH(AB79,HELPER!$B$8:$B$48,-1)+1)),"")) | AD79: =IF(AC79="","",IFERROR(VLOOKUP(AC79,HELPER!$F$8:$G$48,2,FALSE),""))
B80: 12 | C80: =IF('INPUT DATA'!N22="","",'INPUT DATA'!N22) | K80: =IF(COUNT($F80:$J80)=0,"",SUM($F80:$J80)) | L80: =IF(COUNT(F80:J80)=0,"",IFERROR(K80/$K$15*$L$15,"")) | M80: =IF(L80="","",L80*$M$15) | Q80: =IF(COUNT(N80:P80)=0,"",SUM(N80:P80)) | R80: =IF(COUNT(N80:P80)=0,"",IFERROR(Q80/$Q$15*$R$15,"")) | S80: =IF(R80="","",R80*$S$15) | W80: =IF(T80="","",IFERROR(T80/$T$15*$W$15,"")) | X80: =IF(U80="","",IFERROR(U80/$U$15*$X$15,"")) | Y80: =IF(V80="","",IFERROR(V80/$V$15*$Y$15,"")) | Z80: =IF(COUNT(T80:V80)=0,"",SUM(W80:Y80)) | AA80: =IF(Z80="","",Z80*$AA$15) | AB80: =IF(COUNT(F80:J80,N80:P80,T80:V80)=0,"",SUM(M80,S80,AA80)) | AC80: =IF(AB80="","",IFERROR(INDEX(HELPER!$D$8:$D$48,IF(AB80>=HELPER!$B$8,1,MATCH(AB80,HELPER!$B$8:$B$48,-1)+1)),"")) | AD80: =IF(AC80="","",IFERROR(VLOOKUP(AC80,HELPER!$F$8:$G$48,2,FALSE),""))
... B118: 50 | C118: =IF('INPUT DATA'!N60="","",'INPUT DATA'!N60) | K118: =IF(COUNT($F118:$J118)=0,"",SUM($F118:$J118)) | L118: =IF(COUNT(F118:J118)=0,"",IFERROR(K118/$K$15*$L$15,"")) | M118: =IF(L118="","",L118*$M$15) | Q118: =IF(COUNT(N118:P118)=0,"",SUM(N118:P118)) | R118: =IF(COUNT(N118:P118)=0,"",IFERROR(Q118/$Q$15*$R$15,"")) | S118: =IF(R118="","",R118*$S$15) | W118: =IF(T118="","",IFERROR(T118/$T$15*$W$15,"")) | X118: =IF(U118="","",IFERROR(U118/$U$15*$X$15,"")) | Y118: =IF(V118="","",IFERROR(V118/$V$15*$Y$15,"")) | Z118: =IF(COUNT(T118:V118)=0,"",SUM(W118:Y118)) | AA118: =IF(Z118="","",Z118*$AA$15) | AB118: =IF(COUNT(F118:J118,N118:P118,T118:V118)=0,"",SUM(M118,S118,AA118)) | AC118: =IF(AB118="","",IFERROR(INDEX(HELPER!$D$8:$D$48,IF(AB118>=HELPER!$B$8,1,MATCH(AB118,HELPER!$B$8:$B$48,-1)+1)),"")) | AD118: =IF(AC118="","",IFERROR(VLOOKUP(AC118,HELPER!$F$8:$G$48,2,FALSE),""))

Sheet TERM 1 PE and H
B2: CLASS RECORD
E5: REGION | F5: =IF('INPUT DATA'!E10="","",'INPUT DATA'!E10) | Q5: DIVISION | R5: =IF('INPUT DATA'!E11="","",'INPUT DATA'!E11) | Y5: SCHOOL ID | Z5: =IF('INPUT DATA'!E13="","",'INPUT DATA'!E13)
E7: SCHOOL NAME | F7: =IF('INPUT DATA'!E14="","",'INPUT DATA'!E14) | Y7: SCHOOL YEAR | Z7: =IF('INPUT DATA'!E15="","",'INPUT DATA'!E15)
B10: FIRST TERM | F10: GRADE LEVEL | J10: =IF('INPUT DATA'!E25="","",'INPUT DATA'!E25) | N10: TEACHER | Q10: =IF('INPUT DATA'!E23="","",'INPUT DATA'!E23) | Y10: SUBJECT | AA10: Music and Arts
F11: SECTION | J11: =IF('INPUT DATA'!E26="","",'INPUT DATA'!E26)
F12: WRITTEN / ORAL WORKS (WWs) | N12: PRODUCT / PERFORMANCE TASKS (PTs) | T12: EXAMINATIONS (EXs) | AB12: Initial Grade | AC12: Term Grade | AD12: Descriptor
F14: 1 | G14: 2 | H14: 3 | I14: 4 | J14: 5 | K14: Total | L14: PS | M14: WS | N14: 1 | O14: 2 | P14: 3 | Q14: Total | R14: PS | S14: WS | T14: ST1 | U14: ST2 | V14: TE | W14: WS ST1 | X14: WS ST2 | Y14: WS TE | Z14: PS | AA14: WS
B15: HIGHEST POSSIBLE SCORE | K15: =IF(COUNT(F15:J15)=0,"",SUM(F15:J15)) | L15: 100 | M15: 0.2 | Q15: =IF(COUNT(N15:P15)=0,"",SUM(N15:P15)) | R15: 100 | S15: 0.6 | W15: 30 | X15: 30 | Y15: 40 | Z15: 100 | AA15: 0.2
B16: LEARNERS' NAMES
B17: MALE
B18: 1 | C18: =IF('INPUT DATA'!K11="","",'INPUT DATA'!K11) | K18: =IF(COUNT($F18:$J18)=0,"",SUM($F18:$J18)) | L18: =IF(COUNT(F18:J18)=0,"",IFERROR(K18/$K$15*$L$15,"")) | M18: =IF(L18="","",L18*$M$15) | Q18: =IF(COUNT(N18:P18)=0,"",SUM(N18:P18)) | R18: =IF(COUNT(N18:P18)=0,"",IFERROR(Q18/$Q$15*$R$15,"")) | S18: =IF(R18="","",R18*$S$15) | W18: =IF(T18="","",IFERROR(T18/$T$15*$W$15,"")) | X18: =IF(U18="","",IFERROR(U18/$U$15*$X$15,"")) | Y18: =IF(V18="","",IFERROR(V18/$V$15*$Y$15,"")) | Z18: =IF(COUNT(T18:V18)=0,"",SUM(W18:Y18)) | AA18: =IF(Z18="","",Z18*$AA$15) | AB18: =IF(COUNT(F18:J18,N18:P18,T18:V18)=0,"",SUM(M18,S18,AA18)) | AC18: =IF(AB18="","",IFERROR(INDEX(HELPER!$D$8:$D$48,IF(AB18>=HELPER!$B$8,1,MATCH(AB18,HELPER!$B$8:$B$48,-1)+1)),"")) | AD18: =IF(AC18="","",IFERROR(VLOOKUP(AC18,HELPER!$F$8:$G$48,2,FALSE),""))
B19: 2 | C19: =IF('INPUT DATA'!K12="","",'INPUT DATA'!K12) | K19: =IF(COUNT($F19:$J19)=0,"",SUM($F19:$J19)) | L19: =IF(COUNT(F19:J19)=0,"",IFERROR(K19/$K$15*$L$15,"")) | M19: =IF(L19="","",L19*$M$15) | Q19: =IF(COUNT(N19:P19)=0,"",SUM(N19:P19)) | R19: =IF(COUNT(N19:P19)=0,"",IFERROR(Q19/$Q$15*$R$15,"")) | S19: =IF(R19="","",R19*$S$15) | W19: =IF(T19="","",IFERROR(T19/$T$15*$W$15,"")) | X19: =IF(U19="","",IFERROR(U19/$U$15*$X$15,"")) | Y19: =IF(V19="","",IFERROR(V19/$V$15*$Y$15,"")) | Z19: =IF(COUNT(T19:V19)=0,"",SUM(W19:Y19)) | AA19: =IF(Z19="","",Z19*$AA$15) | AB19: =IF(COUNT(F19:J19,N19:P19,T19:V19)=0,"",SUM(M19,S19,AA19)) | AC19: =IF(AB19="","",IFERROR(INDEX(HELPER!$D$8:$D$48,IF(AB19>=HELPER!$B$8,1,MATCH(AB19,HELPER!$B$8:$B$48,-1)+1)),"")) | AD19: =IF(AC19="","",IFERROR(VLOOKUP(AC19,HELPER!$F$8:$G$48,2,FALSE),""))
B20: 3 | C20: =IF('INPUT DATA'!K13="","",'INPUT DATA'!K13) | K20: =IF(COUNT($F20:$J20)=0,"",SUM($F20:$J20)) | L20: =IF(COUNT(F20:J20)=0,"",IFERROR(K20/$K$15*$L$15,"")) | M20: =IF(L20="","",L20*$M$15) | Q20: =IF(COUNT(N20:P20)=0,"",SUM(N20:P20)) | R20: =IF(COUNT(N20:P20)=0,"",IFERROR(Q20/$Q$15*$R$15,"")) | S20: =IF(R20="","",R20*$S$15) | W20: =IF(T20="","",IFERROR(T20/$T$15*$W$15,"")) | X20: =IF(U20="","",IFERROR(U20/$U$15*$X$15,"")) | Y20: =IF(V20="","",IFERROR(V20/$V$15*$Y$15,"")) | Z20: =IF(COUNT(T20:V20)=0,"",SUM(W20:Y20)) | AA20: =IF(Z20="","",Z20*$AA$15) | AB20: =IF(COUNT(F20:J20,N20:P20,T20:V20)=0,"",SUM(M20,S20,AA20)) | AC20: =IF(AB20="","",IFERROR(INDEX(HELPER!$D$8:$D$48,IF(AB20>=HELPER!$B$8,1,MATCH(AB20,HELPER!$B$8:$B$48,-1)+1)),"")) | AD20: =IF(AC20="","",IFERROR(VLOOKUP(AC20,HELPER!$F$8:$G$48,2,FALSE),""))
B21: 4 | C21: =IF('INPUT DATA'!K14="","",'INPUT DATA'!K14) | K21: =IF(COUNT($F21:$J21)=0,"",SUM($F21:$J21)) | L21: =IF(COUNT(F21:J21)=0,"",IFERROR(K21/$K$15*$L$15,"")) | M21: =IF(L21="","",L21*$M$15) | Q21: =IF(COUNT(N21:P21)=0,"",SUM(N21:P21)) | R21: =IF(COUNT(N21:P21)=0,"",IFERROR(Q21/$Q$15*$R$15,"")) | S21: =IF(R21="","",R21*$S$15) | W21: =IF(T21="","",IFERROR(T21/$T$15*$W$15,"")) | X21: =IF(U21="","",IFERROR(U21/$U$15*$X$15,"")) | Y21: =IF(V21="","",IFERROR(V21/$V$15*$Y$15,"")) | Z21: =IF(COUNT(T21:V21)=0,"",SUM(W21:Y21)) | AA21: =IF(Z21="","",Z21*$AA$15) | AB21: =IF(COUNT(F21:J21,N21:P21,T21:V21)=0,"",SUM(M21,S21,AA21)) | AC21: =IF(AB21="","",IFERROR(INDEX(HELPER!$D$8:$D$48,IF(AB21>=HELPER!$B$8,1,MATCH(AB21,HELPER!$B$8:$B$48,-1)+1)),"")) | AD21: =IF(AC21="","",IFERROR(VLOOKUP(AC21,HELPER!$F$8:$G$48,2,FALSE),""))
B22: 5 | C22: =IF('INPUT DATA'!K15="","",'INPUT DATA'!K15) | K22: =IF(COUNT($F22:$J22)=0,"",SUM($F22:$J22)) | L22: =IF(COUNT(F22:J22)=0,"",IFERROR(K22/$K$15*$L$15,"")) | M22: =IF(L22="","",L22*$M$15) | Q22: =IF(COUNT(N22:P22)=0,"",SUM(N22:P22)) | R22: =IF(COUNT(N22:P22)=0,"",IFERROR(Q22/$Q$15*$R$15,"")) | S22: =IF(R22="","",R22*$S$15) | W22: =IF(T22="","",IFERROR(T22/$T$15*$W$15,"")) | X22: =IF(U22="","",IFERROR(U22/$U$15*$X$15,"")) | Y22: =IF(V22="","",IFERROR(V22/$V$15*$Y$15,"")) | Z22: =IF(COUNT(T22:V22)=0,"",SUM(W22:Y22)) | AA22: =IF(Z22="","",Z22*$AA$15) | AB22: =IF(COUNT(F22:J22,N22:P22,T22:V22)=0,"",SUM(M22,S22,AA22)) | AC22: =IF(AB22="","",IFERROR(INDEX(HELPER!$D$8:$D$48,IF(AB22>=HELPER!$B$8,1,MATCH(AB22,HELPER!$B$8:$B$48,-1)+1)),"")) | AD22: =IF(AC22="","",IFERROR(VLOOKUP(AC22,HELPER!$F$8:$G$48,2,FALSE),""))
B23: 6 | C23: =IF('INPUT DATA'!K16="","",'INPUT DATA'!K16) | K23: =IF(COUNT($F23:$J23)=0,"",SUM($F23:$J23)) | L23: =IF(COUNT(F23:J23)=0,"",IFERROR(K23/$K$15*$L$15,"")) | M23: =IF(L23="","",L23*$M$15) | Q23: =IF(COUNT(N23:P23)=0,"",SUM(N23:P23)) | R23: =IF(COUNT(N23:P23)=0,"",IFERROR(Q23/$Q$15*$R$15,"")) | S23: =IF(R23="","",R23*$S$15) | W23: =IF(T23="","",IFERROR(T23/$T$15*$W$15,"")) | X23: =IF(U23="","",IFERROR(U23/$U$15*$X$15,"")) | Y23: =IF(V23="","",IFERROR(V23/$V$15*$Y$15,"")) | Z23: =IF(COUNT(T23:V23)=0,"",SUM(W23:Y23)) | AA23: =IF(Z23="","",Z23*$AA$15) | AB23: =IF(COUNT(F23:J23,N23:P23,T23:V23)=0,"",SUM(M23,S23,AA23)) | AC23: =IF(AB23="","",IFERROR(INDEX(HELPER!$D$8:$D$48,IF(AB23>=HELPER!$B$8,1,MATCH(AB23,HELPER!$B$8:$B$48,-1)+1)),"")) | AD23: =IF(AC23="","",IFERROR(VLOOKUP(AC23,HELPER!$F$8:$G$48,2,FALSE),""))
B24: 7 | C24: =IF('INPUT DATA'!K17="","",'INPUT DATA'!K17) | K24: =IF(COUNT($F24:$J24)=0,"",SUM($F24:$J24)) | L24: =IF(COUNT(F24:J24)=0,"",IFERROR(K24/$K$15*$L$15,"")) | M24: =IF(L24="","",L24*$M$15) | Q24: =IF(COUNT(N24:P24)=0,"",SUM(N24:P24)) | R24: =IF(COUNT(N24:P24)=0,"",IFERROR(Q24/$Q$15*$R$15,"")) | S24: =IF(R24="","",R24*$S$15) | W24: =IF(T24="","",IFERROR(T24/$T$15*$W$15,"")) | X24: =IF(U24="","",IFERROR(U24/$U$15*$X$15,"")) | Y24: =IF(V24="","",IFERROR(V24/$V$15*$Y$15,"")) | Z24: =IF(COUNT(T24:V24)=0,"",SUM(W24:Y24)) | AA24: =IF(Z24="","",Z24*$AA$15) | AB24: =IF(COUNT(F24:J24,N24:P24,T24:V24)=0,"",SUM(M24,S24,AA24)) | AC24: =IF(AB24="","",IFERROR(INDEX(HELPER!$D$8:$D$48,IF(AB24>=HELPER!$B$8,1,MATCH(AB24,HELPER!$B$8:$B$48,-1)+1)),"")) | AD24: =IF(AC24="","",IFERROR(VLOOKUP(AC24,HELPER!$F$8:$G$48,2,FALSE),""))
B25: 8 | C25: =IF('INPUT DATA'!K18="","",'INPUT DATA'!K18) | K25: =IF(COUNT($F25:$J25)=0,"",SUM($F25:$J25)) | L25: =IF(COUNT(F25:J25)=0,"",IFERROR(K25/$K$15*$L$15,"")) | M25: =IF(L25="","",L25*$M$15) | Q25: =IF(COUNT(N25:P25)=0,"",SUM(N25:P25)) | R25: =IF(COUNT(N25:P25)=0,"",IFERROR(Q25/$Q$15*$R$15,"")) | S25: =IF(R25="","",R25*$S$15) | W25: =IF(T25="","",IFERROR(T25/$T$15*$W$15,"")) | X25: =IF(U25="","",IFERROR(U25/$U$15*$X$15,"")) | Y25: =IF(V25="","",IFERROR(V25/$V$15*$Y$15,"")) | Z25: =IF(COUNT(T25:V25)=0,"",SUM(W25:Y25)) | AA25: =IF(Z25="","",Z25*$AA$15) | AB25: =IF(COUNT(F25:J25,N25:P25,T25:V25)=0,"",SUM(M25,S25,AA25)) | AC25: =IF(AB25="","",IFERROR(INDEX(HELPER!$D$8:$D$48,IF(AB25>=HELPER!$B$8,1,MATCH(AB25,HELPER!$B$8:$B$48,-1)+1)),"")) | AD25: =IF(AC25="","",IFERROR(VLOOKUP(AC25,HELPER!$F$8:$G$48,2,FALSE),""))
B26: 9 | C26: =IF('INPUT DATA'!K19="","",'INPUT DATA'!K19) | K26: =IF(COUNT($F26:$J26)=0,"",SUM($F26:$J26)) | L26: =IF(COUNT(F26:J26)=0,"",IFERROR(K26/$K$15*$L$15,"")) | M26: =IF(L26="","",L26*$M$15) | Q26: =IF(COUNT(N26:P26)=0,"",SUM(N26:P26)) | R26: =IF(COUNT(N26:P26)=0,"",IFERROR(Q26/$Q$15*$R$15,"")) | S26: =IF(R26="","",R26*$S$15) | W26: =IF(T26="","",IFERROR(T26/$T$15*$W$15,"")) | X26: =IF(U26="","",IFERROR(U26/$U$15*$X$15,"")) | Y26: =IF(V26="","",IFERROR(V26/$V$15*$Y$15,"")) | Z26: =IF(COUNT(T26:V26)=0,"",SUM(W26:Y26)) | AA26: =IF(Z26="","",Z26*$AA$15) | AB26: =IF(COUNT(F26:J26,N26:P26,T26:V26)=0,"",SUM(M26,S26,AA26)) | AC26: =IF(AB26="","",IFERROR(INDEX(HELPER!$D$8:$D$48,IF(AB26>=HELPER!$B$8,1,MATCH(AB26,HELPER!$B$8:$B$48,-1)+1)),"")) | AD26: =IF(AC26="","",IFERROR(VLOOKUP(AC26,HELPER!$F$8:$G$48,2,FALSE),""))
B27: 10 | C27: =IF('INPUT DATA'!K20="","",'INPUT DATA'!K20) | K27: =IF(COUNT($F27:$J27)=0,"",SUM($F27:$J27)) | L27: =IF(COUNT(F27:J27)=0,"",IFERROR(K27/$K$15*$L$15,"")) | M27: =IF(L27="","",L27*$M$15) | Q27: =IF(COUNT(N27:P27)=0,"",SUM(N27:P27)) | R27: =IF(COUNT(N27:P27)=0,"",IFERROR(Q27/$Q$15*$R$15,"")) | S27: =IF(R27="","",R27*$S$15) | W27: =IF(T27="","",IFERROR(T27/$T$15*$W$15,"")) | X27: =IF(U27="","",IFERROR(U27/$U$15*$X$15,"")) | Y27: =IF(V27="","",IFERROR(V27/$V$15*$Y$15,"")) | Z27: =IF(COUNT(T27:V27)=0,"",SUM(W27:Y27)) | AA27: =IF(Z27="","",Z27*$AA$15) | AB27: =IF(COUNT(F27:J27,N27:P27,T27:V27)=0,"",SUM(M27,S27,AA27)) | AC27: =IF(AB27="","",IFERROR(INDEX(HELPER!$D$8:$D$48,IF(AB27>=HELPER!$B$8,1,MATCH(AB27,HELPER!$B$8:$B$48,-1)+1)),"")) | AD27: =IF(AC27="","",IFERROR(VLOOKUP(AC27,HELPER!$F$8:$G$48,2,FALSE),""))
B28: 11 | C28: =IF('INPUT DATA'!K21="","",'INPUT DATA'!K21) | K28: =IF(COUNT($F28:$J28)=0,"",SUM($F28:$J28)) | L28: =IF(COUNT(F28:J28)=0,"",IFERROR(K28/$K$15*$L$15,"")) | M28: =IF(L28="","",L28*$M$15) | Q28: =IF(COUNT(N28:P28)=0,"",SUM(N28:P28)) | R28: =IF(COUNT(N28:P28)=0,"",IFERROR(Q28/$Q$15*$R$15,"")) | S28: =IF(R28="","",R28*$S$15) | W28: =IF(T28="","",IFERROR(T28/$T$15*$W$15,"")) | X28: =IF(U28="","",IFERROR(U28/$U$15*$X$15,"")) | Y28: =IF(V28="","",IFERROR(V28/$V$15*$Y$15,"")) | Z28: =IF(COUNT(T28:V28)=0,"",SUM(W28:Y28)) | AA28: =IF(Z28="","",Z28*$AA$15) | AB28: =IF(COUNT(F28:J28,N28:P28,T28:V28)=0,"",SUM(M28,S28,AA28)) | AC28: =IF(AB28="","",IFERROR(INDEX(HELPER!$D$8:$D$48,IF(AB28>=HELPER!$B$8,1,MATCH(AB28,HELPER!$B$8:$B$48,-1)+1)),"")) | AD28: =IF(AC28="","",IFERROR(VLOOKUP(AC28,HELPER!$F$8:$G$48,2,FALSE),""))
B29: 12 | C29: =IF('INPUT DATA'!K22="","",'INPUT DATA'!K22) | K29: =IF(COUNT($F29:$J29)=0,"",SUM($F29:$J29)) | L29: =IF(COUNT(F29:J29)=0,"",IFERROR(K29/$K$15*$L$15,"")) | M29: =IF(L29="","",L29*$M$15) | Q29: =IF(COUNT(N29:P29)=0,"",SUM(N29:P29)) | R29: =IF(COUNT(N29:P29)=0,"",IFERROR(Q29/$Q$15*$R$15,"")) | S29: =IF(R29="","",R29*$S$15) | W29: =IF(T29="","",IFERROR(T29/$T$15*$W$15,"")) | X29: =IF(U29="","",IFERROR(U29/$U$15*$X$15,"")) | Y29: =IF(V29="","",IFERROR(V29/$V$15*$Y$15,"")) | Z29: =IF(COUNT(T29:V29)=0,"",SUM(W29:Y29)) | AA29: =IF(Z29="","",Z29*$AA$15) | AB29: =IF(COUNT(F29:J29,N29:P29,T29:V29)=0,"",SUM(M29,S29,AA29)) | AC29: =IF(AB29="","",IFERROR(INDEX(HELPER!$D$8:$D$48,IF(AB29>=HELPER!$B$8,1,MATCH(AB29,HELPER!$B$8:$B$48,-1)+1)),"")) | AD29: =IF(AC29="","",IFERROR(VLOOKUP(AC29,HELPER!$F$8:$G$48,2,FALSE),""))
... B67: 50 | C67: =IF('INPUT DATA'!K60="","",'INPUT DATA'!K60) | K67: =IF(COUNT($F67:$J67)=0,"",SUM($F67:$J67)) | L67: =IF(COUNT(F67:J67)=0,"",IFERROR(K67/$K$15*$L$15,"")) | M67: =IF(L67="","",L67*$M$15) | Q67: =IF(COUNT(N67:P67)=0,"",SUM(N67:P67)) | R67: =IF(COUNT(N67:P67)=0,"",IFERROR(Q67/$Q$15*$R$15,"")) | S67: =IF(R67="","",R67*$S$15) | W67: =IF(T67="","",IFERROR(T67/$T$15*$W$15,"")) | X67: =IF(U67="","",IFERROR(U67/$U$15*$X$15,"")) | Y67: =IF(V67="","",IFERROR(V67/$V$15*$Y$15,"")) | Z67: =IF(COUNT(T67:V67)=0,"",SUM(W67:Y67)) | AA67: =IF(Z67="","",Z67*$AA$15) | AB67: =IF(COUNT(F67:J67,N67:P67,T67:V67)=0,"",SUM(M67,S67,AA67)) | AC67: =IF(AB67="","",IFERROR(INDEX(HELPER!$D$8:$D$48,IF(AB67>=HELPER!$B$8,1,MATCH(AB67,HELPER!$B$8:$B$48,-1)+1)),"")) | AD67: =IF(AC67="","",IFERROR(VLOOKUP(AC67,HELPER!$F$8:$G$48,2,FALSE),""))
B68: FEMALE
B69: 1 | C69: =IF('INPUT DATA'!N11="","",'INPUT DATA'!N11) | K69: =IF(COUNT($F69:$J69)=0,"",SUM($F69:$J69)) | L69: =IF(COUNT(F69:J69)=0,"",IFERROR(K69/$K$15*$L$15,"")) | M69: =IF(L69="","",L69*$M$15) | Q69: =IF(COUNT(N69:P69)=0,"",SUM(N69:P69)) | R69: =IF(COUNT(N69:P69)=0,"",IFERROR(Q69/$Q$15*$R$15,"")) | S69: =IF(R69="","",R69*$S$15) | W69: =IF(T69="","",IFERROR(T69/$T$15*$W$15,"")) | X69: =IF(U69="","",IFERROR(U69/$U$15*$X$15,"")) | Y69: =IF(V69="","",IFERROR(V69/$V$15*$Y$15,"")) | Z69: =IF(COUNT(T69:V69)=0,"",SUM(W69:Y69)) | AA69: =IF(Z69="","",Z69*$AA$15) | AB69: =IF(COUNT(F69:J69,N69:P69,T69:V69)=0,"",SUM(M69,S69,AA69)) | AC69: =IF(AB69="","",IFERROR(INDEX(HELPER!$D$8:$D$48,IF(AB69>=HELPER!$B$8,1,MATCH(AB69,HELPER!$B$8:$B$48,-1)+1)),"")) | AD69: =IF(AC69="","",IFERROR(VLOOKUP(AC69,HELPER!$F$8:$G$48,2,FALSE),""))
B70: 2 | C70: =IF('INPUT DATA'!N12="","",'INPUT DATA'!N12) | K70: =IF(COUNT($F70:$J70)=0,"",SUM($F70:$J70)) | L70: =IF(COUNT(F70:J70)=0,"",IFERROR(K70/$K$15*$L$15,"")) | M70: =IF(L70="","",L70*$M$15) | Q70: =IF(COUNT(N70:P70)=0,"",SUM(N70:P70)) | R70: =IF(COUNT(N70:P70)=0,"",IFERROR(Q70/$Q$15*$R$15,"")) | S70: =IF(R70="","",R70*$S$15) | W70: =IF(T70="","",IFERROR(T70/$T$15*$W$15,"")) | X70: =IF(U70="","",IFERROR(U70/$U$15*$X$15,"")) | Y70: =IF(V70="","",IFERROR(V70/$V$15*$Y$15,"")) | Z70: =IF(COUNT(T70:V70)=0,"",SUM(W70:Y70)) | AA70: =IF(Z70="","",Z70*$AA$15) | AB70: =IF(COUNT(F70:J70,N70:P70,T70:V70)=0,"",SUM(M70,S70,AA70)) | AC70: =IF(AB70="","",IFERROR(INDEX(HELPER!$D$8:$D$48,IF(AB70>=HELPER!$B$8,1,MATCH(AB70,HELPER!$B$8:$B$48,-1)+1)),"")) | AD70: =IF(AC70="","",IFERROR(VLOOKUP(AC70,HELPER!$F$8:$G$48,2,FALSE),""))
B71: 3 | C71: =IF('INPUT DATA'!N13="","",'INPUT DATA'!N13) | K71: =IF(COUNT($F71:$J71)=0,"",SUM($F71:$J71)) | L71: =IF(COUNT(F71:J71)=0,"",IFERROR(K71/$K$15*$L$15,"")) | M71: =IF(L71="","",L71*$M$15) | Q71: =IF(COUNT(N71:P71)=0,"",SUM(N71:P71)) | R71: =IF(COUNT(N71:P71)=0,"",IFERROR(Q71/$Q$15*$R$15,"")) | S71: =IF(R71="","",R71*$S$15) | W71: =IF(T71="","",IFERROR(T71/$T$15*$W$15,"")) | X71: =IF(U71="","",IFERROR(U71/$U$15*$X$15,"")) | Y71: =IF(V71="","",IFERROR(V71/$V$15*$Y$15,"")) | Z71: =IF(COUNT(T71:V71)=0,"",SUM(W71:Y71)) | AA71: =IF(Z71="","",Z71*$AA$15) | AB71: =IF(COUNT(F71:J71,N71:P71,T71:V71)=0,"",SUM(M71,S71,AA71)) | AC71: =IF(AB71="","",IFERROR(INDEX(HELPER!$D$8:$D$48,IF(AB71>=HELPER!$B$8,1,MATCH(AB71,HELPER!$B$8:$B$48,-1)+1)),"")) | AD71: =IF(AC71="","",IFERROR(VLOOKUP(AC71,HELPER!$F$8:$G$48,2,FALSE),""))
B72: 4 | C72: =IF('INPUT DATA'!N14="","",'INPUT DATA'!N14) | K72: =IF(COUNT($F72:$J72)=0,"",SUM($F72:$J72)) | L72: =IF(COUNT(F72:J72)=0,"",IFERROR(K72/$K$15*$L$15,"")) | M72: =IF(L72="","",L72*$M$15) | Q72: =IF(COUNT(N72:P72)=0,"",SUM(N72:P72)) | R72: =IF(COUNT(N72:P72)=0,"",IFERROR(Q72/$Q$15*$R$15,"")) | S72: =IF(R72="","",R72*$S$15) | W72: =IF(T72="","",IFERROR(T72/$T$15*$W$15,"")) | X72: =IF(U72="","",IFERROR(U72/$U$15*$X$15,"")) | Y72: =IF(V72="","",IFERROR(V72/$V$15*$Y$15,"")) | Z72: =IF(COUNT(T72:V72)=0,"",SUM(W72:Y72)) | AA72: =IF(Z72="","",Z72*$AA$15) | AB72: =IF(COUNT(F72:J72,N72:P72,T72:V72)=0,"",SUM(M72,S72,AA72)) | AC72: =IF(AB72="","",IFERROR(INDEX(HELPER!$D$8:$D$48,IF(AB72>=HELPER!$B$8,1,MATCH(AB72,HELPER!$B$8:$B$48,-1)+1)),"")) | AD72: =IF(AC72="","",IFERROR(VLOOKUP(AC72,HELPER!$F$8:$G$48,2,FALSE),""))
B73: 5 | C73: =IF('INPUT DATA'!N15="","",'INPUT DATA'!N15) | K73: =IF(COUNT($F73:$J73)=0,"",SUM($F73:$J73)) | L73: =IF(COUNT(F73:J73)=0,"",IFERROR(K73/$K$15*$L$15,"")) | M73: =IF(L73="","",L73*$M$15) | Q73: =IF(COUNT(N73:P73)=0,"",SUM(N73:P73)) | R73: =IF(COUNT(N73:P73)=0,"",IFERROR(Q73/$Q$15*$R$15,"")) | S73: =IF(R73="","",R73*$S$15) | W73: =IF(T73="","",IFERROR(T73/$T$15*$W$15,"")) | X73: =IF(U73="","",IFERROR(U73/$U$15*$X$15,"")) | Y73: =IF(V73="","",IFERROR(V73/$V$15*$Y$15,"")) | Z73: =IF(COUNT(T73:V73)=0,"",SUM(W73:Y73)) | AA73: =IF(Z73="","",Z73*$AA$15) | AB73: =IF(COUNT(F73:J73,N73:P73,T73:V73)=0,"",SUM(M73,S73,AA73)) | AC73: =IF(AB73="","",IFERROR(INDEX(HELPER!$D$8:$D$48,IF(AB73>=HELPER!$B$8,1,MATCH(AB73,HELPER!$B$8:$B$48,-1)+1)),"")) | AD73: =IF(AC73="","",IFERROR(VLOOKUP(AC73,HELPER!$F$8:$G$48,2,FALSE),""))
B74: 6 | C74: =IF('INPUT DATA'!N16="","",'INPUT DATA'!N16) | K74: =IF(COUNT($F74:$J74)=0,"",SUM($F74:$J74)) | L74: =IF(COUNT(F74:J74)=0,"",IFERROR(K74/$K$15*$L$15,"")) | M74: =IF(L74="","",L74*$M$15) | Q74: =IF(COUNT(N74:P74)=0,"",SUM(N74:P74)) | R74: =IF(COUNT(N74:P74)=0,"",IFERROR(Q74/$Q$15*$R$15,"")) | S74: =IF(R74="","",R74*$S$15) | W74: =IF(T74="","",IFERROR(T74/$T$15*$W$15,"")) | X74: =IF(U74="","",IFERROR(U74/$U$15*$X$15,"")) | Y74: =IF(V74="","",IFERROR(V74/$V$15*$Y$15,"")) | Z74: =IF(COUNT(T74:V74)=0,"",SUM(W74:Y74)) | AA74: =IF(Z74="","",Z74*$AA$15) | AB74: =IF(COUNT(F74:J74,N74:P74,T74:V74)=0,"",SUM(M74,S74,AA74)) | AC74: =IF(AB74="","",IFERROR(INDEX(HELPER!$D$8:$D$48,IF(AB74>=HELPER!$B$8,1,MATCH(AB74,HELPER!$B$8:$B$48,-1)+1)),"")) | AD74: =IF(AC74="","",IFERROR(VLOOKUP(AC74,HELPER!$F$8:$G$48,2,FALSE),""))
B75: 7 | C75: =IF('INPUT DATA'!N17="","",'INPUT DATA'!N17) | K75: =IF(COUNT($F75:$J75)=0,"",SUM($F75:$J75)) | L75: =IF(COUNT(F75:J75)=0,"",IFERROR(K75/$K$15*$L$15,"")) | M75: =IF(L75="","",L75*$M$15) | Q75: =IF(COUNT(N75:P75)=0,"",SUM(N75:P75)) | R75: =IF(COUNT(N75:P75)=0,"",IFERROR(Q75/$Q$15*$R$15,"")) | S75: =IF(R75="","",R75*$S$15) | W75: =IF(T75="","",IFERROR(T75/$T$15*$W$15,"")) | X75: =IF(U75="","",IFERROR(U75/$U$15*$X$15,"")) | Y75: =IF(V75="","",IFERROR(V75/$V$15*$Y$15,"")) | Z75: =IF(COUNT(T75:V75)=0,"",SUM(W75:Y75)) | AA75: =IF(Z75="","",Z75*$AA$15) | AB75: =IF(COUNT(F75:J75,N75:P75,T75:V75)=0,"",SUM(M75,S75,AA75)) | AC75: =IF(AB75="","",IFERROR(INDEX(HELPER!$D$8:$D$48,IF(AB75>=HELPER!$B$8,1,MATCH(AB75,HELPER!$B$8:$B$48,-1)+1)),"")) | AD75: =IF(AC75="","",IFERROR(VLOOKUP(AC75,HELPER!$F$8:$G$48,2,FALSE),""))
B76: 8 | C76: =IF('INPUT DATA'!N18="","",'INPUT DATA'!N18) | K76: =IF(COUNT($F76:$J76)=0,"",SUM($F76:$J76)) | L76: =IF(COUNT(F76:J76)=0,"",IFERROR(K76/$K$15*$L$15,"")) | M76: =IF(L76="","",L76*$M$15) | Q76: =IF(COUNT(N76:P76)=0,"",SUM(N76:P76)) | R76: =IF(COUNT(N76:P76)=0,"",IFERROR(Q76/$Q$15*$R$15,"")) | S76: =IF(R76="","",R76*$S$15) | W76: =IF(T76="","",IFERROR(T76/$T$15*$W$15,"")) | X76: =IF(U76="","",IFERROR(U76/$U$15*$X$15,"")) | Y76: =IF(V76="","",IFERROR(V76/$V$15*$Y$15,"")) | Z76: =IF(COUNT(T76:V76)=0,"",SUM(W76:Y76)) | AA76: =IF(Z76="","",Z76*$AA$15) | AB76: =IF(COUNT(F76:J76,N76:P76,T76:V76)=0,"",SUM(M76,S76,AA76)) | AC76: =IF(AB76="","",IFERROR(INDEX(HELPER!$D$8:$D$48,IF(AB76>=HELPER!$B$8,1,MATCH(AB76,HELPER!$B$8:$B$48,-1)+1)),"")) | AD76: =IF(AC76="","",IFERROR(VLOOKUP(AC76,HELPER!$F$8:$G$48,2,FALSE),""))
B77: 9 | C77: =IF('INPUT DATA'!N19="","",'INPUT DATA'!N19) | K77: =IF(COUNT($F77:$J77)=0,"",SUM($F77:$J77)) | L77: =IF(COUNT(F77:J77)=0,"",IFERROR(K77/$K$15*$L$15,"")) | M77: =IF(L77="","",L77*$M$15) | Q77: =IF(COUNT(N77:P77)=0,"",SUM(N77:P77)) | R77: =IF(COUNT(N77:P77)=0,"",IFERROR(Q77/$Q$15*$R$15,"")) | S77: =IF(R77="","",R77*$S$15) | W77: =IF(T77="","",IFERROR(T77/$T$15*$W$15,"")) | X77: =IF(U77="","",IFERROR(U77/$U$15*$X$15,"")) | Y77: =IF(V77="","",IFERROR(V77/$V$15*$Y$15,"")) | Z77: =IF(COUNT(T77:V77)=0,"",SUM(W77:Y77)) | AA77: =IF(Z77="","",Z77*$AA$15) | AB77: =IF(COUNT(F77:J77,N77:P77,T77:V77)=0,"",SUM(M77,S77,AA77)) | AC77: =IF(AB77="","",IFERROR(INDEX(HELPER!$D$8:$D$48,IF(AB77>=HELPER!$B$8,1,MATCH(AB77,HELPER!$B$8:$B$48,-1)+1)),"")) | AD77: =IF(AC77="","",IFERROR(VLOOKUP(AC77,HELPER!$F$8:$G$48,2,FALSE),""))
B78: 10 | C78: =IF('INPUT DATA'!N20="","",'INPUT DATA'!N20) | K78: =IF(COUNT($F78:$J78)=0,"",SUM($F78:$J78)) | L78: =IF(COUNT(F78:J78)=0,"",IFERROR(K78/$K$15*$L$15,"")) | M78: =IF(L78="","",L78*$M$15) | Q78: =IF(COUNT(N78:P78)=0,"",SUM(N78:P78)) | R78: =IF(COUNT(N78:P78)=0,"",IFERROR(Q78/$Q$15*$R$15,"")) | S78: =IF(R78="","",R78*$S$15) | W78: =IF(T78="","",IFERROR(T78/$T$15*$W$15,"")) | X78: =IF(U78="","",IFERROR(U78/$U$15*$X$15,"")) | Y78: =IF(V78="","",IFERROR(V78/$V$15*$Y$15,"")) | Z78: =IF(COUNT(T78:V78)=0,"",SUM(W78:Y78)) | AA78: =IF(Z78="","",Z78*$AA$15) | AB78: =IF(COUNT(F78:J78,N78:P78,T78:V78)=0,"",SUM(M78,S78,AA78)) | AC78: =IF(AB78="","",IFERROR(INDEX(HELPER!$D$8:$D$48,IF(AB78>=HELPER!$B$8,1,MATCH(AB78,HELPER!$B$8:$B$48,-1)+1)),"")) | AD78: =IF(AC78="","",IFERROR(VLOOKUP(AC78,HELPER!$F$8:$G$48,2,FALSE),""))
B79: 11 | C79: =IF('INPUT DATA'!N21="","",'INPUT DATA'!N21) | K79: =IF(COUNT($F79:$J79)=0,"",SUM($F79:$J79)) | L79: =IF(COUNT(F79:J79)=0,"",IFERROR(K79/$K$15*$L$15,"")) | M79: =IF(L79="","",L79*$M$15) | Q79: =IF(COUNT(N79:P79)=0,"",SUM(N79:P79)) | R79: =IF(COUNT(N79:P79)=0,"",IFERROR(Q79/$Q$15*$R$15,"")) | S79: =IF(R79="","",R79*$S$15) | W79: =IF(T79="","",IFERROR(T79/$T$15*$W$15,"")) | X79: =IF(U79="","",IFERROR(U79/$U$15*$X$15,"")) | Y79: =IF(V79="","",IFERROR(V79/$V$15*$Y$15,"")) | Z79: =IF(COUNT(T79:V79)=0,"",SUM(W79:Y79)) | AA79: =IF(Z79="","",Z79*$AA$15) | AB79: =IF(COUNT(F79:J79,N79:P79,T79:V79)=0,"",SUM(M79,S79,AA79)) | AC79: =IF(AB79="","",IFERROR(INDEX(HELPER!$D$8:$D$48,IF(AB79>=HELPER!$B$8,1,MATCH(AB79,HELPER!$B$8:$B$48,-1)+1)),"")) | AD79: =IF(AC79="","",IFERROR(VLOOKUP(AC79,HELPER!$F$8:$G$48,2,FALSE),""))
B80: 12 | C80: =IF('INPUT DATA'!N22="","",'INPUT DATA'!N22) | K80: =IF(COUNT($F80:$J80)=0,"",SUM($F80:$J80)) | L80: =IF(COUNT(F80:J80)=0,"",IFERROR(K80/$K$15*$L$15,"")) | M80: =IF(L80="","",L80*$M$15) | Q80: =IF(COUNT(N80:P80)=0,"",SUM(N80:P80)) | R80: =IF(COUNT(N80:P80)=0,"",IFERROR(Q80/$Q$15*$R$15,"")) | S80: =IF(R80="","",R80*$S$15) | W80: =IF(T80="","",IFERROR(T80/$T$15*$W$15,"")) | X80: =IF(U80="","",IFERROR(U80/$U$15*$X$15,"")) | Y80: =IF(V80="","",IFERROR(V80/$V$15*$Y$15,"")) | Z80: =IF(COUNT(T80:V80)=0,"",SUM(W80:Y80)) | AA80: =IF(Z80="","",Z80*$AA$15) | AB80: =IF(COUNT(F80:J80,N80:P80,T80:V80)=0,"",SUM(M80,S80,AA80)) | AC80: =IF(AB80="","",IFERROR(INDEX(HELPER!$D$8:$D$48,IF(AB80>=HELPER!$B$8,1,MATCH(AB80,HELPER!$B$8:$B$48,-1)+1)),"")) | AD80: =IF(AC80="","",IFERROR(VLOOKUP(AC80,HELPER!$F$8:$G$48,2,FALSE),""))
... B118: 50 | C118: =IF('INPUT DATA'!N60="","",'INPUT DATA'!N60) | K118: =IF(COUNT($F118:$J118)=0,"",SUM($F118:$J118)) | L118: =IF(COUNT(F118:J118)=0,"",IFERROR(K118/$K$15*$L$15,"")) | M118: =IF(L118="","",L118*$M$15) | Q118: =IF(COUNT(N118:P118)=0,"",SUM(N118:P118)) | R118: =IF(COUNT(N118:P118)=0,"",IFERROR(Q118/$Q$15*$R$15,"")) | S118: =IF(R118="","",R118*$S$15) | W118: =IF(T118="","",IFERROR(T118/$T$15*$W$15,"")) | X118: =IF(U118="","",IFERROR(U118/$U$15*$X$15,"")) | Y118: =IF(V118="","",IFERROR(V118/$V$15*$Y$15,"")) | Z118: =IF(COUNT(T118:V118)=0,"",SUM(W118:Y118)) | AA118: =IF(Z118="","",Z118*$AA$15) | AB118: =IF(COUNT(F118:J118,N118:P118,T118:V118)=0,"",SUM(M118,S118,AA118)) | AC118: =IF(AB118="","",IFERROR(INDEX(HELPER!$D$8:$D$48,IF(AB118>=HELPER!$B$8,1,MATCH(AB118,HELPER!$B$8:$B$48,-1)+1)),"")) | AD118: =IF(AC118="","",IFERROR(VLOOKUP(AC118,HELPER!$F$8:$G$48,2,FALSE),""))

Sheet TERM 2 M and A
B2: CLASS RECORD
E5: REGION | F5: =IF('INPUT DATA'!E10="","",'INPUT DATA'!E10) | Q5: DIVISION | R5: =IF('INPUT DATA'!E11="","",'INPUT DATA'!E11) | Y5: SCHOOL ID | Z5: =IF('INPUT DATA'!E13="","",'INPUT DATA'!E13)
E7: SCHOOL NAME | F7: =IF('INPUT DATA'!E14="","",'INPUT DATA'!E14) | Y7: SCHOOL YEAR | Z7: =IF('INPUT DATA'!E15="","",'INPUT DATA'!E15)
B10: SECOND TERM | F10: GRADE LEVEL | J10: =IF('INPUT DATA'!E25="","",'INPUT DATA'!E25) | N10: TEACHER | Q10: =IF('INPUT DATA'!E23="","",'INPUT DATA'!E23) | Y10: SUBJECT | AA10: Music and Arts
F11: SECTION | J11: =IF('INPUT DATA'!E26="","",'INPUT DATA'!E26)
F12: WRITTEN / ORAL WORKS (WWs) | N12: PRODUCT / PERFORMANCE TASKS (PTs) | T12: EXAMINATIONS (EXs) | AB12: Initial Grade | AC12: Term Grade | AD12: Descriptor
F14: 1 | G14: 2 | H14: 3 | I14: 4 | J14: 5 | K14: Total | L14: PS | M14: WS | N14: 1 | O14: 2 | P14: 3 | Q14: Total | R14: PS | S14: WS | T14: ST1 | U14: ST2 | V14: TE | W14: WS ST1 | X14: WS ST2 | Y14: WS TE | Z14: PS | AA14: WS
B15: HIGHEST POSSIBLE SCORE | K15: =IF(COUNT(F15:J15)=0,"",SUM(F15:J15)) | L15: 100 | M15: 0.2 | Q15: =IF(COUNT(N15:P15)=0,"",SUM(N15:P15)) | R15: 100 | S15: 0.6 | W15: 30 | X15: 30 | Y15: 40 | Z15: 100 | AA15: 0.2
B16: LEARNERS' NAMES
B17: MALE
B18: 1 | C18: =IF('INPUT DATA'!K11="","",'INPUT DATA'!K11) | K18: =IF(COUNT($F18:$J18)=0,"",SUM($F18:$J18)) | L18: =IF(COUNT(F18:J18)=0,"",IFERROR(K18/$K$15*$L$15,"")) | M18: =IF(L18="","",L18*$M$15) | Q18: =IF(COUNT(N18:P18)=0,"",SUM(N18:P18)) | R18: =IF(COUNT(N18:P18)=0,"",IFERROR(Q18/$Q$15*$R$15,"")) | S18: =IF(R18="","",R18*$S$15) | W18: =IF(T18="","",IFERROR(T18/$T$15*$W$15,"")) | X18: =IF(U18="","",IFERROR(U18/$U$15*$X$15,"")) | Y18: =IF(V18="","",IFERROR(V18/$V$15*$Y$15,"")) | Z18: =IF(COUNT(T18:V18)=0,"",SUM(W18:Y18)) | AA18: =IF(Z18="","",Z18*$AA$15) | AB18: =IF(COUNT(F18:J18,N18:P18,T18:V18)=0,"",SUM(M18,S18,AA18)) | AC18: =IF(AB18="","",IFERROR(INDEX(HELPER!$D$8:$D$48,IF(AB18>=HELPER!$B$8,1,MATCH(AB18,HELPER!$B$8:$B$48,-1)+1)),"")) | AD18: =IF(AC18="","",IFERROR(VLOOKUP(AC18,HELPER!$F$8:$G$48,2,FALSE),""))
B19: 2 | C19: =IF('INPUT DATA'!K12="","",'INPUT DATA'!K12) | K19: =IF(COUNT($F19:$J19)=0,"",SUM($F19:$J19)) | L19: =IF(COUNT(F19:J19)=0,"",IFERROR(K19/$K$15*$L$15,"")) | M19: =IF(L19="","",L19*$M$15) | Q19: =IF(COUNT(N19:P19)=0,"",SUM(N19:P19)) | R19: =IF(COUNT(N19:P19)=0,"",IFERROR(Q19/$Q$15*$R$15,"")) | S19: =IF(R19="","",R19*$S$15) | W19: =IF(T19="","",IFERROR(T19/$T$15*$W$15,"")) | X19: =IF(U19="","",IFERROR(U19/$U$15*$X$15,"")) | Y19: =IF(V19="","",IFERROR(V19/$V$15*$Y$15,"")) | Z19: =IF(COUNT(T19:V19)=0,"",SUM(W19:Y19)) | AA19: =IF(Z19="","",Z19*$AA$15) | AB19: =IF(COUNT(F19:J19,N19:P19,T19:V19)=0,"",SUM(M19,S19,AA19)) | AC19: =IF(AB19="","",IFERROR(INDEX(HELPER!$D$8:$D$48,IF(AB19>=HELPER!$B$8,1,MATCH(AB19,HELPER!$B$8:$B$48,-1)+1)),"")) | AD19: =IF(AC19="","",IFERROR(VLOOKUP(AC19,HELPER!$F$8:$G$48,2,FALSE),""))
B20: 3 | C20: =IF('INPUT DATA'!K13="","",'INPUT DATA'!K13) | K20: =IF(COUNT($F20:$J20)=0,"",SUM($F20:$J20)) | L20: =IF(COUNT(F20:J20)=0,"",IFERROR(K20/$K$15*$L$15,"")) | M20: =IF(L20="","",L20*$M$15) | Q20: =IF(COUNT(N20:P20)=0,"",SUM(N20:P20)) | R20: =IF(COUNT(N20:P20)=0,"",IFERROR(Q20/$Q$15*$R$15,"")) | S20: =IF(R20="","",R20*$S$15) | W20: =IF(T20="","",IFERROR(T20/$T$15*$W$15,"")) | X20: =IF(U20="","",IFERROR(U20/$U$15*$X$15,"")) | Y20: =IF(V20="","",IFERROR(V20/$V$15*$Y$15,"")) | Z20: =IF(COUNT(T20:V20)=0,"",SUM(W20:Y20)) | AA20: =IF(Z20="","",Z20*$AA$15) | AB20: =IF(COUNT(F20:J20,N20:P20,T20:V20)=0,"",SUM(M20,S20,AA20)) | AC20: =IF(AB20="","",IFERROR(INDEX(HELPER!$D$8:$D$48,IF(AB20>=HELPER!$B$8,1,MATCH(AB20,HELPER!$B$8:$B$48,-1)+1)),"")) | AD20: =IF(AC20="","",IFERROR(VLOOKUP(AC20,HELPER!$F$8:$G$48,2,FALSE),""))
B21: 4 | C21: =IF('INPUT DATA'!K14="","",'INPUT DATA'!K14) | K21: =IF(COUNT($F21:$J21)=0,"",SUM($F21:$J21)) | L21: =IF(COUNT(F21:J21)=0,"",IFERROR(K21/$K$15*$L$15,"")) | M21: =IF(L21="","",L21*$M$15) | Q21: =IF(COUNT(N21:P21)=0,"",SUM(N21:P21)) | R21: =IF(COUNT(N21:P21)=0,"",IFERROR(Q21/$Q$15*$R$15,"")) | S21: =IF(R21="","",R21*$S$15) | W21: =IF(T21="","",IFERROR(T21/$T$15*$W$15,"")) | X21: =IF(U21="","",IFERROR(U21/$U$15*$X$15,"")) | Y21: =IF(V21="","",IFERROR(V21/$V$15*$Y$15,"")) | Z21: =IF(COUNT(T21:V21)=0,"",SUM(W21:Y21)) | AA21: =IF(Z21="","",Z21*$AA$15) | AB21: =IF(COUNT(F21:J21,N21:P21,T21:V21)=0,"",SUM(M21,S21,AA21)) | AC21: =IF(AB21="","",IFERROR(INDEX(HELPER!$D$8:$D$48,IF(AB21>=HELPER!$B$8,1,MATCH(AB21,HELPER!$B$8:$B$48,-1)+1)),"")) | AD21: =IF(AC21="","",IFERROR(VLOOKUP(AC21,HELPER!$F$8:$G$48,2,FALSE),""))
B22: 5 | C22: =IF('INPUT DATA'!K15="","",'INPUT DATA'!K15) | K22: =IF(COUNT($F22:$J22)=0,"",SUM($F22:$J22)) | L22: =IF(COUNT(F22:J22)=0,"",IFERROR(K22/$K$15*$L$15,"")) | M22: =IF(L22="","",L22*$M$15) | Q22: =IF(COUNT(N22:P22)=0,"",SUM(N22:P22)) | R22: =IF(COUNT(N22:P22)=0,"",IFERROR(Q22/$Q$15*$R$15,"")) | S22: =IF(R22="","",R22*$S$15) | W22: =IF(T22="","",IFERROR(T22/$T$15*$W$15,"")) | X22: =IF(U22="","",IFERROR(U22/$U$15*$X$15,"")) | Y22: =IF(V22="","",IFERROR(V22/$V$15*$Y$15,"")) | Z22: =IF(COUNT(T22:V22)=0,"",SUM(W22:Y22)) | AA22: =IF(Z22="","",Z22*$AA$15) | AB22: =IF(COUNT(F22:J22,N22:P22,T22:V22)=0,"",SUM(M22,S22,AA22)) | AC22: =IF(AB22="","",IFERROR(INDEX(HELPER!$D$8:$D$48,IF(AB22>=HELPER!$B$8,1,MATCH(AB22,HELPER!$B$8:$B$48,-1)+1)),"")) | AD22: =IF(AC22="","",IFERROR(VLOOKUP(AC22,HELPER!$F$8:$G$48,2,FALSE),""))
B23: 6 | C23: =IF('INPUT DATA'!K16="","",'INPUT DATA'!K16) | K23: =IF(COUNT($F23:$J23)=0,"",SUM($F23:$J23)) | L23: =IF(COUNT(F23:J23)=0,"",IFERROR(K23/$K$15*$L$15,"")) | M23: =IF(L23="","",L23*$M$15) | Q23: =IF(COUNT(N23:P23)=0,"",SUM(N23:P23)) | R23: =IF(COUNT(N23:P23)=0,"",IFERROR(Q23/$Q$15*$R$15,"")) | S23: =IF(R23="","",R23*$S$15) | W23: =IF(T23="","",IFERROR(T23/$T$15*$W$15,"")) | X23: =IF(U23="","",IFERROR(U23/$U$15*$X$15,"")) | Y23: =IF(V23="","",IFERROR(V23/$V$15*$Y$15,"")) | Z23: =IF(COUNT(T23:V23)=0,"",SUM(W23:Y23)) | AA23: =IF(Z23="","",Z23*$AA$15) | AB23: =IF(COUNT(F23:J23,N23:P23,T23:V23)=0,"",SUM(M23,S23,AA23)) | AC23: =IF(AB23="","",IFERROR(INDEX(HELPER!$D$8:$D$48,IF(AB23>=HELPER!$B$8,1,MATCH(AB23,HELPER!$B$8:$B$48,-1)+1)),"")) | AD23: =IF(AC23="","",IFERROR(VLOOKUP(AC23,HELPER!$F$8:$G$48,2,FALSE),""))
B24: 7 | C24: =IF('INPUT DATA'!K17="","",'INPUT DATA'!K17) | K24: =IF(COUNT($F24:$J24)=0,"",SUM($F24:$J24)) | L24: =IF(COUNT(F24:J24)=0,"",IFERROR(K24/$K$15*$L$15,"")) | M24: =IF(L24="","",L24*$M$15) | Q24: =IF(COUNT(N24:P24)=0,"",SUM(N24:P24)) | R24: =IF(COUNT(N24:P24)=0,"",IFERROR(Q24/$Q$15*$R$15,"")) | S24: =IF(R24="","",R24*$S$15) | W24: =IF(T24="","",IFERROR(T24/$T$15*$W$15,"")) | X24: =IF(U24="","",IFERROR(U24/$U$15*$X$15,"")) | Y24: =IF(V24="","",IFERROR(V24/$V$15*$Y$15,"")) | Z24: =IF(COUNT(T24:V24)=0,"",SUM(W24:Y24)) | AA24: =IF(Z24="","",Z24*$AA$15) | AB24: =IF(COUNT(F24:J24,N24:P24,T24:V24)=0,"",SUM(M24,S24,AA24)) | AC24: =IF(AB24="","",IFERROR(INDEX(HELPER!$D$8:$D$48,IF(AB24>=HELPER!$B$8,1,MATCH(AB24,HELPER!$B$8:$B$48,-1)+1)),"")) | AD24: =IF(AC24="","",IFERROR(VLOOKUP(AC24,HELPER!$F$8:$G$48,2,FALSE),""))
B25: 8 | C25: =IF('INPUT DATA'!K18="","",'INPUT DATA'!K18) | K25: =IF(COUNT($F25:$J25)=0,"",SUM($F25:$J25)) | L25: =IF(COUNT(F25:J25)=0,"",IFERROR(K25/$K$15*$L$15,"")) | M25: =IF(L25="","",L25*$M$15) | Q25: =IF(COUNT(N25:P25)=0,"",SUM(N25:P25)) | R25: =IF(COUNT(N25:P25)=0,"",IFERROR(Q25/$Q$15*$R$15,"")) | S25: =IF(R25="","",R25*$S$15) | W25: =IF(T25="","",IFERROR(T25/$T$15*$W$15,"")) | X25: =IF(U25="","",IFERROR(U25/$U$15*$X$15,"")) | Y25: =IF(V25="","",IFERROR(V25/$V$15*$Y$15,"")) | Z25: =IF(COUNT(T25:V25)=0,"",SUM(W25:Y25)) | AA25: =IF(Z25="","",Z25*$AA$15) | AB25: =IF(COUNT(F25:J25,N25:P25,T25:V25)=0,"",SUM(M25,S25,AA25)) | AC25: =IF(AB25="","",IFERROR(INDEX(HELPER!$D$8:$D$48,IF(AB25>=HELPER!$B$8,1,MATCH(AB25,HELPER!$B$8:$B$48,-1)+1)),"")) | AD25: =IF(AC25="","",IFERROR(VLOOKUP(AC25,HELPER!$F$8:$G$48,2,FALSE),""))
B26: 9 | C26: =IF('INPUT DATA'!K19="","",'INPUT DATA'!K19) | K26: =IF(COUNT($F26:$J26)=0,"",SUM($F26:$J26)) | L26: =IF(COUNT(F26:J26)=0,"",IFERROR(K26/$K$15*$L$15,"")) | M26: =IF(L26="","",L26*$M$15) | Q26: =IF(COUNT(N26:P26)=0,"",SUM(N26:P26)) | R26: =IF(COUNT(N26:P26)=0,"",IFERROR(Q26/$Q$15*$R$15,"")) | S26: =IF(R26="","",R26*$S$15) | W26: =IF(T26="","",IFERROR(T26/$T$15*$W$15,"")) | X26: =IF(U26="","",IFERROR(U26/$U$15*$X$15,"")) | Y26: =IF(V26="","",IFERROR(V26/$V$15*$Y$15,"")) | Z26: =IF(COUNT(T26:V26)=0,"",SUM(W26:Y26)) | AA26: =IF(Z26="","",Z26*$AA$15) | AB26: =IF(COUNT(F26:J26,N26:P26,T26:V26)=0,"",SUM(M26,S26,AA26)) | AC26: =IF(AB26="","",IFERROR(INDEX(HELPER!$D$8:$D$48,IF(AB26>=HELPER!$B$8,1,MATCH(AB26,HELPER!$B$8:$B$48,-1)+1)),"")) | AD26: =IF(AC26="","",IFERROR(VLOOKUP(AC26,HELPER!$F$8:$G$48,2,FALSE),""))
B27: 10 | C27: =IF('INPUT DATA'!K20="","",'INPUT DATA'!K20) | K27: =IF(COUNT($F27:$J27)=0,"",SUM($F27:$J27)) | L27: =IF(COUNT(F27:J27)=0,"",IFERROR(K27/$K$15*$L$15,"")) | M27: =IF(L27="","",L27*$M$15) | Q27: =IF(COUNT(N27:P27)=0,"",SUM(N27:P27)) | R27: =IF(COUNT(N27:P27)=0,"",IFERROR(Q27/$Q$15*$R$15,"")) | S27: =IF(R27="","",R27*$S$15) | W27: =IF(T27="","",IFERROR(T27/$T$15*$W$15,"")) | X27: =IF(U27="","",IFERROR(U27/$U$15*$X$15,"")) | Y27: =IF(V27="","",IFERROR(V27/$V$15*$Y$15,"")) | Z27: =IF(COUNT(T27:V27)=0,"",SUM(W27:Y27)) | AA27: =IF(Z27="","",Z27*$AA$15) | AB27: =IF(COUNT(F27:J27,N27:P27,T27:V27)=0,"",SUM(M27,S27,AA27)) | AC27: =IF(AB27="","",IFERROR(INDEX(HELPER!$D$8:$D$48,IF(AB27>=HELPER!$B$8,1,MATCH(AB27,HELPER!$B$8:$B$48,-1)+1)),"")) | AD27: =IF(AC27="","",IFERROR(VLOOKUP(AC27,HELPER!$F$8:$G$48,2,FALSE),""))
B28: 11 | C28: =IF('INPUT DATA'!K21="","",'INPUT DATA'!K21) | K28: =IF(COUNT($F28:$J28)=0,"",SUM($F28:$J28)) | L28: =IF(COUNT(F28:J28)=0,"",IFERROR(K28/$K$15*$L$15,"")) | M28: =IF(L28="","",L28*$M$15) | Q28: =IF(COUNT(N28:P28)=0,"",SUM(N28:P28)) | R28: =IF(COUNT(N28:P28)=0,"",IFERROR(Q28/$Q$15*$R$15,"")) | S28: =IF(R28="","",R28*$S$15) | W28: =IF(T28="","",IFERROR(T28/$T$15*$W$15,"")) | X28: =IF(U28="","",IFERROR(U28/$U$15*$X$15,"")) | Y28: =IF(V28="","",IFERROR(V28/$V$15*$Y$15,"")) | Z28: =IF(COUNT(T28:V28)=0,"",SUM(W28:Y28)) | AA28: =IF(Z28="","",Z28*$AA$15) | AB28: =IF(COUNT(F28:J28,N28:P28,T28:V28)=0,"",SUM(M28,S28,AA28)) | AC28: =IF(AB28="","",IFERROR(INDEX(HELPER!$D$8:$D$48,IF(AB28>=HELPER!$B$8,1,MATCH(AB28,HELPER!$B$8:$B$48,-1)+1)),"")) | AD28: =IF(AC28="","",IFERROR(VLOOKUP(AC28,HELPER!$F$8:$G$48,2,FALSE),""))
B29: 12 | C29: =IF('INPUT DATA'!K22="","",'INPUT DATA'!K22) | K29: =IF(COUNT($F29:$J29)=0,"",SUM($F29:$J29)) | L29: =IF(COUNT(F29:J29)=0,"",IFERROR(K29/$K$15*$L$15,"")) | M29: =IF(L29="","",L29*$M$15) | Q29: =IF(COUNT(N29:P29)=0,"",SUM(N29:P29)) | R29: =IF(COUNT(N29:P29)=0,"",IFERROR(Q29/$Q$15*$R$15,"")) | S29: =IF(R29="","",R29*$S$15) | W29: =IF(T29="","",IFERROR(T29/$T$15*$W$15,"")) | X29: =IF(U29="","",IFERROR(U29/$U$15*$X$15,"")) | Y29: =IF(V29="","",IFERROR(V29/$V$15*$Y$15,"")) | Z29: =IF(COUNT(T29:V29)=0,"",SUM(W29:Y29)) | AA29: =IF(Z29="","",Z29*$AA$15) | AB29: =IF(COUNT(F29:J29,N29:P29,T29:V29)=0,"",SUM(M29,S29,AA29)) | AC29: =IF(AB29="","",IFERROR(INDEX(HELPER!$D$8:$D$48,IF(AB29>=HELPER!$B$8,1,MATCH(AB29,HELPER!$B$8:$B$48,-1)+1)),"")) | AD29: =IF(AC29="","",IFERROR(VLOOKUP(AC29,HELPER!$F$8:$G$48,2,FALSE),""))
... B67: 50 | C67: =IF('INPUT DATA'!K60="","",'INPUT DATA'!K60) | K67: =IF(COUNT($F67:$J67)=0,"",SUM($F67:$J67)) | L67: =IF(COUNT(F67:J67)=0,"",IFERROR(K67/$K$15*$L$15,"")) | M67: =IF(L67="","",L67*$M$15) | Q67: =IF(COUNT(N67:P67)=0,"",SUM(N67:P67)) | R67: =IF(COUNT(N67:P67)=0,"",IFERROR(Q67/$Q$15*$R$15,"")) | S67: =IF(R67="","",R67*$S$15) | W67: =IF(T67="","",IFERROR(T67/$T$15*$W$15,"")) | X67: =IF(U67="","",IFERROR(U67/$U$15*$X$15,"")) | Y67: =IF(V67="","",IFERROR(V67/$V$15*$Y$15,"")) | Z67: =IF(COUNT(T67:V67)=0,"",SUM(W67:Y67)) | AA67: =IF(Z67="","",Z67*$AA$15) | AB67: =IF(COUNT(F67:J67,N67:P67,T67:V67)=0,"",SUM(M67,S67,AA67)) | AC67: =IF(AB67="","",IFERROR(INDEX(HELPER!$D$8:$D$48,IF(AB67>=HELPER!$B$8,1,MATCH(AB67,HELPER!$B$8:$B$48,-1)+1)),"")) | AD67: =IF(AC67="","",IFERROR(VLOOKUP(AC67,HELPER!$F$8:$G$48,2,FALSE),""))
B68: FEMALE
